Workbook

Sheet T-JCI2 RH
B1: Screen Id | D1: PPSP0020 | F1: Machine Name | H1: EGPSPC024 | J1: Printed On | L1: 2026-05-10 11:00:59
B3: MPS Plan - Customer:[JCI]
B5: Section Code | D5: PORT SAID MANUFACTURING(SAID)
B6: MPS ID | D6: JCI2 RH_VOLVO RH_W20/26_W44/27_01 | J6: MPS Type | L6: Oblige | N6: Target Efficiency | P6: 0.92
B7: Facility | D7: JCI2 RH | J7: Car Model | L7: VOLVO RH | N7: Working Hours | P7: 7
B8: From Date | D8: 2026/05/11 | E8: To Date | G8: 2027/11/07 | J8: Total Weeks | L8: 78 | N8: offset Weeks | P8: 4
B9: Facility (DOS) | D9: 10 | E9: Plan Suggestion By | G9: OPERATOR_EFFICIENCY | J9: Week Plan Offset | L9: 99 | N9: Assy Std.Hr. | P9: 0.297
S10: JCI2 RH(Shift 1) | W10: JCI2 RH(Shift 2) | AA10: JCI2 RH(Shift 3)
B11: Month | C11: Plan Date | D11: Week No | E11: SEWS-E WD | F11: Cust WD | G11: Invt Qty | H11: WIP | I11: Sales Qty | J11: Avg Days | K11: Plan Qty | L11: Bottom P/Qty | M11: Assy Std.Hr. | N11: GPTC Tm. | O11: Cust P.P. | P11: Comments | Q11: Customer Plan | R11: Cust. Avg. Daily Build | S11: Heads | T11: Eff % | U11: Week/Hrs | V11: Team Qty | W11: Heads | X11: Eff % | Y11: Week/Hrs | Z11: Team Qty | AA11: Heads | AB11: Eff % | AC11: Week/Hrs | AD11: Team Qty | AE11: Total Op. | AF11: Car %age | AG11: TotStdTm | AH11: Clock Hours | AI11: Eff %
B12: May | C12: 46153 | D12: 20 | E12: 6 | F12: 5 | G12: ='B-JCI2 RH'!D260 -> 25017 | H12: ='B-JCI2 RH'!D261 -> 2732 | I12: ='B-JCI2 RH'!D263 -> 320 | J12: =IF(I12=0,"N/S",ROUND( ( ((G12) * 1)/I12)*F12,1)) -> 390.9 | K12: =V12+Z12+AD12 -> 2694 | L12: {=TRANSPOSE('B-JCI2 RH'!D262:CC262)} -> 2576 | M12: ='B-JCI2 RH'!$D$295 -> 0.2963 | N12: 0 | O12: 5 | Q12: 0 | R12: =IF(F12=0,0,ROUND(I12/F12,0)) -> 64 | S12: 19 | T12: 0.5 | U12: =E12*7-N12 -> 42 | V12: =ROUND(((S12*T12*U12)/M12),0) -> 1347 | W12: =S12 -> 19 | X12: 0.5 | Y12: =U12 -> 42 | Z12: =ROUND(((W12*X12*Y12)/M12),0) -> 1347 | AA12: 0 | AB12: 0 | AC12: =E12*7-N12 -> 42 | AD12: =ROUND(((AA12*AB12*AC12)/M12),0) -> 0 | AE12: =S12+W12+AA12 -> 38 | AG12: =K12*M12 -> 798.2322 | AH12: =S12*U12+W12*Y12+AA12*AC12 -> 1596 | AI12: =IF(AH12=0,0,AG12/AH12) -> 0.50014549
B13: May | C13: 46160 | D13: 21 | E13: 6 | F13: 10 | G13: =(G12+H12-I12) -> 27429 | H13: 0 | I13: ='B-JCI2 RH'!E263 -> 5700 | J13: =IF(I13=0,"N/S",ROUND( ( ((G13) * 1)/I13)*F13,1)) -> 48.1 | K13: =V13+Z13+AD13 -> 3232 | L13: 3544 | M13: ='B-JCI2 RH'!$D$295 -> 0.2963 | N13: 0 | O13: 5 | Q13: 0 | R13: =IF(F13=0,0,ROUND(I13/F13,0)) -> 570 | S13: 19 | T13: 0.6 | U13: =E13*7-N13 -> 42 | V13: =ROUND(((S13*T13*U13)/M13),0) -> 1616 | W13: =S13 -> 19 | X13: 0.6 | Y13: =U13 -> 42 | Z13: =ROUND(((W13*X13*Y13)/M13),0) -> 1616 | AA13: 0 | AB13: 0 | AC13: =E13*7-N13 -> 42 | AD13: =ROUND(((AA13*AB13*AC13)/M13),0) -> 0 | AE13: =S13+W13+AA13 -> 38 | AG13: =K13*M13 -> 957.6416 | AH13: =S13*U13+W13*Y13+AA13*AC13 -> 1596 | AI13: =IF(AH13=0,0,AG13/AH13) -> 0.60002607
B14: May | C14: 46167 | D14: 22 | E14: 3 | F14: 5 | G14: =(G13+H13-I13) -> 21729 | H14: 0 | I14: ='B-JCI2 RH'!F263 -> 3660 | J14: =IF(I14=0,"N/S",ROUND( ( ((G14) * 1)/I14)*F14,1)) -> 29.7 | K14: =V14+Z14+AD14 -> 1886 | L14: 1950 | M14: ='B-JCI2 RH'!$D$295 -> 0.2963 | N14: 0 | O14: 5 | Q14: 0 | R14: =IF(F14=0,0,ROUND(I14/F14,0)) -> 732 | S14: 19 | T14: 0.7 | U14: =E14*7-N14 -> 21 | V14: =ROUND(((S14*T14*U14)/M14),0) -> 943 | W14: =S14 -> 19 | X14: 0.7 | Y14: =U14 -> 21 | Z14: =ROUND(((W14*X14*Y14)/M14),0) -> 943 | AA14: 0 | AB14: 0 | AC14: =E14*7-N14 -> 21 | AD14: =ROUND(((AA14*AB14*AC14)/M14),0) -> 0 | AE14: =S14+W14+AA14 -> 38 | AG14: =K14*M14 -> 558.8218 | AH14: =S14*U14+W14*Y14+AA14*AC14 -> 798 | AI14: =IF(AH14=0,0,AG14/AH14) -> 0.70027794
B15: Jun | C15: 46174 | D15: 23 | E15: 5 | F15: 5 | G15: =(G14+H14-I14) -> 18069 | H15: 0 | I15: ='B-JCI2 RH'!G263 -> 4240 | J15: =IF(I15=0,"N/S",ROUND( ( ((G15) * 1)/I15)*F15,1)) -> 21.3 | K15: =V15+Z15+AD15 -> 3456 | L15: 0 | M15: ='B-JCI2 RH'!$D$295 -> 0.2963 | N15: 0 | O15: 6 | Q15: 0 | R15: =IF(F15=0,0,ROUND(I15/F15,0)) -> 848 | S15: 19 | T15: 0.77 | U15: =E15*7-N15 -> 35 | V15: =ROUND(((S15*T15*U15)/M15),0) -> 1728 | W15: =S15 -> 19 | X15: 0.77 | Y15: =U15 -> 35 | Z15: =ROUND(((W15*X15*Y15)/M15),0) -> 1728 | AA15: 0 | AB15: 0 | AC15: =E15*7-N15 -> 35 | AD15: =ROUND(((AA15*AB15*AC15)/M15),0) -> 0 | AE15: =S15+W15+AA15 -> 38 | AG15: =K15*M15 -> 1024.0128 | AH15: =S15*U15+W15*Y15+AA15*AC15 -> 1330 | AI15: =IF(AH15=0,0,AG15/AH15) -> 0.76993444
B16: Jun | C16: 46181 | D16: 24 | E16: 6 | F16: 5 | G16: =(G15+H15-I15) -> 13829 | H16: 0 | I16: ='B-JCI2 RH'!H263 -> 3975 | J16: =IF(I16=0,"N/S",ROUND( ( ((G16) * 1)/I16)*F16,1)) -> 17.4 | K16: =V16+Z16+AD16 -> 4148 | L16: 0 | M16: ='B-JCI2 RH'!$D$295 -> 0.2963 | N16: 0 | O16: 6 | Q16: 0 | R16: =IF(F16=0,0,ROUND(I16/F16,0)) -> 795 | S16: 19 | T16: 0.77 | U16: =E16*7-N16 -> 42 | V16: =ROUND(((S16*T16*U16)/M16),0) -> 2074 | W16: =S16 -> 19 | X16: 0.77 | Y16: =U16 -> 42 | Z16: =ROUND(((W16*X16*Y16)/M16),0) -> 2074 | AA16: 0 | AB16: 0 | AC16: =E16*7-N16 -> 42 | AD16: =ROUND(((AA16*AB16*AC16)/M16),0) -> 0 | AE16: =S16+W16+AA16 -> 38 | AG16: =K16*M16 -> 1229.0524 | AH16: =S16*U16+W16*Y16+AA16*AC16 -> 1596 | AI16: =IF(AH16=0,0,AG16/AH16) -> 0.77008296
B17: Jun | C17: 46188 | D17: 25 | E17: 3 | F17: 5 | G17: =(G16+H16-I16+K12) -> 12548 | H17: 0 | I17: ='B-JCI2 RH'!I263 -> 3860 | J17: =IF(I17=0,"N/S",ROUND( ( ((G17) * 1)/I17)*F17,1)) -> 16.3 | K17: =V17+Z17+AD17 -> 2074 | L17: 0 | M17: ='B-JCI2 RH'!$D$295 -> 0.2963 | N17: 0 | O17: 6 | P17: Move to Posa.3 | Q17: 0 | R17: =IF(F17=0,0,ROUND(I17/F17,0)) -> 772 | S17: 19 | T17: 0.77 | U17: =E17*7-N17 -> 21 | V17: =ROUND(((S17*T17*U17)/M17),0) -> 1037 | W17: =S17 -> 19 | X17: 0.77 | Y17: =U17 -> 21 | Z17: =ROUND(((W17*X17*Y17)/M17),0) -> 1037 | AA17: 0 | AB17: 0 | AC17: =E17*7-N17 -> 21 | AD17: =ROUND(((AA17*AB17*AC17)/M17),0) -> 0 | AE17: =S17+W17+AA17 -> 38 | AG17: =K17*M17 -> 614.5262 | AH17: =S17*U17+W17*Y17+AA17*AC17 -> 798 | AI17: =IF(AH17=0,0,AG17/AH17) -> 0.77008296
B18: Jun | C18: 46195 | D18: 26 | E18: 6 | F18: 5 | G18: =(G17+H17-I17+K13) -> 11920 | H18: 0 | I18: ='B-JCI2 RH'!J263 -> 3580 | J18: =IF(I18=0,"N/S",ROUND( ( ((G18) * 1)/I18)*F18,1)) -> 16.6 | K18: =V18+Z18+AD18 -> 4148 | L18: 0 | M18: ='B-JCI2 RH'!$D$295 -> 0.2963 | N18: 0 | O18: 6 | Q18: 0 | R18: =IF(F18=0,0,ROUND(I18/F18,0)) -> 716 | S18: 19 | T18: 0.77 | U18: =E18*7-N18 -> 42 | V18: =ROUND(((S18*T18*U18)/M18),0) -> 2074 | W18: =S18 -> 19 | X18: 0.77 | Y18: =U18 -> 42 | Z18: =ROUND(((W18*X18*Y18)/M18),0) -> 2074 | AA18: 0 | AB18: 0 | AC18: =E18*7-N18 -> 42 | AD18: =ROUND(((AA18*AB18*AC18)/M18),0) -> 0 | AE18: =S18+W18+AA18 -> 38 | AG18: =K18*M18 -> 1229.0524 | AH18: =S18*U18+W18*Y18+AA18*AC18 -> 1596 | AI18: =IF(AH18=0,0,AG18/AH18) -> 0.77008296
B19: Jun | C19: 46202 | D19: 27 | E19: 5 | F19: 5 | G19: =(G18+H18-I18+K14) -> 10226 | H19: 0 | I19: ='B-JCI2 RH'!K263 -> 4000 | J19: =IF(I19=0,"N/S",ROUND( ( ((G19) * 1)/I19)*F19,1)) -> 12.8 | K19: =V19+Z19+AD19 -> 3456 | L19: 0 | M19: ='B-JCI2 RH'!$D$295 -> 0.2963 | N19: 0 | O19: 6 | Q19: 0 | R19: =IF(F19=0,0,ROUND(I19/F19,0)) -> 800 | S19: 19 | T19: 0.77 | U19: =E19*7-N19 -> 35 | V19: =ROUND(((S19*T19*U19)/M19),0) -> 1728 | W19: =S19 -> 19 | X19: 0.77 | Y19: =U19 -> 35 | Z19: =ROUND(((W19*X19*Y19)/M19),0) -> 1728 | AA19: 0 | AB19: 0 | AC19: =E19*7-N19 -> 35 | AD19: =ROUND(((AA19*AB19*AC19)/M19),0) -> 0 | AE19: =S19+W19+AA19 -> 38 | AG19: =K19*M19 -> 1024.0128 | AH19: =S19*U19+W19*Y19+AA19*AC19 -> 1330 | AI19: =IF(AH19=0,0,AG19/AH19) -> 0.76993444
B20: Jul | C20: 46209 | D20: 28 | E20: 6 | F20: 5 | G20: =(G19+H19-I19+K15) -> 9682 | H20: 0 | I20: ='B-JCI2 RH'!L263 -> 5400 | J20: =IF(I20=0,"N/S",ROUND( ( ((G20) * 1)/I20)*F20,1)) -> 9 | K20: =V20+Z20+AD20 -> 4148 | L20: 0 | M20: ='B-JCI2 RH'!$D$295 -> 0.2963 | N20: 0 | O20: 7 | Q20: 0 | R20: =IF(F20=0,0,ROUND(I20/F20,0)) -> 1080 | S20: 19 | T20: 0.77 | U20: =E20*7-N20 -> 42 | V20: =ROUND(((S20*T20*U20)/M20),0) -> 2074 | W20: =S20 -> 19 | X20: 0.77 | Y20: =U20 -> 42 | Z20: =ROUND(((W20*X20*Y20)/M20),0) -> 2074 | AA20: 0 | AB20: 0 | AC20: =E20*7-N20 -> 42 | AD20: =ROUND(((AA20*AB20*AC20)/M20),0) -> 0 | AE20: =S20+W20+AA20 -> 38 | AG20: =K20*M20 -> 1229.0524 | AH20: =S20*U20+W20*Y20+AA20*AC20 -> 1596 | AI20: =IF(AH20=0,0,AG20/AH20) -> 0.77008296
B21: Jul | C21: 46216 | D21: 29 | E21: 0 | F21: 10 | G21: =(G20+H20-I20+K16) -> 8430 | H21: 0 | I21: ='B-JCI2 RH'!M263 -> 6300 | J21: =IF(I21=0,"N/S",ROUND( ( ((G21) * 1)/I21)*F21,1)) -> 13.4 | K21: =V21+Z21+AD21 -> 0 | L21: 0 | M21: ='B-JCI2 RH'!$D$295 -> 0.2963 | N21: 0 | O21: 7 | Q21: 0 | R21: =IF(F21=0,0,ROUND(I21/F21,0)) -> 630 | S21: 19 | T21: 0.77 | U21: =E21*7-N21 -> 0 | V21: =ROUND(((S21*T21*U21)/M21),0) -> 0 | W21: =S21 -> 19 | X21: 0.77 | Y21: =U21 -> 0 | Z21: =ROUND(((W21*X21*Y21)/M21),0) -> 0 | AA21: 0 | AB21: 0 | AC21: =E21*7-N21 -> 0 | AD21: =ROUND(((AA21*AB21*AC21)/M21),0) -> 0 | AE21: =S21+W21+AA21 -> 38 | AG21: =K21*M21 -> 0 | AH21: =S21*U21+W21*Y21+AA21*AC21 -> 0 | AI21: =IF(AH21=0,0,AG21/AH21) -> 0
B22: Jul | C22: 46223 | D22: 30 | E22: 0 | F22: 5 | G22: =(G21+H21-I21+K17) -> 4204 | H22: 0 | I22: ='B-JCI2 RH'!N263 -> 0 | J22: =IF(I22=0,"N/S",ROUND( ( ((G22) * 1)/I22)*F22,1)) -> N/S | K22: =V22+Z22+AD22 -> 0 | L22: 0 | M22: ='B-JCI2 RH'!$D$295 -> 0.2963 | N22: 0 | O22: 7 | Q22: 0 | R22: =IF(F22=0,0,ROUND(I22/F22,0)) -> 0 | S22: 16 | T22: 0.77 | U22: =E22*7-N22 -> 0 | V22: =ROUND(((S22*T22*U22)/M22),0) -> 0 | W22: =S22 -> 16 | X22: 0.77 | Y22: =U22 -> 0 | Z22: =ROUND(((W22*X22*Y22)/M22),0) -> 0 | AA22: 0 | AB22: 0 | AC22: =E22*7-N22 -> 0 | AD22: =ROUND(((AA22*AB22*AC22)/M22),0) -> 0 | AE22: =S22+W22+AA22 -> 32 | AG22: =K22*M22 -> 0 | AH22: =S22*U22+W22*Y22+AA22*AC22 -> 0 | AI22: =IF(AH22=0,0,AG22/AH22) -> 0
B23: Jul | C23: 46230 | D23: 31 | E23: 6 | F23: 5 | G23: =(G22+H22-I22+K18) -> 8352 | H23: 0 | I23: ='B-JCI2 RH'!O263 -> 0 | J23: =IF(I23=0,"N/S",ROUND( ( ((G23) * 1)/I23)*F23,1)) -> N/S | K23: =V23+Z23+AD23 -> 3492 | L23: 0 | M23: ='B-JCI2 RH'!$D$295 -> 0.2963 | N23: 0 | O23: 7 | Q23: 0 | R23: =IF(F23=0,0,ROUND(I23/F23,0)) -> 0 | S23: 16 | T23: 0.77 | U23: =E23*7-N23 -> 42 | V23: =ROUND(((S23*T23*U23)/M23),0) -> 1746 | W23: =S23 -> 16 | X23: 0.77 | Y23: =U23 -> 42 | Z23: =ROUND(((W23*X23*Y23)/M23),0) -> 1746 | AA23: 0 | AB23: 0 | AC23: =E23*7-N23 -> 42 | AD23: =ROUND(((AA23*AB23*AC23)/M23),0) -> 0 | AE23: =S23+W23+AA23 -> 32 | AF23: =ROUND( ((SUM(I22:I23)*1)/SUM(Q22:Q23)*100),1) -> #DIV/0! | AG23: =K23*M23 -> 1034.6796 | AH23: =S23*U23+W23*Y23+AA23*AC23 -> 1344 | AI23: =IF(AH23=0,0,AG23/AH23) -> 0.76985089
B24: Aug | C24: 46237 | D24: 32 | E24: 6 | F24: 5 | G24: =(G23+H23-I23+K19) -> 11808 | H24: 0 | I24: ='B-JCI2 RH'!P263 -> 0 | J24: =IF(I24=0,"N/S",ROUND( ( ((G24) * 1)/I24)*F24,1)) -> N/S | K24: =V24+Z24+AD24 -> 3492 | L24: 0 | M24: ='B-JCI2 RH'!$D$295 -> 0.2963 | N24: 0 | O24: 8 | Q24: 0 | R24: =IF(F24=0,0,ROUND(I24/F24,0)) -> 0 | S24: 16 | T24: 0.77 | U24: =E24*7-N24 -> 42 | V24: =ROUND(((S24*T24*U24)/M24),0) -> 1746 | W24: =S24 -> 16 | X24: 0.77 | Y24: =U24 -> 42 | Z24: =ROUND(((W24*X24*Y24)/M24),0) -> 1746 | AA24: 0 | AB24: 0 | AC24: =E24*7-N24 -> 42 | AD24: =ROUND(((AA24*AB24*AC24)/M24),0) -> 0 | AE24: =S24+W24+AA24 -> 32 | AF24: =ROUND( ((SUM(I23:I24)*1)/SUM(Q23:Q24)*100),1) -> #DIV/0! | AG24: =K24*M24 -> 1034.6796 | AH24: =S24*U24+W24*Y24+AA24*AC24 -> 1344 | AI24: =IF(AH24=0,0,AG24/AH24) -> 0.76985089
B25: Aug | C25: 46244 | D25: 33 | E25: 6 | F25: 4 | G25: =(G24+H24-I24+K20) -> 15956 | H25: 0 | I25: ='B-JCI2 RH'!Q263 -> 0 | J25: =IF(I25=0,"N/S",ROUND( ( ((G25) * 1)/I25)*F25,1)) -> N/S | K25: =V25+Z25+AD25 -> 3492 | L25: 0 | M25: ='B-JCI2 RH'!$D$295 -> 0.2963 | N25: 0 | O25: 8 | Q25: 0 | R25: =IF(F25=0,0,ROUND(I25/F25,0)) -> 0 | S25: 16 | T25: 0.77 | U25: =E25*7-N25 -> 42 | V25: =ROUND(((S25*T25*U25)/M25),0) -> 1746 | W25: =S25 -> 16 | X25: 0.77 | Y25: =U25 -> 42 | Z25: =ROUND(((W25*X25*Y25)/M25),0) -> 1746 | AA25: 0 | AB25: 0 | AC25: =E25*7-N25 -> 42 | AD25: =ROUND(((AA25*AB25*AC25)/M25),0) -> 0 | AE25: =S25+W25+AA25 -> 32 | AF25: =ROUND( ((SUM(I24:I25)*1)/SUM(Q24:Q25)*100),1) -> #DIV/0! | AG25: =K25*M25 -> 1034.6796 | AH25: =S25*U25+W25*Y25+AA25*AC25 -> 1344 | AI25: =IF(AH25=0,0,AG25/AH25) -> 0.76985089
B26: Aug | C26: 46251 | D26: 34 | E26: 6 | F26: 5 | G26: =(G25+H25-I25+K21) -> 15956 | H26: 0 | I26: ='B-JCI2 RH'!R263 -> 3740 | J26: =IF(I26=0,"N/S",ROUND( ( ((G26) * 1)/I26)*F26,1)) -> 21.3 | K26: =V26+Z26+AD26 -> 3492 | L26: 0 | M26: ='B-JCI2 RH'!$D$295 -> 0.2963 | N26: 0 | O26: 8 | Q26: 0 | R26: =IF(F26=0,0,ROUND(I26/F26,0)) -> 748 | S26: 16 | T26: 0.77 | U26: =E26*7-N26 -> 42 | V26: =ROUND(((S26*T26*U26)/M26),0) -> 1746 | W26: =S26 -> 16 | X26: 0.77 | Y26: =U26 -> 42 | Z26: =ROUND(((W26*X26*Y26)/M26),0) -> 1746 | AA26: 0 | AB26: 0 | AC26: =E26*7-N26 -> 42 | AD26: =ROUND(((AA26*AB26*AC26)/M26),0) -> 0 | AE26: =S26+W26+AA26 -> 32 | AF26: =ROUND( ((SUM(I25:I26)*1)/SUM(Q25:Q26)*100),1) -> #DIV/0! | AG26: =K26*M26 -> 1034.6796 | AH26: =S26*U26+W26*Y26+AA26*AC26 -> 1344 | AI26: =IF(AH26=0,0,AG26/AH26) -> 0.76985089
B27: Aug | C27: 46258 | D27: 35 | E27: 5 | F27: 5 | G27: =(G26+H26-I26+K22) -> 12216 | H27: 0 | I27: ='B-JCI2 RH'!S263 -> 3400 | J27: =IF(I27=0,"N/S",ROUND( ( ((G27) * 1)/I27)*F27,1)) -> 18 | K27: =V27+Z27+AD27 -> 2910 | L27: 0 | M27: ='B-JCI2 RH'!$D$295 -> 0.2963 | N27: 0 | O27: 8 | Q27: 0 | R27: =IF(F27=0,0,ROUND(I27/F27,0)) -> 680 | S27: 16 | T27: 0.77 | U27: =E27*7-N27 -> 35 | V27: =ROUND(((S27*T27*U27)/M27),0) -> 1455 | W27: =S27 -> 16 | X27: 0.77 | Y27: =U27 -> 35 | Z27: =ROUND(((W27*X27*Y27)/M27),0) -> 1455 | AA27: 0 | AB27: 0 | AC27: =E27*7-N27 -> 35 | AD27: =ROUND(((AA27*AB27*AC27)/M27),0) -> 0 | AE27: =S27+W27+AA27 -> 32 | AF27: =ROUND( ((SUM(I26:I27)*1)/SUM(Q26:Q27)*100),1) -> #DIV/0! | AG27: =K27*M27 -> 862.233 | AH27: =S27*U27+W27*Y27+AA27*AC27 -> 1120 | AI27: =IF(AH27=0,0,AG27/AH27) -> 0.76985089
B28: Aug | C28: 46265 | D28: 36 | E28: 6 | F28: 5 | G28: =(G27+H27-I27+K23) -> 12308 | H28: 0 | I28: ='B-JCI2 RH'!T263 -> 3260 | J28: =IF(I28=0,"N/S",ROUND( ( ((G28) * 1)/I28)*F28,1)) -> 18.9 | K28: =V28+Z28+AD28 -> 3492 | L28: 0 | M28: ='B-JCI2 RH'!$D$295 -> 0.2963 | N28: 0 | O28: 8 | Q28: 0 | R28: =IF(F28=0,0,ROUND(I28/F28,0)) -> 652 | S28: 16 | T28: 0.77 | U28: =E28*7-N28 -> 42 | V28: =ROUND(((S28*T28*U28)/M28),0) -> 1746 | W28: =S28 -> 16 | X28: 0.77 | Y28: =U28 -> 42 | Z28: =ROUND(((W28*X28*Y28)/M28),0) -> 1746 | AA28: 0 | AB28: 0 | AC28: =E28*7-N28 -> 42 | AD28: =ROUND(((AA28*AB28*AC28)/M28),0) -> 0 | AE28: =S28+W28+AA28 -> 32 | AF28: =ROUND( ((SUM(I27:I28)*1)/SUM(Q27:Q28)*100),1) -> #DIV/0! | AG28: =K28*M28 -> 1034.6796 | AH28: =S28*U28+W28*Y28+AA28*AC28 -> 1344 | AI28: =IF(AH28=0,0,AG28/AH28) -> 0.76985089
B29: Sep | C29: 46272 | D29: 37 | E29: 6 | F29: 5 | G29: =(G28+H28-I28+K24) -> 12540 | H29: 0 | I29: ='B-JCI2 RH'!U263 -> 3680 | J29: =IF(I29=0,"N/S",ROUND( ( ((G29) * 1)/I29)*F29,1)) -> 17 | K29: =V29+Z29+AD29 -> 3056 | L29: 0 | M29: ='B-JCI2 RH'!$D$295 -> 0.2963 | N29: 0 | O29: 9 | Q29: 0 | R29: =IF(F29=0,0,ROUND(I29/F29,0)) -> 736 | S29: 14 | T29: 0.77 | U29: =E29*7-N29 -> 42 | V29: =ROUND(((S29*T29*U29)/M29),0) -> 1528 | W29: =S29 -> 14 | X29: 0.77 | Y29: =U29 -> 42 | Z29: =ROUND(((W29*X29*Y29)/M29),0) -> 1528 | AA29: 0 | AB29: 0 | AC29: =E29*7-N29 -> 42 | AD29: =ROUND(((AA29*AB29*AC29)/M29),0) -> 0 | AE29: =S29+W29+AA29 -> 28 | AF29: =ROUND( ((SUM(I28:I29)*1)/SUM(Q28:Q29)*100),1) -> #DIV/0! | AG29: =K29*M29 -> 905.4928 | AH29: =S29*U29+W29*Y29+AA29*AC29 -> 1176 | AI29: =IF(AH29=0,0,AG29/AH29) -> 0.76997687
B30: Sep | C30: 46279 | D30: 38 | E30: 6 | F30: 5 | G30: =(G29+H29-I29+K25) -> 12352 | H30: 0 | I30: ='B-JCI2 RH'!V263 -> 3680 | J30: =IF(I30=0,"N/S",ROUND( ( ((G30) * 1)/I30)*F30,1)) -> 16.8 | K30: =V30+Z30+AD30 -> 3056 | L30: 0 | M30: ='B-JCI2 RH'!$D$295 -> 0.2963 | N30: 0 | O30: 9 | Q30: 0 | R30: =IF(F30=0,0,ROUND(I30/F30,0)) -> 736 | S30: 14 | T30: 0.77 | U30: =E30*7-N30 -> 42 | V30: =ROUND(((S30*T30*U30)/M30),0) -> 1528 | W30: =S30 -> 14 | X30: 0.77 | Y30: =U30 -> 42 | Z30: =ROUND(((W30*X30*Y30)/M30),0) -> 1528 | AA30: 0 | AB30: 0 | AC30: =E30*7-N30 -> 42 | AD30: =ROUND(((AA30*AB30*AC30)/M30),0) -> 0 | AE30: =S30+W30+AA30 -> 28 | AF30: =ROUND( ((SUM(I29:I30)*1)/SUM(Q29:Q30)*100),1) -> #DIV/0! | AG30: =K30*M30 -> 905.4928 | AH30: =S30*U30+W30*Y30+AA30*AC30 -> 1176 | AI30: =IF(AH30=0,0,AG30/AH30) -> 0.76997687
B31: Sep | C31: 46286 | D31: 39 | E31: 4 | F31: 5 | G31: =(G30+H30-I30+K26) -> 12164 | H31: 0 | I31: ='B-JCI2 RH'!W263 -> 3680 | J31: =IF(I31=0,"N/S",ROUND( ( ((G31) * 1)/I31)*F31,1)) -> 16.5 | K31: =V31+Z31+AD31 -> 2038 | L31: 0 | M31: ='B-JCI2 RH'!$D$295 -> 0.2963 | N31: 0 | O31: 9 | Q31: 0 | R31: =IF(F31=0,0,ROUND(I31/F31,0)) -> 736 | S31: 14 | T31: 0.77 | U31: =E31*7-N31 -> 28 | V31: =ROUND(((S31*T31*U31)/M31),0) -> 1019 | W31: =S31 -> 14 | X31: 0.77 | Y31: =U31 -> 28 | Z31: =ROUND(((W31*X31*Y31)/M31),0) -> 1019 | AA31: 0 | AB31: 0 | AC31: =E31*7-N31 -> 28 | AD31: =ROUND(((AA31*AB31*AC31)/M31),0) -> 0 | AE31: =S31+W31+AA31 -> 28 | AF31: =ROUND( ((SUM(I30:I31)*1)/SUM(Q30:Q31)*100),1) -> #DIV/0! | AG31: =K31*M31 -> 603.8594 | AH31: =S31*U31+W31*Y31+AA31*AC31 -> 784 | AI31: =IF(AH31=0,0,AG31/AH31) -> 0.77022883
B32: Sep | C32: 46293 | D32: 40 | E32: 5 | F32: 5 | G32: =(G31+H31-I31+K27) -> 11394 | H32: 0 | I32: ='B-JCI2 RH'!X263 -> 3620 | J32: =IF(I32=0,"N/S",ROUND( ( ((G32) * 1)/I32)*F32,1)) -> 15.7 | K32: =V32+Z32+AD32 -> 2546 | L32: 0 | M32: ='B-JCI2 RH'!$D$295 -> 0.2963 | N32: 0 | O32: 9 | Q32: 0 | R32: =IF(F32=0,0,ROUND(I32/F32,0)) -> 724 | S32: 14 | T32: 0.77 | U32: =E32*7-N32 -> 35 | V32: =ROUND(((S32*T32*U32)/M32),0) -> 1273 | W32: =S32 -> 14 | X32: 0.77 | Y32: =U32 -> 35 | Z32: =ROUND(((W32*X32*Y32)/M32),0) -> 1273 | AA32: 0 | AB32: 0 | AC32: =E32*7-N32 -> 35 | AD32: =ROUND(((AA32*AB32*AC32)/M32),0) -> 0 | AE32: =S32+W32+AA32 -> 28 | AF32: =ROUND( ((SUM(I31:I32)*1)/SUM(Q31:Q32)*100),1) -> #DIV/0! | AG32: =K32*M32 -> 754.3798 | AH32: =S32*U32+W32*Y32+AA32*AC32 -> 980 | AI32: =IF(AH32=0,0,AG32/AH32) -> 0.76977531
B33: Oct | C33: 46300 | D33: 41 | E33: 5 | F33: 5 | G33: =(G32+H32-I32+K28) -> 11266 | H33: 0 | I33: ='B-JCI2 RH'!Y263 -> 2530 | J33: =IF(I33=0,"N/S",ROUND( ( ((G33) * 1)/I33)*F33,1)) -> 22.3 | K33: =V33+Z33+AD33 -> 2546 | L33: 0 | M33: ='B-JCI2 RH'!$D$295 -> 0.2963 | N33: 0 | O33: 10 | Q33: 0 | R33: =IF(F33=0,0,ROUND(I33/F33,0)) -> 506 | S33: 14 | T33: 0.77 | U33: =E33*7-N33 -> 35 | V33: =ROUND(((S33*T33*U33)/M33),0) -> 1273 | W33: =S33 -> 14 | X33: 0.77 | Y33: =U33 -> 35 | Z33: =ROUND(((W33*X33*Y33)/M33),0) -> 1273 | AA33: 0 | AB33: 0 | AC33: =E33*7-N33 -> 35 | AD33: =ROUND(((AA33*AB33*AC33)/M33),0) -> 0 | AE33: =S33+W33+AA33 -> 28 | AF33: =ROUND( ((SUM(I32:I33)*1)/SUM(Q32:Q33)*100),1) -> #DIV/0! | AG33: =K33*M33 -> 754.3798 | AH33: =S33*U33+W33*Y33+AA33*AC33 -> 980 | AI33: =IF(AH33=0,0,AG33/AH33) -> 0.76977531
B34: Oct | C34: 46307 | D34: 42 | E34: 6 | F34: 5 | G34: =(G33+H33-I33+K29) -> 11792 | H34: 0 | I34: ='B-JCI2 RH'!Z263 -> 2530 | J34: =IF(I34=0,"N/S",ROUND( ( ((G34) * 1)/I34)*F34,1)) -> 23.3 | K34: =V34+Z34+AD34 -> 3056 | L34: 0 | M34: ='B-JCI2 RH'!$D$295 -> 0.2963 | N34: 0 | O34: 10 | Q34: 0 | R34: =IF(F34=0,0,ROUND(I34/F34,0)) -> 506 | S34: 14 | T34: 0.77 | U34: =E34*7-N34 -> 42 | V34: =ROUND(((S34*T34*U34)/M34),0) -> 1528 | W34: =S34 -> 14 | X34: 0.77 | Y34: =U34 -> 42 | Z34: =ROUND(((W34*X34*Y34)/M34),0) -> 1528 | AA34: 0 | AB34: 0 | AC34: =E34*7-N34 -> 42 | AD34: =ROUND(((AA34*AB34*AC34)/M34),0) -> 0 | AE34: =S34+W34+AA34 -> 28 | AF34: =ROUND( ((SUM(I33:I34)*1)/SUM(Q33:Q34)*100),1) -> #DIV/0! | AG34: =K34*M34 -> 905.4928 | AH34: =S34*U34+W34*Y34+AA34*AC34 -> 1176 | AI34: =IF(AH34=0,0,AG34/AH34) -> 0.76997687
B35: Oct | C35: 46314 | D35: 43 | E35: 6 | F35: 5 | G35: =(G34+H34-I34+K30) -> 12318 | H35: 0 | I35: ='B-JCI2 RH'!AA263 -> 2530 | J35: =IF(I35=0,"N/S",ROUND( ( ((G35) * 1)/I35)*F35,1)) -> 24.3 | K35: =V35+Z35+AD35 -> 3056 | L35: 0 | M35: ='B-JCI2 RH'!$D$295 -> 0.2963 | N35: 0 | O35: 10 | Q35: 0 | R35: =IF(F35=0,0,ROUND(I35/F35,0)) -> 506 | S35: 14 | T35: 0.77 | U35: =E35*7-N35 -> 42 | V35: =ROUND(((S35*T35*U35)/M35),0) -> 1528 | W35: =S35 -> 14 | X35: 0.77 | Y35: =U35 -> 42 | Z35: =ROUND(((W35*X35*Y35)/M35),0) -> 1528 | AA35: 0 | AB35: 0 | AC35: =E35*7-N35 -> 42 | AD35: =ROUND(((AA35*AB35*AC35)/M35),0) -> 0 | AE35: =S35+W35+AA35 -> 28 | AF35: =ROUND( ((SUM(I34:I35)*1)/SUM(Q34:Q35)*100),1) -> #DIV/0! | AG35: =K35*M35 -> 905.4928 | AH35: =S35*U35+W35*Y35+AA35*AC35 -> 1176 | AI35: =IF(AH35=0,0,AG35/AH35) -> 0.76997687
B36: Oct | C36: 46321 | D36: 44 | E36: 6 | F36: 5 | G36: =(G35+H35-I35+K31) -> 11826 | H36: 0 | I36: ='B-JCI2 RH'!AB263 -> 2470 | J36: =IF(I36=0,"N/S",ROUND( ( ((G36) * 1)/I36)*F36,1)) -> 23.9 | K36: =V36+Z36+AD36 -> 3056 | L36: 0 | M36: ='B-JCI2 RH'!$D$295 -> 0.2963 | N36: 0 | O36: 10 | Q36: 0 | R36: =IF(F36=0,0,ROUND(I36/F36,0)) -> 494 | S36: 14 | T36: 0.77 | U36: =E36*7-N36 -> 42 | V36: =ROUND(((S36*T36*U36)/M36),0) -> 1528 | W36: =S36 -> 14 | X36: 0.77 | Y36: =U36 -> 42 | Z36: =ROUND(((W36*X36*Y36)/M36),0) -> 1528 | AA36: 0 | AB36: 0 | AC36: =E36*7-N36 -> 42 | AD36: =ROUND(((AA36*AB36*AC36)/M36),0) -> 0 | AE36: =S36+W36+AA36 -> 28 | AF36: =ROUND( ((SUM(I35:I36)*1)/SUM(Q35:Q36)*100),1) -> #DIV/0! | AG36: =K36*M36 -> 905.4928 | AH36: =S36*U36+W36*Y36+AA36*AC36 -> 1176 | AI36: =IF(AH36=0,0,AG36/AH36) -> 0.76997687
B37: Nov | C37: 46328 | D37: 45 | E37: 6 | F37: 5 | G37: =(G36+H36-I36+K32) -> 11902 | H37: 0 | I37: ='B-JCI2 RH'!AC263 -> 3790 | J37: =IF(I37=0,"N/S",ROUND( ( ((G37) * 1)/I37)*F37,1)) -> 15.7 | K37: =V37+Z37+AD37 -> 3056 | L37: 0 | M37: ='B-JCI2 RH'!$D$295 -> 0.2963 | N37: 0 | O37: 11 | Q37: 0 | R37: =IF(F37=0,0,ROUND(I37/F37,0)) -> 758 | S37: 14 | T37: 0.77 | U37: =E37*7-N37 -> 42 | V37: =ROUND(((S37*T37*U37)/M37),0) -> 1528 | W37: =S37 -> 14 | X37: 0.77 | Y37: =U37 -> 42 | Z37: =ROUND(((W37*X37*Y37)/M37),0) -> 1528 | AA37: 0 | AB37: 0 | AC37: =E37*7-N37 -> 42 | AD37: =ROUND(((AA37*AB37*AC37)/M37),0) -> 0 | AE37: =S37+W37+AA37 -> 28 | AF37: =ROUND( ((SUM(I36:I37)*1)/SUM(Q36:Q37)*100),1) -> #DIV/0! | AG37: =K37*M37 -> 905.4928 | AH37: =S37*U37+W37*Y37+AA37*AC37 -> 1176 | AI37: =IF(AH37=0,0,AG37/AH37) -> 0.76997687
B38: Nov | C38: 46335 | D38: 46 | E38: 6 | F38: 4 | G38: =(G37+H37-I37+K33) -> 10658 | H38: 0 | I38: ='B-JCI2 RH'!AD263 -> 3790 | J38: =IF(I38=0,"N/S",ROUND( ( ((G38) * 1)/I38)*F38,1)) -> 11.2 | K38: =V38+Z38+AD38 -> 3056 | L38: 0 | M38: ='B-JCI2 RH'!$D$295 -> 0.2963 | N38: 0 | O38: 11 | Q38: 0 | R38: =IF(F38=0,0,ROUND(I38/F38,0)) -> 948 | S38: 14 | T38: 0.77 | U38: =E38*7-N38 -> 42 | V38: =ROUND(((S38*T38*U38)/M38),0) -> 1528 | W38: =S38 -> 14 | X38: 0.77 | Y38: =U38 -> 42 | Z38: =ROUND(((W38*X38*Y38)/M38),0) -> 1528 | AA38: 0 | AB38: 0 | AC38: =E38*7-N38 -> 42 | AD38: =ROUND(((AA38*AB38*AC38)/M38),0) -> 0 | AE38: =S38+W38+AA38 -> 28 | AF38: =ROUND( ((SUM(I37:I38)*1)/SUM(Q37:Q38)*100),1) -> #DIV/0! | AG38: =K38*M38 -> 905.4928 | AH38: =S38*U38+W38*Y38+AA38*AC38 -> 1176 | AI38: =IF(AH38=0,0,AG38/AH38) -> 0.76997687
B39: Nov | C39: 46342 | D39: 47 | E39: 6 | F39: 5 | G39: =(G38+H38-I38+K34) -> 9924 | H39: 0 | I39: ='B-JCI2 RH'!AE263 -> 3780 | J39: =IF(I39=0,"N/S",ROUND( ( ((G39) * 1)/I39)*F39,1)) -> 13.1 | K39: =V39+Z39+AD39 -> 3056 | L39: 0 | M39: ='B-JCI2 RH'!$D$295 -> 0.2963 | N39: 0 | O39: 11 | Q39: 0 | R39: =IF(F39=0,0,ROUND(I39/F39,0)) -> 756 | S39: 14 | T39: 0.77 | U39: =E39*7-N39 -> 42 | V39: =ROUND(((S39*T39*U39)/M39),0) -> 1528 | W39: =S39 -> 14 | X39: 0.77 | Y39: =U39 -> 42 | Z39: =ROUND(((W39*X39*Y39)/M39),0) -> 1528 | AA39: 0 | AB39: 0 | AC39: =E39*7-N39 -> 42 | AD39: =ROUND(((AA39*AB39*AC39)/M39),0) -> 0 | AE39: =S39+W39+AA39 -> 28 | AF39: =ROUND( ((SUM(I38:I39)*1)/SUM(Q38:Q39)*100),1) -> #DIV/0! | AG39: =K39*M39 -> 905.4928 | AH39: =S39*U39+W39*Y39+AA39*AC39 -> 1176 | AI39: =IF(AH39=0,0,AG39/AH39) -> 0.76997687
B40: Nov | C40: 46349 | D40: 48 | E40: 6 | F40: 5 | G40: =(G39+H39-I39+K35) -> 9200 | H40: 0 | I40: ='B-JCI2 RH'!AF263 -> 3780 | J40: =IF(I40=0,"N/S",ROUND( ( ((G40) * 1)/I40)*F40,1)) -> 12.2 | K40: =V40+Z40+AD40 -> 3056 | L40: 0 | M40: ='B-JCI2 RH'!$D$295 -> 0.2963 | N40: 0 | O40: 11 | Q40: 0 | R40: =IF(F40=0,0,ROUND(I40/F40,0)) -> 756 | S40: 14 | T40: 0.77 | U40: =E40*7-N40 -> 42 | V40: =ROUND(((S40*T40*U40)/M40),0) -> 1528 | W40: =S40 -> 14 | X40: 0.77 | Y40: =U40 -> 42 | Z40: =ROUND(((W40*X40*Y40)/M40),0) -> 1528 | AA40: 0 | AB40: 0 | AC40: =E40*7-N40 -> 42 | AD40: =ROUND(((AA40*AB40*AC40)/M40),0) -> 0 | AE40: =S40+W40+AA40 -> 28 | AF40: =ROUND( ((SUM(I39:I40)*1)/SUM(Q39:Q40)*100),1) -> #DIV/0! | AG40: =K40*M40 -> 905.4928 | AH40: =S40*U40+W40*Y40+AA40*AC40 -> 1176 | AI40: =IF(AH40=0,0,AG40/AH40) -> 0.76997687
B41: Nov | C41: 46356 | D41: 49 | E41: 6 | F41: 5 | G41: =(G40+H40-I40+K36) -> 8476 | H41: 0 | I41: ='B-JCI2 RH'!AG263 -> 3480 | J41: =IF(I41=0,"N/S",ROUND( ( ((G41) * 1)/I41)*F41,1)) -> 12.2 | K41: =V41+Z41+AD41 -> 3056 | L41: 0 | M41: ='B-JCI2 RH'!$D$295 -> 0.2963 | N41: 0 | O41: 11 | Q41: 0 | R41: =IF(F41=0,0,ROUND(I41/F41,0)) -> 696 | S41: 14 | T41: 0.77 | U41: =E41*7-N41 -> 42 | V41: =ROUND(((S41*T41*U41)/M41),0) -> 1528 | W41: =S41 -> 14 | X41: 0.77 | Y41: =U41 -> 42 | Z41: =ROUND(((W41*X41*Y41)/M41),0) -> 1528 | AA41: 0 | AB41: 0 | AC41: =E41*7-N41 -> 42 | AD41: =ROUND(((AA41*AB41*AC41)/M41),0) -> 0 | AE41: =S41+W41+AA41 -> 28 | AF41: =ROUND( ((SUM(I40:I41)*1)/SUM(Q40:Q41)*100),1) -> #DIV/0! | AG41: =K41*M41 -> 905.4928 | AH41: =S41*U41+W41*Y41+AA41*AC41 -> 1176 | AI41: =IF(AH41=0,0,AG41/AH41) -> 0.76997687
B42: Dec | C42: 46363 | D42: 50 | E42: 6 | F42: 5 | G42: =(G41+H41-I41+K37) -> 8052 | H42: 0 | I42: ='B-JCI2 RH'!AH263 -> 3810 | J42: =IF(I42=0,"N/S",ROUND( ( ((G42) * 1)/I42)*F42,1)) -> 10.6 | K42: =V42+Z42+AD42 -> 3056 | L42: 0 | M42: ='B-JCI2 RH'!$D$295 -> 0.2963 | N42: 0 | O42: 12 | Q42: 0 | R42: =IF(F42=0,0,ROUND(I42/F42,0)) -> 762 | S42: 14 | T42: 0.77 | U42: =E42*7-N42 -> 42 | V42: =ROUND(((S42*T42*U42)/M42),0) -> 1528 | W42: =S42 -> 14 | X42: 0.77 | Y42: =U42 -> 42 | Z42: =ROUND(((W42*X42*Y42)/M42),0) -> 1528 | AA42: 0 | AB42: 0 | AC42: =E42*7-N42 -> 42 | AD42: =ROUND(((AA42*AB42*AC42)/M42),0) -> 0 | AE42: =S42+W42+AA42 -> 28 | AF42: =ROUND( ((SUM(I41:I42)*1)/SUM(Q41:Q42)*100),1) -> #DIV/0! | AG42: =K42*M42 -> 905.4928 | AH42: =S42*U42+W42*Y42+AA42*AC42 -> 1176 | AI42: =IF(AH42=0,0,AG42/AH42) -> 0.76997687
...

Sheet B-JCI2 RH
B1: Screen Id | C1: PPSP0020 | D1: Machine Name | E1: EGPSPC024 | F1: Printed On | H1: 2026-05-10 11:00:59
D2: 2 | E2: 3 | F2: 4 | G2: 5 | H2: 6 | I2: 7 | J2: 8 | K2: 9 | L2: 10 | M2: 11 | N2: 12 | O2: 13 | P2: 14 | Q2: 15 | R2: 16 | S2: 17 | T2: 18 | U2: 19 | V2: 20 | W2: 21 | X2: 22 | Y2: 23 | Z2: 24 | AA2: 25 | AB2: 26 | AC2: 27 | AD2: 28 | AE2: 29 | AF2: 30 | AG2: 31 | AH2: 32 | AI2: 33 | AJ2: 34
B3: Bottom Level MPS[JCI] | N3: Starting Week Col | O3: 37
D4: 2 | E4: 3 | F4: 4 | N4: Var Row | O4: 10
B5: Section Code | C5: PORT SAID MANUFACTURING(SAID) | G5: Safety Weeks | I5: 1 | K5: Transit Weeks | M5: 4 | N5: Working HRS Row | O5: 291 | AK5: 0 | AL5: 0 | AM5: 0 | AN5: 2709 | AO5: 2709 | AP5: 2709 | AQ5: 3271 | AR5: 3271 | AS5: 2617 | AT5: 3271 | AU5: 3108 | AV5: 3108 | AW5: 3108 | AX5: 3108 | AY5: 2487 | AZ5: 2214 | BA5: 2214 | BB5: 2214 | BC5: 2487 | BD5: 2487 | BE5: 2487 | BF5: 2487 | BG5: 2487 | BH5: 2487 | BI5: 2487 | BJ5: 2487 | BK5: 2487 | BL5: 2473 | BM5: 2473 | BN5: 4514 | BO5: 0 | BP5: 0 | BQ5: 0 | BR5: 0 | BS5: 2041 | BT5: 2041 | BU5: 2041 | BV5: 2041 | BW5: 2041 | BX5: 2041 | BY5: 2041 | BZ5: 2041 | CA5: 2041 | CB5: 2041 | CC5: 2041
B6: MPS ID | C6: JCI2 RH_VOLVO RH_W20/26_W44/27_01 | G6: MPS Type | I6: Oblige | K6: Target Efficiency | M6: 0.92 | N6: Inv Row | O6: 14
B7: Facility | C7: JCI2 RH | G7: Car Model | I7: VOLVO RH | K7: Working Hours | M7: 7 | N7: Pln Row | O7: 16
B8: From Date | C8: 2026/05/11 | D8: To Date | E8: 2027/11/07 | G8: Total Weeks | I8: 78 | K8: offset Weeks | M8: 4 | N8: Weeks to Cover | O8: 5
B9: Facility (DOS) | C9: 10 | D9: Plan Suggestion By | E9: OPERATOR_EFFICIENCY | G9: Week Plan Offset | I9: 99 | K9: Assy Std.Hr. | M9: 0.297 | N9: Target Eff. | O9: -0.01
C10: Efficency Var: | D10: =D286-D265 -> -0.0048545113 | E10: =E286-E265 -> -0.025973935 | F10: =F286-F265 -> -0.0027220551 | G10: =G286-G265 -> 0.76993444 | H10: =H286-H265 -> 0.77008296 | I10: =I286-I265 -> 0.77008296 | J10: =J286-J265 -> 0.77008296 | K10: =K286-K265 -> 0.76993444 | ... CC10: =CC286-CC265 -> 0.76997687
A11: Product No. | B11: Category | C11: Plan Date | D11: 11/05 | E11: 18/05 | F11: 25/05 | G11: 01/06 | H11: 08/06 | I11: 15/06 | J11: 22/06 | K11: 29/06 | L11: 06/07 | M11: 13/07 | N11: 20/07 | O11: 27/07 | P11: 03/08 | Q11: 10/08 | R11: 17/08 | S11: 24/08 | T11: 31/08 | U11: 07/09 | V11: 14/09 | W11: 21/09 | X11: 28/09 | Y11: 05/10 | Z11: 12/10 | AA11: 19/10 | AB11: 26/10 | AC11: 02/11 | AD11: 09/11 | AE11: 16/11 | AF11: 23/11 | AG11: 30/11 | AH11: 07/12 | AI11: 14/12 | AJ11: 21/12 | AK11: 28/12 | AL11: 04/01 | AM11: 11/01 | AN11: 18/01 | AO11: 25/01 | AP11: 01/02 | AQ11: 08/02 | AR11: 15/02 | AS11: 22/02 | AT11: 01/03 | AU11: 08/03 | AV11: 15/03 | AW11: 22/03 | AX11: 29/03 | AY11: 05/04 | AZ11: 12/04 | BA11: 19/04 | BB11: 26/04 | BC11: 03/05 | BD11: 10/05 | BE11: 17/05 | BF11: 24/05 | BG11: 31/05 | BH11: 07/06 | BI11: 14/06 | BJ11: 21/06 | BK11: 28/06 | BL11: 05/07 | BM11: 12/07 | BN11: 19/07 | BO11: 26/07 | BP11: 02/08 | BQ11: 09/08 | BR11: 16/08 | BS11: 23/08 | BT11: 30/08 | BU11: 06/09 | BV11: 13/09 | BW11: 20/09 | BX11: 27/09 | BY11: 04/10 | BZ11: 11/10 | CA11: 18/10 | CB11: 25/10 | CC11: 01/11
C12: Week No | D12: 20 | E12: 21 | F12: 22 | G12: 23 | H12: 24 | I12: 25 | J12: 26 | K12: 27 | L12: 28 | M12: 29 | N12: 30 | O12: 31 | P12: 32 | Q12: 33 | R12: 34 | S12: 35 | T12: 36 | U12: 37 | V12: 38 | W12: 39 | X12: 40 | Y12: 41 | Z12: 42 | AA12: 43 | AB12: 44 | AC12: 45 | AD12: 46 | AE12: 47 | AF12: 48 | AG12: 49 | AH12: 50 | AI12: 51 | AJ12: 52 | AK12: 53 | AL12: 01 | AM12: 02 | AN12: 03 | AO12: 04 | AP12: 05 | AQ12: 06 | AR12: 07 | AS12: 08 | AT12: 09 | AU12: 10 | AV12: 11 | AW12: 12 | AX12: 13 | AY12: 14 | AZ12: 15 | BA12: 16 | BB12: 17 | BC12: 18 | BD12: 19 | BE12: 20 | BF12: 21 | BG12: 22 | BH12: 23 | BI12: 24 | BJ12: 25 | BK12: 26 | BL12: 27 | BM12: 28 | BN12: 29 | BO12: 30 | BP12: 31 | BQ12: 32 | BR12: 33 | BS12: 34 | BT12: 35 | BU12: 36 | BV12: 37 | BW12: 38 | BX12: 39 | BY12: 40 | BZ12: 41 | CA12: 42 | CB12: 43 | CC12: 44
B13: =SUM(D17:AJ17)/SUM($D$263:$AJ$263) -> 0 | C13: Days@Customer | D13: 5 | E13: 5 | F13: 5 | G13: 5 | H13: 5 | I13: 5 | J13: 5 | K13: 5 | L13: 5 | M13: 5 | N13: 5 | O13: 5 | P13: 5 | Q13: 5 | R13: 5 | S13: 5 | T13: 5 | U13: 5 | V13: 5 | W13: 5 | X13: 5 | Y13: 5 | Z13: 5 | AA13: 5 | AB13: 5 | AC13: 5 | AD13: 5 | AE13: 5 | AF13: 5 | AG13: 5 | AH13: 5 | AI13: 5 | AJ13: 5 | AK13: 5 | AL13: 5 | AM13: 5 | AN13: 5 | AO13: 5 | AP13: 5 | AQ13: 5 | AR13: 5 | AS13: 5 | AT13: 5 | AU13: 5 | AV13: 5 | AW13: 5 | AX13: 5 | AY13: 5 | AZ13: 5 | BA13: 5 | BB13: 5 | BC13: 5 | BD13: 5 | BE13: 5 | BF13: 5 | BG13: 5 | BH13: 5 | BI13: 5 | BJ13: 5 | BK13: 5 | BL13: 5 | BM13: 5 | BN13: 5 | BO13: 5 | BP13: 5 | BQ13: 5 | BR13: 5 | BS13: 5 | BT13: 5 | BU13: 5 | BV13: 5 | BW13: 5 | BX13: 5 | BY13: 5 | BZ13: 5 | CA13: 5 | CB13: 5 | CC13: 5
A14: 32248194 | B14: C | C14: Invt Qty | D14: =IFERROR(VLOOKUP(A14,OS!$A:$B,2,0),0) -> 0 | E14: =(D14+D15-D17) -> 0 | F14: =(E14+E15-E17) -> 0 | G14: =(F14+F15-F17) -> 0 | H14: =(G14+G15-G17) -> 0 | I14: =(H14+H15-H17+D16) -> 0 | J14: =(I14+I15-I17+E16) -> 0 | K14: =(J14+J15-J17+F16) -> 0 | L14: =(K14+K15-K17+G16) -> 0 | M14: =(L14+L15-L17+H16) -> 0 | N14: =(M14+M15-M17+I16) -> 0 | O14: =(N14+N15-N17+J16) -> 0 | P14: =(O14+O15-O17+K16) -> 0 | ... CC14: =(CB14+CB15-CB17+BX16) -> 0
A15: Tran. Pr. | B15: 0 | C15: WIP | D15: =IFERROR(VLOOKUP(A14,WIP!$A:$B,2,0),0) -> 0 | E15: 0 | F15: 0 | G15: 0 | H15: 0 | I15: 0 | J15: 0 | K15: 0 | L15: 0 | M15: 0 | N15: 0 | O15: 0 | P15: 0 | Q15: 0 | R15: 0 | S15: 0 | T15: 0 | U15: 0 | V15: 0 | W15: 0 | X15: 0 | Y15: 0 | Z15: 0 | AA15: 0 | AB15: 0 | AC15: 0 | AD15: 0 | AE15: 0 | AF15: 0 | AG15: 0 | AH15: 0 | AI15: 0 | AJ15: 0 | AK15: 0 | AL15: 0 | AM15: 0 | AN15: 0 | AO15: 0 | AP15: 0 | AQ15: 0 | AR15: 0 | AS15: 0 | AT15: 0 | AU15: 0 | AV15: 0 | AW15: 0 | AX15: 0 | AY15: 0 | AZ15: 0 | BA15: 0 | BB15: 0 | BC15: 0 | BD15: 0 | BE15: 0 | BF15: 0 | BG15: 0 | BH15: 0 | BI15: 0 | BJ15: 0 | BK15: 0 | BL15: 0 | BM15: 0 | BN15: 0 | BO15: 0 | BP15: 0 | BQ15: 0 | BR15: 0 | BS15: 0 | BT15: 0 | BU15: 0 | BV15: 0 | BW15: 0 | BX15: 0 | BY15: 0 | BZ15: 0 | CA15: 0 | CB15: 0 | CC15: 0
A16: Assy ST. | B16: 0 | C16: Plan | D16: =IFERROR(VLOOKUP($A14,Plan!$A:B,D$4,0),0) -> 0 | E16: =IFERROR(VLOOKUP($A14,Plan!$A:C,E$4,0),0) -> 0 | F16: =IFERROR(VLOOKUP($A14,Plan!$A:D,F$4,0),0) -> 0 | G16: 0 | H16: 0 | I16: 0 | J16: 0 | K16: 0 | L16: 0 | M16: 0 | N16: 0 | O16: 0 | P16: 0 | Q16: 0 | R16: 0 | S16: 0 | T16: 0 | U16: 0 | V16: 0 | W16: 0 | X16: 0 | Y16: 0 | Z16: 0 | AA16: 0 | AB16: 0 | AC16: 0 | AD16: 0 | AE16: 0 | AF16: 0 | AG16: 0 | AH16: 0 | AI16: 0 | AJ16: 0 | AK16: 0 | AL16: 0 | AM16: 0 | AN16: 0 | AO16: 0 | AP16: 0 | AQ16: 0 | AR16: 0 | AS16: 0 | AT16: 0 | AU16: 0 | AV16: 0 | AW16: 0 | AX16: 0 | AY16: 0 | AZ16: 0 | BA16: 0 | BB16: 0 | BC16: 0 | BD16: 0 | BE16: 0 | BF16: 0 | BG16: 0 | BH16: 0 | BI16: 0 | BJ16: 0 | BK16: 0 | BL16: 0 | BM16: 0 | BN16: 0 | BO16: 0 | BP16: 0 | BQ16: 0 | BR16: 0 | BS16: 0 | BT16: 0 | BU16: 0 | BV16: 0 | BW16: 0 | BX16: 0 | BY16: 0 | BZ16: 0 | CA16: 0 | CB16: 0 | CC16: 0
A17: Lead Prep ST. | B17: 0 | C17: Sales | D17: =IFERROR(VLOOKUP($A14,Sales!$A:B,D$2,0),0) -> 0 | E17: =IFERROR(VLOOKUP($A14,Sales!$A:C,E$2,0),0) -> 0 | F17: =IFERROR(VLOOKUP($A14,Sales!$A:D,F$2,0),0) -> 0 | G17: =IFERROR(VLOOKUP($A14,Sales!$A:E,G$2,0),0) -> 0 | H17: =IFERROR(VLOOKUP($A14,Sales!$A:F,H$2,0),0) -> 0 | I17: =IFERROR(VLOOKUP($A14,Sales!$A:G,I$2,0),0) -> 0 | J17: =IFERROR(VLOOKUP($A14,Sales!$A:H,J$2,0),0) -> 0 | K17: =IFERROR(VLOOKUP($A14,Sales!$A:I,K$2,0),0) -> 0 | L17: =IFERROR(VLOOKUP($A14,Sales!$A:J,L$2,0),0) -> 0 | M17: =IFERROR(VLOOKUP($A14,Sales!$A:K,M$2,0),0) -> 0 | N17: =IFERROR(VLOOKUP($A14,Sales!$A:L,N$2,0),0) -> 0 | O17: =IFERROR(VLOOKUP($A14,Sales!$A:M,O$2,0),0) -> 0 | P17: =IFERROR(VLOOKUP($A14,Sales!$A:N,P$2,0),0) -> 0 | Q17: =IFERROR(VLOOKUP($A14,Sales!$A:O,Q$2,0),0) -> 0 | R17: =IFERROR(VLOOKUP($A14,Sales!$A:P,R$2,0),0) -> 0 | S17: =IFERROR(VLOOKUP($A14,Sales!$A:Q,S$2,0),0) -> 0 | T17: =IFERROR(VLOOKUP($A14,Sales!$A:R,T$2,0),0) -> 0 | U17: =IFERROR(VLOOKUP($A14,Sales!$A:S,U$2,0),0) -> 0 | V17: =IFERROR(VLOOKUP($A14,Sales!$A:T,V$2,0),0) -> 0 | W17: =IFERROR(VLOOKUP($A14,Sales!$A:U,W$2,0),0) -> 0 | X17: =IFERROR(VLOOKUP($A14,Sales!$A:V,X$2,0),0) -> 0 | Y17: =IFERROR(VLOOKUP($A14,Sales!$A:W,Y$2,0),0) -> 0 | Z17: =IFERROR(VLOOKUP($A14,Sales!$A:X,Z$2,0),0) -> 0 | AA17: =IFERROR(VLOOKUP($A14,Sales!$A:Y,AA$2,0),0) -> 0 | AB17: =IFERROR(VLOOKUP($A14,Sales!$A:Z,AB$2,0),0) -> 0 | AC17: =IFERROR(VLOOKUP($A14,Sales!$A:AA,AC$2,0),0) -> 0 | AD17: =IFERROR(VLOOKUP($A14,Sales!$A:AB,AD$2,0),0) -> 0 | AE17: =IFERROR(VLOOKUP($A14,Sales!$A:AC,AE$2,0),0) -> 0 | AF17: =IFERROR(VLOOKUP($A14,Sales!$A:AD,AF$2,0),0) -> 0 | AG17: =IFERROR(VLOOKUP($A14,Sales!$A:AE,AG$2,0),0) -> 0 | AH17: =IFERROR(VLOOKUP($A14,Sales!$A:AF,AH$2,0),0) -> 0 | AI17: =IFERROR(VLOOKUP($A14,Sales!$A:AG,AI$2,0),0) -> 0 | AJ17: =IFERROR(VLOOKUP($A14,Sales!$A:AH,AJ$2,0),0) -> 0 | AK17: =CEILING(AK$5*$B13,1) -> 0 | AL17: =CEILING(AL$5*$B13,1) -> 0 | AM17: =CEILING(AM$5*$B13,1) -> 0 | AN17: =CEILING(AN$5*$B13,1) -> 0 | AO17: =CEILING(AO$5*$B13,1) -> 0 | AP17: =CEILING(AP$5*$B13,1) -> 0 | AQ17: =CEILING(AQ$5*$B13,1) -> 0 | AR17: =CEILING(AR$5*$B13,1) -> 0 | ... CC17: =CEILING(CC$5*$B13,1) -> 0
A18: Total ST. | B18: 0 | C18: Days | D18: =IF(D17=0,0, ROUND(D14 * 1/D17* D$13,1)) -> 0 | E18: =IF(E17=0,0, ROUND(E14 * 1/E17* E$13,1)) -> 0 | F18: =IF(F17=0,0, ROUND(F14 * 1/F17* F$13,1)) -> 0 | G18: =IF(G17=0,0, ROUND(G14 * 1/G17* G$13,1)) -> 0 | H18: =IF(H17=0,0, ROUND(H14 * 1/H17* H$13,1)) -> 0 | I18: =IF(I17=0,0, ROUND(I14 * 1/I17* I$13,1)) -> 0 | J18: =IF(J17=0,0, ROUND(J14 * 1/J17* J$13,1)) -> 0 | K18: =IF(K17=0,0, ROUND(K14 * 1/K17* K$13,1)) -> 0 | ... CC18: =IF(CC17=0,0, ROUND(CC14 * 1/CC17* CC$13,1)) -> 0
A19: 1 | B19: 1 | C19: 0 | D19: =D16/$B19 -> 0 | E19: =E16/$B19 -> 0 | F19: =F16/$B19 -> 0 | G19: =G16/$B19 -> 0 | H19: =H16/$B19 -> 0 | I19: =I16/$B19 -> 0 | J19: =J16/$B19 -> 0 | K19: =K16/$B19 -> 0 | ... CC19: =CC16/$B19 -> 0
B20: =SUM(D24:AJ24)/SUM($D$263:$AJ$263) -> 0 | C20: Shortage | D20: =D14-D17 -> 0 | E20: =E14-E17 -> 0 | F20: =F14-F17 -> 0 | G20: =G14-G17 -> 0 | H20: =H14-H17 -> 0 | I20: =I14-I17 -> 0 | J20: =J14-J17 -> 0 | K20: =K14-K17 -> 0 | ... CC20: =CC14-CC17 -> 0
A21: 32248195 | B21: C | C21: Invt Qty | D21: =IFERROR(VLOOKUP(A21,OS!$A:$B,2,0),0) -> 0 | E21: =(D21+D22-D24) -> 0 | F21: =(E21+E22-E24) -> 0 | G21: =(F21+F22-F24) -> 0 | H21: =(G21+G22-G24) -> 0 | I21: =(H21+H22-H24+D23) -> 0 | J21: =(I21+I22-I24+E23) -> 0 | K21: =(J21+J22-J24+F23) -> 0 | L21: =(K21+K22-K24+G23) -> 0 | M21: =(L21+L22-L24+H23) -> 0 | N21: =(M21+M22-M24+I23) -> 0 | O21: =(N21+N22-N24+J23) -> 0 | P21: =(O21+O22-O24+K23) -> 0 | ... CC21: =(CB21+CB22-CB24+BX23) -> 0
A22: Tran. Pr. | B22: 0 | C22: WIP | D22: =IFERROR(VLOOKUP(A21,WIP!$A:$B,2,0),0) -> 0 | E22: 0 | F22: 0 | G22: 0 | H22: 0 | I22: 0 | J22: 0 | K22: 0 | L22: 0 | M22: 0 | N22: 0 | O22: 0 | P22: 0 | Q22: 0 | R22: 0 | S22: 0 | T22: 0 | U22: 0 | V22: 0 | W22: 0 | X22: 0 | Y22: 0 | Z22: 0 | AA22: 0 | AB22: 0 | AC22: 0 | AD22: 0 | AE22: 0 | AF22: 0 | AG22: 0 | AH22: 0 | AI22: 0 | AJ22: 0 | AK22: 0 | AL22: 0 | AM22: 0 | AN22: 0 | AO22: 0 | AP22: 0 | AQ22: 0 | AR22: 0 | AS22: 0 | AT22: 0 | AU22: 0 | AV22: 0 | AW22: 0 | AX22: 0 | AY22: 0 | AZ22: 0 | BA22: 0 | BB22: 0 | BC22: 0 | BD22: 0 | BE22: 0 | BF22: 0 | BG22: 0 | BH22: 0 | BI22: 0 | BJ22: 0 | BK22: 0 | BL22: 0 | BM22: 0 | BN22: 0 | BO22: 0 | BP22: 0 | BQ22: 0 | BR22: 0 | BS22: 0 | BT22: 0 | BU22: 0 | BV22: 0 | BW22: 0 | BX22: 0 | BY22: 0 | BZ22: 0 | CA22: 0 | CB22: 0 | CC22: 0
A23: Assy ST. | B23: 0 | C23: Plan | D23: =IFERROR(VLOOKUP($A21,Plan!$A:B,D$4,0),0) -> 0 | E23: =IFERROR(VLOOKUP($A21,Plan!$A:C,E$4,0),0) -> 0 | F23: =IFERROR(VLOOKUP($A21,Plan!$A:D,F$4,0),0) -> 0 | G23: 0 | H23: 0 | I23: 0 | J23: 0 | K23: 0 | L23: 0 | M23: 0 | N23: 0 | O23: 0 | P23: 0 | Q23: 0 | R23: 0 | S23: 0 | T23: 0 | U23: 0 | V23: 0 | W23: 0 | X23: 0 | Y23: 0 | Z23: 0 | AA23: 0 | AB23: 0 | AC23: 0 | AD23: 0 | AE23: 0 | AF23: 0 | AG23: 0 | AH23: 0 | AI23: 0 | AJ23: 0 | AK23: 0 | AL23: 0 | AM23: 0 | AN23: 0 | AO23: 0 | AP23: 0 | AQ23: 0 | AR23: 0 | AS23: 0 | AT23: 0 | AU23: 0 | AV23: 0 | AW23: 0 | AX23: 0 | AY23: 0 | AZ23: 0 | BA23: 0 | BB23: 0 | BC23: 0 | BD23: 0 | BE23: 0 | BF23: 0 | BG23: 0 | BH23: 0 | BI23: 0 | BJ23: 0 | BK23: 0 | BL23: 0 | BM23: 0 | BN23: 0 | BO23: 0 | BP23: 0 | BQ23: 0 | BR23: 0 | BS23: 0 | BT23: 0 | BU23: 0 | BV23: 0 | BW23: 0 | BX23: 0 | BY23: 0 | BZ23: 0 | CA23: 0 | CB23: 0 | CC23: 0
A24: Lead Prep ST. | B24: 0 | C24: Sales | D24: =IFERROR(VLOOKUP($A21,Sales!$A:B,D$2,0),0) -> 0 | E24: =IFERROR(VLOOKUP($A21,Sales!$A:C,E$2,0),0) -> 0 | F24: =IFERROR(VLOOKUP($A21,Sales!$A:D,F$2,0),0) -> 0 | G24: =IFERROR(VLOOKUP($A21,Sales!$A:E,G$2,0),0) -> 0 | H24: =IFERROR(VLOOKUP($A21,Sales!$A:F,H$2,0),0) -> 0 | I24: =IFERROR(VLOOKUP($A21,Sales!$A:G,I$2,0),0) -> 0 | J24: =IFERROR(VLOOKUP($A21,Sales!$A:H,J$2,0),0) -> 0 | K24: =IFERROR(VLOOKUP($A21,Sales!$A:I,K$2,0),0) -> 0 | L24: =IFERROR(VLOOKUP($A21,Sales!$A:J,L$2,0),0) -> 0 | M24: =IFERROR(VLOOKUP($A21,Sales!$A:K,M$2,0),0) -> 0 | N24: =IFERROR(VLOOKUP($A21,Sales!$A:L,N$2,0),0) -> 0 | O24: =IFERROR(VLOOKUP($A21,Sales!$A:M,O$2,0),0) -> 0 | P24: =IFERROR(VLOOKUP($A21,Sales!$A:N,P$2,0),0) -> 0 | Q24: =IFERROR(VLOOKUP($A21,Sales!$A:O,Q$2,0),0) -> 0 | R24: =IFERROR(VLOOKUP($A21,Sales!$A:P,R$2,0),0) -> 0 | S24: =IFERROR(VLOOKUP($A21,Sales!$A:Q,S$2,0),0) -> 0 | T24: =IFERROR(VLOOKUP($A21,Sales!$A:R,T$2,0),0) -> 0 | U24: =IFERROR(VLOOKUP($A21,Sales!$A:S,U$2,0),0) -> 0 | V24: =IFERROR(VLOOKUP($A21,Sales!$A:T,V$2,0),0) -> 0 | W24: =IFERROR(VLOOKUP($A21,Sales!$A:U,W$2,0),0) -> 0 | X24: =IFERROR(VLOOKUP($A21,Sales!$A:V,X$2,0),0) -> 0 | Y24: =IFERROR(VLOOKUP($A21,Sales!$A:W,Y$2,0),0) -> 0 | Z24: =IFERROR(VLOOKUP($A21,Sales!$A:X,Z$2,0),0) -> 0 | AA24: =IFERROR(VLOOKUP($A21,Sales!$A:Y,AA$2,0),0) -> 0 | AB24: =IFERROR(VLOOKUP($A21,Sales!$A:Z,AB$2,0),0) -> 0 | AC24: =IFERROR(VLOOKUP($A21,Sales!$A:AA,AC$2,0),0) -> 0 | AD24: =IFERROR(VLOOKUP($A21,Sales!$A:AB,AD$2,0),0) -> 0 | AE24: =IFERROR(VLOOKUP($A21,Sales!$A:AC,AE$2,0),0) -> 0 | AF24: =IFERROR(VLOOKUP($A21,Sales!$A:AD,AF$2,0),0) -> 0 | AG24: =IFERROR(VLOOKUP($A21,Sales!$A:AE,AG$2,0),0) -> 0 | AH24: =IFERROR(VLOOKUP($A21,Sales!$A:AF,AH$2,0),0) -> 0 | AI24: =IFERROR(VLOOKUP($A21,Sales!$A:AG,AI$2,0),0) -> 0 | AJ24: =IFERROR(VLOOKUP($A21,Sales!$A:AH,AJ$2,0),0) -> 0 | AK24: =CEILING(AK$5*$B20,1) -> 0 | AL24: =CEILING(AL$5*$B20,1) -> 0 | AM24: =CEILING(AM$5*$B20,1) -> 0 | AN24: =CEILING(AN$5*$B20,1) -> 0 | AO24: =CEILING(AO$5*$B20,1) -> 0 | AP24: =CEILING(AP$5*$B20,1) -> 0 | AQ24: =CEILING(AQ$5*$B20,1) -> 0 | AR24: =CEILING(AR$5*$B20,1) -> 0 | ... CC24: =CEILING(CC$5*$B20,1) -> 0
A25: Total ST. | B25: 0 | C25: Days | D25: =IF(D24=0,0, ROUND(D21 * 1/D24* D$13,1)) -> 0 | E25: =IF(E24=0,0, ROUND(E21 * 1/E24* E$13,1)) -> 0 | F25: =IF(F24=0,0, ROUND(F21 * 1/F24* F$13,1)) -> 0 | G25: =IF(G24=0,0, ROUND(G21 * 1/G24* G$13,1)) -> 0 | H25: =IF(H24=0,0, ROUND(H21 * 1/H24* H$13,1)) -> 0 | I25: =IF(I24=0,0, ROUND(I21 * 1/I24* I$13,1)) -> 0 | J25: =IF(J24=0,0, ROUND(J21 * 1/J24* J$13,1)) -> 0 | K25: =IF(K24=0,0, ROUND(K21 * 1/K24* K$13,1)) -> 0 | ... CC25: =IF(CC24=0,0, ROUND(CC21 * 1/CC24* CC$13,1)) -> 0
A26: 1 | B26: 1 | C26: 0 | D26: =D23/$B26 -> 0 | E26: =E23/$B26 -> 0 | F26: =F23/$B26 -> 0 | G26: =G23/$B26 -> 0 | H26: =H23/$B26 -> 0 | I26: =I23/$B26 -> 0 | J26: =J23/$B26 -> 0 | K26: =K23/$B26 -> 0 | ... CC26: =CC23/$B26 -> 0
B27: =SUM(D31:AJ31)/SUM($D$263:$AJ$263) -> 0.0087894917 | C27: Shortage | D27: =D21-D24 -> 0 | E27: =E21-E24 -> 0 | F27: =F21-F24 -> 0 | G27: =G21-G24 -> 0 | H27: =H21-H24 -> 0 | I27: =I21-I24 -> 0 | J27: =J21-J24 -> 0 | K27: =K21-K24 -> 0 | ... CC27: =CC21-CC24 -> 0
A28: 4172784 | B28: C | C28: Invt Qty | D28: =IFERROR(VLOOKUP(A28,OS!$A:$B,2,0),0) -> 657 | E28: =(D28+D29-D31) -> 657 | F28: =(E28+E29-E31) -> 557 | G28: =(F28+F29-F31) -> 557 | H28: =(G28+G29-G31) -> 557 | I28: =(H28+H29-H31+D30) -> 557 | J28: =(I28+I29-I31+E30) -> 557 | K28: =(J28+J29-J31+F30) -> 557 | L28: =(K28+K29-K31+G30) -> 457 | M28: =(L28+L29-L31+H30) -> 457 | N28: =(M28+M29-M31+I30) -> 457 | O28: =(N28+N29-N31+J30) -> 457 | P28: =(O28+O29-O31+K30) -> 457 | ... CC28: =(CB28+CB29-CB31+BX30) -> -1082
A29: Tran. Pr. | B29: 7.57311 | C29: WIP | D29: =IFERROR(VLOOKUP(A28,WIP!$A:$B,2,0),0) -> 0 | E29: 0 | F29: 0 | G29: 0 | H29: 0 | I29: 0 | J29: 0 | K29: 0 | L29: 0 | M29: 0 | N29: 0 | O29: 0 | P29: 0 | Q29: 0 | R29: 0 | S29: 0 | T29: 0 | U29: 0 | V29: 0 | W29: 0 | X29: 0 | Y29: 0 | Z29: 0 | AA29: 0 | AB29: 0 | AC29: 0 | AD29: 0 | AE29: 0 | AF29: 0 | AG29: 0 | AH29: 0 | AI29: 0 | AJ29: 0 | AK29: 0 | AL29: 0 | AM29: 0 | AN29: 0 | AO29: 0 | AP29: 0 | AQ29: 0 | AR29: 0 | AS29: 0 | AT29: 0 | AU29: 0 | AV29: 0 | AW29: 0 | AX29: 0 | AY29: 0 | AZ29: 0 | BA29: 0 | BB29: 0 | BC29: 0 | BD29: 0 | BE29: 0 | BF29: 0 | BG29: 0 | BH29: 0 | BI29: 0 | BJ29: 0 | BK29: 0 | BL29: 0 | BM29: 0 | BN29: 0 | BO29: 0 | BP29: 0 | BQ29: 0 | BR29: 0 | BS29: 0 | BT29: 0 | BU29: 0 | BV29: 0 | BW29: 0 | BX29: 0 | BY29: 0 | BZ29: 0 | CA29: 0 | CB29: 0 | CC29: 0
A30: Assy ST. | B30: 0.229 | C30: Plan | D30: =IFERROR(VLOOKUP($A28,Plan!$A:B,D$4,0),0) -> 0 | E30: =IFERROR(VLOOKUP($A28,Plan!$A:C,E$4,0),0) -> 0 | F30: =IFERROR(VLOOKUP($A28,Plan!$A:D,F$4,0),0) -> 0 | G30: 0 | H30: 0 | I30: 0 | J30: 0 | K30: 0 | L30: 0 | M30: 0 | N30: 0 | O30: 0 | P30: 0 | Q30: 0 | R30: 0 | S30: 0 | T30: 0 | U30: 0 | V30: 0 | W30: 0 | X30: 0 | Y30: 0 | Z30: 0 | AA30: 0 | AB30: 0 | AC30: 0 | AD30: 0 | AE30: 0 | AF30: 0 | AG30: 0 | AH30: 0 | AI30: 0 | AJ30: 0 | AK30: 0 | AL30: 0 | AM30: 0 | AN30: 0 | AO30: 0 | AP30: 0 | AQ30: 0 | AR30: 0 | AS30: 0 | AT30: 0 | AU30: 0 | AV30: 0 | AW30: 0 | AX30: 0 | AY30: 0 | AZ30: 0 | BA30: 0 | BB30: 0 | BC30: 0 | BD30: 0 | BE30: 0 | BF30: 0 | BG30: 0 | BH30: 0 | BI30: 0 | BJ30: 0 | BK30: 0 | BL30: 0 | BM30: 0 | BN30: 0 | BO30: 0 | BP30: 0 | BQ30: 0 | BR30: 0 | BS30: 0 | BT30: 0 | BU30: 0 | BV30: 0 | BW30: 0 | BX30: 0 | BY30: 0 | BZ30: 0 | CA30: 0 | CB30: 0 | CC30: 0
A31: Lead Prep ST. | B31: 0.033 | C31: Sales | D31: =IFERROR(VLOOKUP($A28,Sales!$A:B,D$2,0),0) -> 0 | E31: =IFERROR(VLOOKUP($A28,Sales!$A:C,E$2,0),0) -> 100 | F31: =IFERROR(VLOOKUP($A28,Sales!$A:D,F$2,0),0) -> 0 | G31: =IFERROR(VLOOKUP($A28,Sales!$A:E,G$2,0),0) -> 0 | H31: =IFERROR(VLOOKUP($A28,Sales!$A:F,H$2,0),0) -> 0 | I31: =IFERROR(VLOOKUP($A28,Sales!$A:G,I$2,0),0) -> 0 | J31: =IFERROR(VLOOKUP($A28,Sales!$A:H,J$2,0),0) -> 0 | K31: =IFERROR(VLOOKUP($A28,Sales!$A:I,K$2,0),0) -> 100 | L31: =IFERROR(VLOOKUP($A28,Sales!$A:J,L$2,0),0) -> 0 | M31: =IFERROR(VLOOKUP($A28,Sales!$A:K,M$2,0),0) -> 0 | N31: =IFERROR(VLOOKUP($A28,Sales!$A:L,N$2,0),0) -> 0 | O31: =IFERROR(VLOOKUP($A28,Sales!$A:M,O$2,0),0) -> 0 | P31: =IFERROR(VLOOKUP($A28,Sales!$A:N,P$2,0),0) -> 0 | Q31: =IFERROR(VLOOKUP($A28,Sales!$A:O,Q$2,0),0) -> 0 | R31: =IFERROR(VLOOKUP($A28,Sales!$A:P,R$2,0),0) -> 0 | S31: =IFERROR(VLOOKUP($A28,Sales!$A:Q,S$2,0),0) -> 0 | T31: =IFERROR(VLOOKUP($A28,Sales!$A:R,T$2,0),0) -> 0 | U31: =IFERROR(VLOOKUP($A28,Sales!$A:S,U$2,0),0) -> 30 | V31: =IFERROR(VLOOKUP($A28,Sales!$A:T,V$2,0),0) -> 30 | W31: =IFERROR(VLOOKUP($A28,Sales!$A:U,W$2,0),0) -> 30 | X31: =IFERROR(VLOOKUP($A28,Sales!$A:V,X$2,0),0) -> 10 | Y31: =IFERROR(VLOOKUP($A28,Sales!$A:W,Y$2,0),0) -> 0 | Z31: =IFERROR(VLOOKUP($A28,Sales!$A:X,Z$2,0),0) -> 0 | AA31: =IFERROR(VLOOKUP($A28,Sales!$A:Y,AA$2,0),0) -> 0 | AB31: =IFERROR(VLOOKUP($A28,Sales!$A:Z,AB$2,0),0) -> 0 | AC31: =IFERROR(VLOOKUP($A28,Sales!$A:AA,AC$2,0),0) -> 60 | AD31: =IFERROR(VLOOKUP($A28,Sales!$A:AB,AD$2,0),0) -> 60 | AE31: =IFERROR(VLOOKUP($A28,Sales!$A:AC,AE$2,0),0) -> 60 | AF31: =IFERROR(VLOOKUP($A28,Sales!$A:AD,AF$2,0),0) -> 60 | AG31: =IFERROR(VLOOKUP($A28,Sales!$A:AE,AG$2,0),0) -> 60 | AH31: =IFERROR(VLOOKUP($A28,Sales!$A:AF,AH$2,0),0) -> 150 | AI31: =IFERROR(VLOOKUP($A28,Sales!$A:AG,AI$2,0),0) -> 150 | AJ31: =IFERROR(VLOOKUP($A28,Sales!$A:AH,AJ$2,0),0) -> 0 | AK31: =CEILING(AK$5*$B27,1) -> 0 | AL31: =CEILING(AL$5*$B27,1) -> 0 | AM31: =CEILING(AM$5*$B27,1) -> 0 | AN31: =CEILING(AN$5*$B27,1) -> 24 | AO31: =CEILING(AO$5*$B27,1) -> 24 | AP31: =CEILING(AP$5*$B27,1) -> 24 | AQ31: =CEILING(AQ$5*$B27,1) -> 29 | AR31: =CEILING(AR$5*$B27,1) -> 29 | ... CC31: =CEILING(CC$5*$B27,1) -> 18
A32: Total ST. | B32: 0.262 | C32: Days | D32: =IF(D31=0,0, ROUND(D28 * 1/D31* D$13,1)) -> 0 | E32: =IF(E31=0,0, ROUND(E28 * 1/E31* E$13,1)) -> 32.9 | F32: =IF(F31=0,0, ROUND(F28 * 1/F31* F$13,1)) -> 0 | G32: =IF(G31=0,0, ROUND(G28 * 1/G31* G$13,1)) -> 0 | H32: =IF(H31=0,0, ROUND(H28 * 1/H31* H$13,1)) -> 0 | I32: =IF(I31=0,0, ROUND(I28 * 1/I31* I$13,1)) -> 0 | J32: =IF(J31=0,0, ROUND(J28 * 1/J31* J$13,1)) -> 0 | K32: =IF(K31=0,0, ROUND(K28 * 1/K31* K$13,1)) -> 27.9 | ... CC32: =IF(CC31=0,0, ROUND(CC28 * 1/CC31* CC$13,1)) -> -300.6
A33: 20 | B33: 1 | C33: 5.77925 | D33: =D30/$B33 -> 0 | E33: =E30/$B33 -> 0 | F33: =F30/$B33 -> 0 | G33: =G30/$B33 -> 0 | H33: =H30/$B33 -> 0 | I33: =I30/$B33 -> 0 | J33: =J30/$B33 -> 0 | K33: =K30/$B33 -> 0 | ... CC33: =CC30/$B33 -> 0
B34: =SUM(D38:AJ38)/SUM($D$263:$AJ$263) -> 0.0015625763 | C34: Shortage | D34: =D28-D31 -> 657 | E34: =E28-E31 -> 557 | F34: =F28-F31 -> 557 | G34: =G28-G31 -> 557 | H34: =H28-H31 -> 557 | I34: =I28-I31 -> 557 | J34: =J28-J31 -> 557 | K34: =K28-K31 -> 457 | ... CC34: =CC28-CC31 -> -1100
A35: 4172790 | B35: C | C35: Invt Qty | D35: =IFERROR(VLOOKUP(A35,OS!$A:$B,2,0),0) -> 40 | E35: =(D35+D36-D38) -> 40 | F35: =(E35+E36-E38) -> 40 | G35: =(F35+F36-F38) -> 40 | H35: =(G35+G36-G38) -> 40 | I35: =(H35+H36-H38+D37) -> 40 | J35: =(I35+I36-I38+E37) -> 40 | K35: =(J35+J36-J38+F37) -> 40 | L35: =(K35+K36-K38+G37) -> 40 | M35: =(L35+L36-L38+H37) -> 40 | N35: =(M35+M36-M38+I37) -> 40 | O35: =(N35+N36-N38+J37) -> 40 | P35: =(O35+O36-O38+K37) -> 40 | ... CC35: =(CB35+CB36-CB38+BX37) -> -286
A36: Tran. Pr. | B36: 6.749 | C36: WIP | D36: =IFERROR(VLOOKUP(A35,WIP!$A:$B,2,0),0) -> 0 | E36: 0 | F36: 0 | G36: 0 | H36: 0 | I36: 0 | J36: 0 | K36: 0 | L36: 0 | M36: 0 | N36: 0 | O36: 0 | P36: 0 | Q36: 0 | R36: 0 | S36: 0 | T36: 0 | U36: 0 | V36: 0 | W36: 0 | X36: 0 | Y36: 0 | Z36: 0 | AA36: 0 | AB36: 0 | AC36: 0 | AD36: 0 | AE36: 0 | AF36: 0 | AG36: 0 | AH36: 0 | AI36: 0 | AJ36: 0 | AK36: 0 | AL36: 0 | AM36: 0 | AN36: 0 | AO36: 0 | AP36: 0 | AQ36: 0 | AR36: 0 | AS36: 0 | AT36: 0 | AU36: 0 | AV36: 0 | AW36: 0 | AX36: 0 | AY36: 0 | AZ36: 0 | BA36: 0 | BB36: 0 | BC36: 0 | BD36: 0 | BE36: 0 | BF36: 0 | BG36: 0 | BH36: 0 | BI36: 0 | BJ36: 0 | BK36: 0 | BL36: 0 | BM36: 0 | BN36: 0 | BO36: 0 | BP36: 0 | BQ36: 0 | BR36: 0 | BS36: 0 | BT36: 0 | BU36: 0 | BV36: 0 | BW36: 0 | BX36: 0 | BY36: 0 | BZ36: 0 | CA36: 0 | CB36: 0 | CC36: 0
A37: Assy ST. | B37: 0.119 | C37: Plan | D37: =IFERROR(VLOOKUP($A35,Plan!$A:B,D$4,0),0) -> 0 | E37: =IFERROR(VLOOKUP($A35,Plan!$A:C,E$4,0),0) -> 0 | F37: =IFERROR(VLOOKUP($A35,Plan!$A:D,F$4,0),0) -> 0 | G37: 0 | H37: 0 | I37: 0 | J37: 0 | K37: 0 | L37: 0 | M37: 0 | N37: 0 | O37: 0 | P37: 0 | Q37: 0 | R37: 0 | S37: 0 | T37: 0 | U37: 0 | V37: 0 | W37: 0 | X37: 0 | Y37: 0 | Z37: 0 | AA37: 0 | AB37: 0 | AC37: 0 | AD37: 0 | AE37: 0 | AF37: 0 | AG37: 0 | AH37: 0 | AI37: 0 | AJ37: 0 | AK37: 0 | AL37: 0 | AM37: 0 | AN37: 0 | AO37: 0 | AP37: 0 | AQ37: 0 | AR37: 0 | AS37: 0 | AT37: 0 | AU37: 0 | AV37: 0 | AW37: 0 | AX37: 0 | AY37: 0 | AZ37: 0 | BA37: 0 | BB37: 0 | BC37: 0 | BD37: 0 | BE37: 0 | BF37: 0 | BG37: 0 | BH37: 0 | BI37: 0 | BJ37: 0 | BK37: 0 | BL37: 0 | BM37: 0 | BN37: 0 | BO37: 0 | BP37: 0 | BQ37: 0 | BR37: 0 | BS37: 0 | BT37: 0 | BU37: 0 | BV37: 0 | BW37: 0 | BX37: 0 | BY37: 0 | BZ37: 0 | CA37: 0 | CB37: 0 | CC37: 0
A38: Lead Prep ST. | B38: 0.01 | C38: Sales | D38: =IFERROR(VLOOKUP($A35,Sales!$A:B,D$2,0),0) -> 0 | E38: =IFERROR(VLOOKUP($A35,Sales!$A:C,E$2,0),0) -> 0 | F38: =IFERROR(VLOOKUP($A35,Sales!$A:D,F$2,0),0) -> 0 | G38: =IFERROR(VLOOKUP($A35,Sales!$A:E,G$2,0),0) -> 0 | H38: =IFERROR(VLOOKUP($A35,Sales!$A:F,H$2,0),0) -> 0 | I38: =IFERROR(VLOOKUP($A35,Sales!$A:G,I$2,0),0) -> 0 | J38: =IFERROR(VLOOKUP($A35,Sales!$A:H,J$2,0),0) -> 0 | K38: =IFERROR(VLOOKUP($A35,Sales!$A:I,K$2,0),0) -> 0 | L38: =IFERROR(VLOOKUP($A35,Sales!$A:J,L$2,0),0) -> 0 | M38: =IFERROR(VLOOKUP($A35,Sales!$A:K,M$2,0),0) -> 0 | N38: =IFERROR(VLOOKUP($A35,Sales!$A:L,N$2,0),0) -> 0 | O38: =IFERROR(VLOOKUP($A35,Sales!$A:M,O$2,0),0) -> 0 | P38: =IFERROR(VLOOKUP($A35,Sales!$A:N,P$2,0),0) -> 0 | Q38: =IFERROR(VLOOKUP($A35,Sales!$A:O,Q$2,0),0) -> 0 | R38: =IFERROR(VLOOKUP($A35,Sales!$A:P,R$2,0),0) -> 0 | S38: =IFERROR(VLOOKUP($A35,Sales!$A:Q,S$2,0),0) -> 0 | T38: =IFERROR(VLOOKUP($A35,Sales!$A:R,T$2,0),0) -> 0 | U38: =IFERROR(VLOOKUP($A35,Sales!$A:S,U$2,0),0) -> 0 | V38: =IFERROR(VLOOKUP($A35,Sales!$A:T,V$2,0),0) -> 0 | W38: =IFERROR(VLOOKUP($A35,Sales!$A:U,W$2,0),0) -> 0 | X38: =IFERROR(VLOOKUP($A35,Sales!$A:V,X$2,0),0) -> 0 | Y38: =IFERROR(VLOOKUP($A35,Sales!$A:W,Y$2,0),0) -> 40 | Z38: =IFERROR(VLOOKUP($A35,Sales!$A:X,Z$2,0),0) -> 40 | AA38: =IFERROR(VLOOKUP($A35,Sales!$A:Y,AA$2,0),0) -> 40 | AB38: =IFERROR(VLOOKUP($A35,Sales!$A:Z,AB$2,0),0) -> 40 | AC38: =IFERROR(VLOOKUP($A35,Sales!$A:AA,AC$2,0),0) -> 0 | AD38: =IFERROR(VLOOKUP($A35,Sales!$A:AB,AD$2,0),0) -> 0 | AE38: =IFERROR(VLOOKUP($A35,Sales!$A:AC,AE$2,0),0) -> 0 | AF38: =IFERROR(VLOOKUP($A35,Sales!$A:AD,AF$2,0),0) -> 0 | AG38: =IFERROR(VLOOKUP($A35,Sales!$A:AE,AG$2,0),0) -> 0 | AH38: =IFERROR(VLOOKUP($A35,Sales!$A:AF,AH$2,0),0) -> 0 | AI38: =IFERROR(VLOOKUP($A35,Sales!$A:AG,AI$2,0),0) -> 0 | AJ38: =IFERROR(VLOOKUP($A35,Sales!$A:AH,AJ$2,0),0) -> 0 | AK38: =CEILING(AK$5*$B34,1) -> 0 | AL38: =CEILING(AL$5*$B34,1) -> 0 | AM38: =CEILING(AM$5*$B34,1) -> 0 | AN38: =CEILING(AN$5*$B34,1) -> 5 | AO38: =CEILING(AO$5*$B34,1) -> 5 | AP38: =CEILING(AP$5*$B34,1) -> 5 | AQ38: =CEILING(AQ$5*$B34,1) -> 6 | AR38: =CEILING(AR$5*$B34,1) -> 6 | ... CC38: =CEILING(CC$5*$B34,1) -> 4
A39: Total ST. | B39: 0.129 | C39: Days | D39: =IF(D38=0,0, ROUND(D35 * 1/D38* D$13,1)) -> 0 | E39: =IF(E38=0,0, ROUND(E35 * 1/E38* E$13,1)) -> 0 | F39: =IF(F38=0,0, ROUND(F35 * 1/F38* F$13,1)) -> 0 | G39: =IF(G38=0,0, ROUND(G35 * 1/G38* G$13,1)) -> 0 | H39: =IF(H38=0,0, ROUND(H35 * 1/H38* H$13,1)) -> 0 | I39: =IF(I38=0,0, ROUND(I35 * 1/I38* I$13,1)) -> 0 | J39: =IF(J38=0,0, ROUND(J35 * 1/J38* J$13,1)) -> 0 | K39: =IF(K38=0,0, ROUND(K35 * 1/K38* K$13,1)) -> 0 | ... CC39: =IF(CC38=0,0, ROUND(CC35 * 1/CC38* CC$13,1)) -> -357.5
A40: 4 | B40: 1 | C40: 2.87729 | D40: =D37/$B40 -> 0 | E40: =E37/$B40 -> 0 | F40: =F37/$B40 -> 0 | G40: =G37/$B40 -> 0 | H40: =H37/$B40 -> 0 | I40: =I37/$B40 -> 0 | J40: =J37/$B40 -> 0 | K40: =K37/$B40 -> 0 | ... CC40: =CC37/$B40 -> 0
...

Sheet T-JCI2 LH
B1: Screen Id | D1: PPSP0020 | F1: Machine Name | H1: EGPSPC024 | J1: Printed On | L1: 2026-05-10 11:00:59
B3: MPS Plan - Customer:[JCI]
B5: Section Code | D5: PORT SAID MANUFACTURING(SAID)
B6: MPS ID | D6: JCI2 LH_VOLVO LH_W20/26_W44/27_01 | J6: MPS Type | L6: Oblige | N6: Target Efficiency | P6: 0.92
B7: Facility | D7: JCI2 LH | J7: Car Model | L7: VOLVO LH | N7: Working Hours | P7: 7
B8: From Date | D8: 2026/05/11 | E8: To Date | G8: 2027/11/07 | J8: Total Weeks | L8: 78 | N8: offset Weeks | P8: 4
B9: Facility (DOS) | D9: 10 | E9: Plan Suggestion By | G9: OPERATOR_EFFICIENCY | J9: Week Plan Offset | L9: 99 | N9: Assy Std.Hr. | P9: 0.3052
S10: JCI2 LH(Shift 1) | W10: JCI2 LH(Shift 2) | AA10: JCI2 LH(Shift 3)
B11: Month | C11: Plan Date | D11: Week No | E11: SEWS-E WD | F11: Cust WD | G11: Invt Qty | H11: WIP | I11: Sales Qty | J11: Avg Days | K11: Plan Qty | L11: Bottom P/Qty | M11: Assy Std.Hr. | N11: GPTC Tm. | O11: Cust P.P. | P11: Comments | Q11: Customer Plan | R11: Cust. Avg. Daily Build | S11: Heads | T11: Eff % | U11: Week/Hrs | V11: Team Qty | W11: Heads | X11: Eff % | Y11: Week/Hrs | Z11: Team Qty | AA11: Heads | AB11: Eff % | AC11: Week/Hrs | AD11: Team Qty | AE11: Total Op. | AF11: Car %age | AG11: TotStdTm | AH11: Clock Hours | AI11: Eff %
B12: May | C12: 46153 | D12: 20 | E12: 6 | F12: 5 | G12: ='B-JCI2 LH'!D260 -> 23160 | H12: ='B-JCI2 LH'!D261 -> 4541 | I12: ='B-JCI2 LH'!D263 -> 240 | J12: =IF(I12=0,"N/S",ROUND( ( ((G12) * 1)/I12)*F12,1)) -> 482.5 | K12: =V12+Z12+AD12 -> 5800 | L12: {=TRANSPOSE('B-JCI2 LH'!D262:CC262)} -> 5680 | M12: ='B-JCI2 LH'!$D$295 -> 0.294 | N12: 0 | O12: 5 | Q12: 0 | R12: =IF(F12=0,0,ROUND(I12/F12,0)) -> 48 | S12: 29 | T12: 0.7 | U12: =E12*7-N12 -> 42 | V12: =ROUND(((S12*T12*U12)/M12),0) -> 2900 | W12: =S12 -> 29 | X12: 0.7 | Y12: =U12 -> 42 | Z12: =ROUND(((W12*X12*Y12)/M12),0) -> 2900 | AA12: 0 | AB12: 0 | AC12: =E12*7-N12 -> 42 | AD12: =ROUND(((AA12*AB12*AC12)/M12),0) -> 0 | AE12: =S12+W12+AA12 -> 58 | AG12: =K12*M12 -> 1705.2 | AH12: =S12*U12+W12*Y12+AA12*AC12 -> 2436 | AI12: =IF(AH12=0,0,AG12/AH12) -> 0.7
B13: May | C13: 46160 | D13: 21 | E13: 6 | F13: 10 | G13: =(G12+H12-I12) -> 27461 | H13: 0 | I13: ='B-JCI2 LH'!E263 -> 5960 | J13: =IF(I13=0,"N/S",ROUND( ( ((G13) * 1)/I13)*F13,1)) -> 46.1 | K13: =V13+Z13+AD13 -> 3300 | L13: 3476 | M13: ='B-JCI2 LH'!$D$295 -> 0.294 | N13: 0 | O13: 5 | Q13: 0 | R13: =IF(F13=0,0,ROUND(I13/F13,0)) -> 596 | S13: 15 | T13: 0.77 | U13: =E13*7-N13 -> 42 | V13: =ROUND(((S13*T13*U13)/M13),0) -> 1650 | W13: =S13 -> 15 | X13: 0.77 | Y13: =U13 -> 42 | Z13: =ROUND(((W13*X13*Y13)/M13),0) -> 1650 | AA13: 0 | AB13: 0 | AC13: =E13*7-N13 -> 42 | AD13: =ROUND(((AA13*AB13*AC13)/M13),0) -> 0 | AE13: =S13+W13+AA13 -> 30 | AG13: =K13*M13 -> 970.2 | AH13: =S13*U13+W13*Y13+AA13*AC13 -> 1260 | AI13: =IF(AH13=0,0,AG13/AH13) -> 0.77
B14: May | C14: 46167 | D14: 22 | E14: 3 | F14: 5 | G14: =(G13+H13-I13) -> 21501 | H14: 0 | I14: ='B-JCI2 LH'!F263 -> 3400 | J14: =IF(I14=0,"N/S",ROUND( ( ((G14) * 1)/I14)*F14,1)) -> 31.6 | K14: =V14+Z14+AD14 -> 1650 | L14: 1720 | M14: ='B-JCI2 LH'!$D$295 -> 0.294 | N14: 0 | O14: 5 | Q14: 0 | R14: =IF(F14=0,0,ROUND(I14/F14,0)) -> 680 | S14: 15 | T14: 0.77 | U14: =E14*7-N14 -> 21 | V14: =ROUND(((S14*T14*U14)/M14),0) -> 825 | W14: =S14 -> 15 | X14: 0.77 | Y14: =U14 -> 21 | Z14: =ROUND(((W14*X14*Y14)/M14),0) -> 825 | AA14: 0 | AB14: 0 | AC14: =E14*7-N14 -> 21 | AD14: =ROUND(((AA14*AB14*AC14)/M14),0) -> 0 | AE14: =S14+W14+AA14 -> 30 | AG14: =K14*M14 -> 485.1 | AH14: =S14*U14+W14*Y14+AA14*AC14 -> 630 | AI14: =IF(AH14=0,0,AG14/AH14) -> 0.77
B15: Jun | C15: 46174 | D15: 23 | E15: 5 | F15: 5 | G15: =(G14+H14-I14) -> 18101 | H15: 0 | I15: ='B-JCI2 LH'!G263 -> 3900 | J15: =IF(I15=0,"N/S",ROUND( ( ((G15) * 1)/I15)*F15,1)) -> 23.2 | K15: =V15+Z15+AD15 -> 2750 | L15: 0 | M15: ='B-JCI2 LH'!$D$295 -> 0.294 | N15: 0 | O15: 6 | Q15: 0 | R15: =IF(F15=0,0,ROUND(I15/F15,0)) -> 780 | S15: 15 | T15: 0.77 | U15: =E15*7-N15 -> 35 | V15: =ROUND(((S15*T15*U15)/M15),0) -> 1375 | W15: =S15 -> 15 | X15: 0.77 | Y15: =U15 -> 35 | Z15: =ROUND(((W15*X15*Y15)/M15),0) -> 1375 | AA15: 0 | AB15: 0 | AC15: =E15*7-N15 -> 35 | AD15: =ROUND(((AA15*AB15*AC15)/M15),0) -> 0 | AE15: =S15+W15+AA15 -> 30 | AG15: =K15*M15 -> 808.5 | AH15: =S15*U15+W15*Y15+AA15*AC15 -> 1050 | AI15: =IF(AH15=0,0,AG15/AH15) -> 0.77
B16: Jun | C16: 46181 | D16: 24 | E16: 6 | F16: 5 | G16: =(G15+H15-I15) -> 14201 | H16: 0 | I16: ='B-JCI2 LH'!H263 -> 4116 | J16: =IF(I16=0,"N/S",ROUND( ( ((G16) * 1)/I16)*F16,1)) -> 17.3 | K16: =V16+Z16+AD16 -> 3300 | L16: 0 | M16: ='B-JCI2 LH'!$D$295 -> 0.294 | N16: 0 | O16: 6 | Q16: 0 | R16: =IF(F16=0,0,ROUND(I16/F16,0)) -> 823 | S16: 15 | T16: 0.77 | U16: =E16*7-N16 -> 42 | V16: =ROUND(((S16*T16*U16)/M16),0) -> 1650 | W16: =S16 -> 15 | X16: 0.77 | Y16: =U16 -> 42 | Z16: =ROUND(((W16*X16*Y16)/M16),0) -> 1650 | AA16: 0 | AB16: 0 | AC16: =E16*7-N16 -> 42 | AD16: =ROUND(((AA16*AB16*AC16)/M16),0) -> 0 | AE16: =S16+W16+AA16 -> 30 | AG16: =K16*M16 -> 970.2 | AH16: =S16*U16+W16*Y16+AA16*AC16 -> 1260 | AI16: =IF(AH16=0,0,AG16/AH16) -> 0.77
B17: Jun | C17: 46188 | D17: 25 | E17: 3 | F17: 5 | G17: =(G16+H16-I16+K12) -> 15885 | H17: 0 | I17: ='B-JCI2 LH'!I263 -> 4260 | J17: =IF(I17=0,"N/S",ROUND( ( ((G17) * 1)/I17)*F17,1)) -> 18.6 | K17: =V17+Z17+AD17 -> 1650 | L17: 0 | M17: ='B-JCI2 LH'!$D$295 -> 0.294 | N17: 0 | O17: 6 | P17: Move to Posa.3 | Q17: 0 | R17: =IF(F17=0,0,ROUND(I17/F17,0)) -> 852 | S17: 15 | T17: 0.77 | U17: =E17*7-N17 -> 21 | V17: =ROUND(((S17*T17*U17)/M17),0) -> 825 | W17: =S17 -> 15 | X17: 0.77 | Y17: =U17 -> 21 | Z17: =ROUND(((W17*X17*Y17)/M17),0) -> 825 | AA17: 0 | AB17: 0 | AC17: =E17*7-N17 -> 21 | AD17: =ROUND(((AA17*AB17*AC17)/M17),0) -> 0 | AE17: =S17+W17+AA17 -> 30 | AG17: =K17*M17 -> 485.1 | AH17: =S17*U17+W17*Y17+AA17*AC17 -> 630 | AI17: =IF(AH17=0,0,AG17/AH17) -> 0.77
B18: Jun | C18: 46195 | D18: 26 | E18: 6 | F18: 5 | G18: =(G17+H17-I17+K13) -> 14925 | H18: 0 | I18: ='B-JCI2 LH'!J263 -> 3560 | J18: =IF(I18=0,"N/S",ROUND( ( ((G18) * 1)/I18)*F18,1)) -> 21 | K18: =V18+Z18+AD18 -> 3300 | L18: 0 | M18: ='B-JCI2 LH'!$D$295 -> 0.294 | N18: 0 | O18: 6 | Q18: 0 | R18: =IF(F18=0,0,ROUND(I18/F18,0)) -> 712 | S18: 15 | T18: 0.77 | U18: =E18*7-N18 -> 42 | V18: =ROUND(((S18*T18*U18)/M18),0) -> 1650 | W18: =S18 -> 15 | X18: 0.77 | Y18: =U18 -> 42 | Z18: =ROUND(((W18*X18*Y18)/M18),0) -> 1650 | AA18: 0 | AB18: 0 | AC18: =E18*7-N18 -> 42 | AD18: =ROUND(((AA18*AB18*AC18)/M18),0) -> 0 | AE18: =S18+W18+AA18 -> 30 | AG18: =K18*M18 -> 970.2 | AH18: =S18*U18+W18*Y18+AA18*AC18 -> 1260 | AI18: =IF(AH18=0,0,AG18/AH18) -> 0.77
