Workbook

Sheet Adient Shortage report
A1: Prepared By: | B1: Mohamed Galal | D1: China | H1: 36 | I1: WK | J1: 2 | P1: =H1+1 -> 37 | Q1: WK | R1: =J1+1 -> 3 | X1: =P1+1 -> 38 | Y1: WK | Z1: =R1+1 -> 4 | AF1: =X1+1 -> 39 | AG1: WK | AH1: =Z1+1 -> 5 | AN1: =AF1+1 -> 40 | AO1: WK | AP1: =AH1+1 -> 6 | AW1: =AN1+1 -> 41 | AX1: WK | AY1: =AP1+1 -> 7 | BE1: =AW1+1 -> 42 | BF1: WK | BG1: =AY1+1 -> 8 | BO1: =BE1+1 -> 43 | BP1: WK | BQ1: =BG1+1 -> 9 | BZ1: =BO1+1 -> 44 | CA1: WK | CB1: =BQ1+1 -> 10 | CJ1: =BZ1+1 -> 45 | CK1: WK | CL1: =CB1+1 -> 11 | CS1: =CJ1+1 -> 46 | CT1: WK | CU1: =CL1+1 -> 12 | DC1: =CS1+1 -> 47 | DD1: WK | DE1: =CU1+1 -> 13 | DL1: =DC1+1 -> 48 | DM1: WK | DN1: =DE1+1 -> 14 | DT1: =DL1+1 -> 49 | DU1: WK | DV1: =DN1+1 -> 15 | ED1: =DT1+1 -> 50 | EE1: WK | EF1: =DV1+1 -> 16 | EM1: =ED1+1 -> 51 | EN1: WK | EO1: =EF1+1 -> 17 | EU1: =EM1+1 -> 52 | EV1: WK | EW1: =EO1+1 -> 18 | FC1: 1 | FD1: WK 0 | FE1: =EW1+1 -> 19 | FK1: =FC1+1 -> 2 | FL1: WK 0 | FM1: =FE1+1 -> 20 | FS1: =FK1+1 -> 3 | FT1: WK 0 | FU1: =FM1+1 -> 21 | GF1: =FS1+1 -> 4 | GG1: WK 0 | GH1: =FU1+1 -> 22 | GO1: =GF1+1 -> 5 | GP1: WK 0 | GQ1: =GH1+1 -> 23 | GX1: =GO1+1 -> 6 | GY1: WK 0 | GZ1: =GQ1+1 -> 24 | HG1: =GX1+1 -> 7 | HH1: WK 0 | HI1: =GZ1+1 -> 25 | HP1: =HG1+1 -> 8 | HQ1: WK 0 | HR1: =HI1+1 -> 26 | HY1: =HP1+1 -> 9 | HZ1: WK 0 | IA1: =HR1+1 -> 27 | IH1: =HY1+1 -> 10 | II1: WK | IJ1: =IA1+1 -> 28 | IP1: =IH1+1 -> 11 | IQ1: WK | IR1: =IJ1+1 -> 29 | IY1: =IP1+1 -> 12 | IZ1: WK | JA1: =IR1+1 -> 30 | JG1: =IY1+1 -> 13 | JH1: WK | JI1: =JA1+1 -> 31 | JP1: =JG1+1 -> 14 | JQ1: WK | JR1: =JI1+1 -> 32 | JX1: =JP1+1 -> 15 | JY1: WK | JZ1: =JR1+1 -> 33 | KF1: =JX1+1 -> 16 | KG1: WK | KH1: =JZ1+1 -> 34 | KO1: =KF1+1 -> 17 | KP1: WK | KQ1: =KH1+1 -> 35 | KX1: =KO1+1 -> 18 | KY1: WK | KZ1: =KQ1+1 -> 36 | LF1: =KX1+1 -> 19 | LG1: WK | LH1: =KZ1+1 -> 37 | LO1: =LF1+1 -> 20 | LP1: WK | LQ1: =LH1+1 -> 38 | LW1: =LO1+1 -> 21 | LX1: WK | LY1: =LQ1+1 -> 39 | ME1: =LW1+1 -> 22 | MF1: WK | MG1: =LY1+1 -> 40 | MM1: =ME1+1 -> 23 | MN1: WK | MO1: =MG1+1 -> 41 | MU1: =MM1+1 -> 24 | MV1: WK | MW1: =MO1+1 -> 42 | NC1: =MU1+1 -> 25 | ND1: WK | NE1: =MW1+1 -> 43 | NK1: =NC1+1 -> 26 | NL1: WK | NM1: =NE1+1 -> 44 | NS1: =NK1+1 -> 27 | NT1: WK | NU1: =NM1+1 -> 45 | OA1: =NS1+1 -> 28 | OB1: WK | OC1: =NU1+1 -> 46 | OI1: =OA1+1 -> 29 | OJ1: WK | OK1: =OC1+1 -> 47 | OQ1: =OI1+1 -> 30 | OR1: WK | OS1: =OK1+1 -> 48 | OY1: =OQ1+1 -> 31 | OZ1: WK | PA1: =OS1+1 -> 49 | PG1: =OY1+1 -> 32 | PH1: WK | PI1: =PA1+1 -> 50 | PO1: =PG1+1 -> 33 | PP1: WK | PQ1: =PI1+1 -> 51 | PW1: =PO1+1 -> 34 | PX1: WK | PY1: =PQ1+1 -> 52 | QE1: =PW1+1 -> 35 | QF1: WK | QG1: =PY1+1 -> 53 | QM1: =QE1+1 -> 36 | QN1: WK | QO1: =QG1+1 -> 54 | QU1: =QM1+1 -> 37 | QV1: WK | QW1: =QO1+1 -> 55 | RC1: =QU1+1 -> 38 | RD1: WK | RE1: =QW1+1 -> 56 | RK1: =RC1+1 -> 39 | RL1: WK | RM1: =RE1+1 -> 57 | RS1: =RK1+1 -> 40 | RT1: WK | RU1: =RM1+1 -> 58 | SA1: =RS1+1 -> 41 | SB1: WK | SC1: =RU1+1 -> 59 | SI1: =SA1+1 -> 42 | SJ1: WK | SK1: =SC1+1 -> 60 | SQ1: =SI1+1 -> 43 | SR1: WK | SS1: =SK1+1 -> 61 | SY1: =SQ1+1 -> 44 | SZ1: WK | TA1: =SS1+1 -> 62 | TG1: =SY1+1 -> 45 | TH1: WK | TI1: =TA1+1 -> 63 | TO1: =TG1+1 -> 46 | TP1: WK | TQ1: =TI1+1 -> 64 | TW1: =TO1+1 -> 47 | TX1: WK | TY1: =TQ1+1 -> 65 | UE1: =TW1+1 -> 48 | UF1: WK | UG1: =TY1+1 -> 66 | UM1: =UE1+1 -> 49 | UN1: WK | UO1: =UG1+1 -> 67 | UU1: =UM1+1 -> 50 | UV1: WK | UW1: =UO1+1 -> 68 | VC1: =UU1+1 -> 51 | VD1: WK | VE1: =UW1+1 -> 69 | VK1: =VC1+1 -> 52 | VL1: WK | VM1: =VE1+1 -> 70
A2: Updated by | B2: Mohamed Galal | D2: Malaezia | EV2: From 23-12
A3: T2 Shortage report-VOLVO | D3: China - Malaezia | AR3: Air Shipment | BI3: Air Shipment | BS3: Air Shipment | BU3: Air Shipment | CD3: Air Shipment | CE3: Air Shipment | CT3: Cust.Off | CW3: Air Shipment | EV3: Cust.Off | FD3: Cust.Off | FL3: Del WK 52 | JY3: Cust.Off | LJ3: Vessel Delay | MF3: Cust.Off
A4: Port Said | H4: 45901 | P4: 45901 | X4: 45901 | AF4: 45901 | AN4: 45931 | AW4: 45931 | BE4: 45931 | BO4: 45931 | BZ4: 45931 | CJ4: 45962 | CS4: 45962 | DC4: 45962 | DL4: 45992 | DT4: 45992 | ED4: 45992 | EM4: 45992 | EU4: 45992 | FC4: 46023 | FK4: 46023 | FS4: 46023 | GF4: 46023 | GO4: 46023 | GX4: 46054 | HG4: 46054 | HP4: 46054 | HY4: 46054 | IH4: 46082 | IP4: 46082 | IY4: 46082 | JG4: 46082 | JP4: 46113 | JX4: 46113 | KF4: 46113 | KO4: 46113 | KX4: 46143 | LF4: 46143 | LO4: 46143 | LW4: 46143 | ME4: 46143 | MM4: 46174 | MU4: 46174 | NC4: 46174 | NK4: 46174 | NS4: 46204 | OA4: 46204 | OI4: 46204 | OQ4: 46204 | OY4: 46204 | PG4: 46235 | PO4: 46235 | PW4: 46235 | QE4: 46235 | QM4: 46266 | QU4: 46266 | RC4: 46266 | RK4: 46266 | RS4: 46296 | SA4: 46296 | SI4: 46296 | SQ4: 46296 | SY4: 46296 | TG4: 46327 | TO4: 46327 | TW4: 46327 | UE4: 46327 | UM4: 46296 | UU4: 46296 | VC4: 46296 | VK4: 46296
A5: 46113 | B5: WK 17 | H5: =I1&H1 -> WK 36 | P5: =Q1&P1 -> WK 37 | X5: =Y1&X1 -> WK 38 | AF5: =AG1&AF1 -> WK 39 | AN5: =AO1&AN1 -> WK 40 | AW5: =AX1&AW1 -> WK 41 | BE5: =BF1&BE1 -> WK 42 | BO5: =BP1&BO1 -> WK 43 | BZ5: =CA1&BZ1 -> WK 44 | CJ5: =CK1&CJ1 -> WK 45 | CS5: =CT1&CS1 -> WK 46 | DC5: =DD1&DC1 -> WK 47 | DL5: =DM1&DL1 -> WK 48 | DT5: =DU1&DT1 -> WK 49 | ED5: =EE1&ED1 -> WK 50 | EM5: =EN1&EM1 -> WK 51 | EU5: =EV1&EU1 -> WK 52 | FC5: =FD1&FC1 -> WK 01 | FK5: =FL1&FK1 -> WK 02 | FS5: =FT1&FS1 -> WK 03 | GF5: =GG1&GF1 -> WK 04 | GO5: =GP1&GO1 -> WK 05 | GX5: =GY1&GX1 -> WK 06 | HG5: =HH1&HG1 -> WK 07 | HP5: =HQ1&HP1 -> WK 08 | HY5: =HZ1&HY1 -> WK 09 | IH5: =II1&IH1 -> WK 10 | IP5: =IQ1&IP1 -> WK 11 | IY5: =IZ1&IY1 -> WK 12 | JG5: =JH1&JG1 -> WK 13 | JP5: =JQ1&JP1 -> WK 14 | JX5: =JY1&JX1 -> WK 15 | KF5: =KG1&KF1 -> WK 16 | KO5: =KP1&KO1 -> WK 17 | KX5: =KY1&KX1 -> WK 18 | LF5: =LG1&LF1 -> WK 19 | LO5: =LP1&LO1 -> WK 20 | LW5: =LX1&LW1 -> WK 21 | ME5: =MF1&ME1 -> WK 22 | MM5: =MN1&MM1 -> WK 23 | MU5: =MV1&MU1 -> WK 24 | NC5: =ND1&NC1 -> WK 25 | NK5: =NL1&NK1 -> WK 26 | NS5: =NT1&NS1 -> WK 27 | OA5: =OB1&OA1 -> WK 28 | OI5: =OJ1&OI1 -> WK 29 | OQ5: =OR1&OQ1 -> WK 30 | OY5: =OZ1&OY1 -> WK 31 | PG5: =PH1&PG1 -> WK 32 | PO5: =PP1&PO1 -> WK 33 | PW5: =PX1&PW1 -> WK 34 | QE5: =QF1&QE1 -> WK 35 | QM5: =QN1&QM1 -> WK 36 | QU5: =QV1&QU1 -> WK 37 | RC5: =RD1&RC1 -> WK 38 | RK5: =RL1&RK1 -> WK 39 | RS5: =RT1&RS1 -> WK 40 | SA5: =SB1&SA1 -> WK 41 | SI5: =SJ1&SI1 -> WK 42 | SQ5: =SR1&SQ1 -> WK 43 | SY5: =SZ1&SY1 -> WK 44 | TG5: =TH1&TG1 -> WK 45 | TO5: =TP1&TO1 -> WK 46 | TW5: =TX1&TW1 -> WK 47 | UE5: =UF1&UE1 -> WK 48 | UM5: =UN1&UM1 -> WK 49 | UU5: =UV1&UU1 -> WK 50 | VC5: =VD1&VC1 -> WK 51 | VK5: =VL1&VK1 -> WK 52
A6: Project | B6: Facility | C6: Customer part | D6: Part NO. | E6: Pack Factor | F6: Pallet Factor | H6: Alba DC | I6: Belgium | J6: Malaezia | K6: China | L6: Delivery to | M6: STOCKS | N6: Alba DC | P6: Alba DC | Q6: Belgium | R6: Malaezia | S6: China | T6: Delivery to | U6: STOCKS | V6: Alba DC | X6: Alba DC | Y6: Belgium | Z6: Malaezia | AA6: China | AB6: Delivery to | AC6: STOCKS | AD6: Alba DC | AF6: Alba DC | AG6: Belgium | AH6: Malaezia | AI6: China | AJ6: Delivery to | AK6: STOCKS | AL6: Alba DC | AN6: Alba DC | AO6: Belgium | AP6: Malaezia | AQ6: China | AR6: IHB0019432 | AS6: Delivery to | AT6: STOCKS | AU6: Alba DC | AW6: Alba DC | AX6: Belgium | AY6: Malaezia | AZ6: China | BA6: Delivery to | BB6: STOCKS | BC6: Alba DC | BE6: Alba DC | BF6: Belgium | BG6: Malaezia | BH6: China | BI6: IHB0019521 | BJ6: IHB0019592 | BK6: Delivery to | BL6: STOCKS | BM6: Alba DC | BO6: Alba DC | BP6: Belgium | BQ6: Malaezia | BR6: China | BS6: IHB0019625 | BT6: IHB0019592 | BU6: IHB0019645 | BV6: Delivery to | BW6: STOCKS | BX6: Alba DC | BZ6: Alba DC | CA6: Belgium | CB6: Malaezia | CC6: China | CD6: IHB0019692 | CE6: IHB0019717 | CF6: Delivery to | CG6: STOCKS | CH6: Alba DC | CJ6: Alba DC | CK6: Belgium | CL6: Malaezia | CM6: China | CN6: IHB0019572 | CO6: Delivery to | CP6: STOCKS | CQ6: Alba DC | CS6: Alba DC | CT6: Belgium | CU6: Malaezia | CV6: China | CW6: IHB0019888 | CX6: IHB0019536 | CY6: Delivery to | CZ6: STOCKS | DA6: Alba DC | DC6: Alba DC | DD6: Belgium | DE6: Malaezia | DF6: China | DG6: IHB0019908 | DH6: Delivery to | DI6: STOCKS | DJ6: Alba DC | DL6: Alba DC | DM6: Belgium | DN6: Malaezia | DO6: China | DP6: Delivery to | DQ6: STOCKS | DR6: Alba DC | DT6: Alba DC | DU6: Belgium | DV6: Malaezia | DW6: China | DX6: IHB0020012 | DY6: IHB0020091 | DZ6: Delivery to | EA6: STOCKS | EB6: Alba DC | ED6: Alba DC | EE6: Belgium | EF6: Malaezia | EG6: China | EH6: IHB0020213 | EI6: Delivery to | EJ6: STOCKS | EK6: Alba DC | EM6: Alba DC | EN6: Belgium | EO6: Malaezia | EP6: China | EQ6: Delivery to | ER6: STOCKS | ES6: Alba DC | EU6: Alba DC | EV6: Belgium | EW6: Malaezia | EX6: China | EY6: Delivery to | EZ6: STOCKS | FA6: Alba DC | FC6: Alba DC | FD6: Belgium | FE6: Malaezia | FF6: China | FG6: Delivery to | FH6: STOCKS | FI6: Alba DC | FK6: Alba DC | FL6: Belgium | FM6: Malaezia | FN6: China | FO6: Delivery to | FP6: STOCKS | FQ6: Alba DC | FS6: Alba DC | FT6: Belgium | FU6: Malaezia | FV6: China | FW6: IHB0020285 | FX6: IHB0020466 | FY6: IHB0020368 | FZ6: IHB0020470 | GA6: IHB0020446 | GB6: Delivery to | GC6: STOCKS | GD6: Alba DC | GF6: Alba DC | GG6: Belgium | GH6: Malaezia | GI6: China | GJ6: IHB0020666 | GK6: Delivery to | GL6: STOCKS | GM6: Alba DC | GO6: Alba DC | GP6: Belgium | GQ6: Malaezia | GR6: China | GS6: IHB0020756 | GT6: Delivery to | GU6: STOCKS | GV6: Alba DC | GX6: Alba DC | GY6: Belgium | GZ6: Malaezia | HA6: China | HB6: IHB0020843 | HC6: Delivery to | HD6: STOCKS | HE6: Alba DC | HG6: Alba DC | HH6: Belgium | HI6: Malaezia | HJ6: China | HK6: IHB0020923 | HL6: Delivery to | HM6: STOCKS | HN6: Alba DC | HP6: Alba DC | HQ6: Belgium | HR6: Malaezia | HS6: China | HT6: IHB0021005 | HU6: Delivery to | HV6: STOCKS | HW6: Alba DC | HY6: Alba DC | HZ6: Belgium | IA6: Malaezia | IB6: China | IC6: IHB0021097 | ID6: Delivery to | IE6: STOCKS | IF6: Alba DC | IH6: Alba DC | II6: Belgium | IJ6: Malaezia | IK6: China | IL6: Delivery to | IM6: STOCKS | IN6: Alba DC | IP6: Alba DC | IQ6: Belgium | IR6: Malaezia | IS6: China | IT6: IHB0021174 | IU6: Delivery to | IV6: STOCKS | IW6: Alba DC | IY6: Alba DC | IZ6: Belgium | JA6: Malaezia | JB6: China | JC6: Delivery to | JD6: STOCKS | JE6: Alba DC | JG6: Alba DC | JH6: Belgium | JI6: Malaezia | JJ6: China | JK6: IHB0021293 | JL6: Delivery to | JM6: STOCKS | JN6: Alba DC | JP6: Alba DC | JQ6: Belgium | JR6: Malaezia | JS6: China | JT6: Delivery to | JU6: STOCKS | JV6: Alba DC | JX6: Alba DC | JY6: Belgium | JZ6: Malaezia | KA6: China | KB6: Delivery to | KC6: STOCKS | KD6: Alba DC | KF6: Alba DC | KG6: Belgium | KH6: Malaezia | KI6: China | KJ6: IHB0021448 | KK6: Delivery to | KL6: STOCKS | KM6: Alba DC | KO6: Alba DC | KP6: Belgium | KQ6: Malaezia | KR6: China | KS6: IHB0021691 | KT6: Delivery to | KU6: STOCKS | KV6: Alba DC | KX6: Alba DC | KY6: Belgium | KZ6: Malaezia | LA6: China | LB6: Delivery to | LC6: STOCKS | LD6: Alba DC | LF6: Alba DC | LG6: Belgium | LH6: Malaezia | LI6: China | LJ6: IHB0021559 | LK6: Delivery to | LL6: STOCKS | LM6: Alba DC | LO6: Alba DC | LP6: Belgium | LQ6: Malaezia | LR6: China | LS6: Delivery to | LT6: STOCKS | LU6: Alba DC | LW6: Alba DC | LX6: Belgium | LY6: Malaezia | LZ6: China | MA6: Delivery to | MB6: STOCKS | MC6: Alba DC | ME6: Alba DC | MF6: Belgium | MG6: Malaezia | MH6: China | MI6: Delivery to | MJ6: STOCKS | MK6: Alba DC | MM6: Alba DC | MN6: Belgium | MO6: Malaezia | MP6: China | MQ6: Delivery to | MR6: STOCKS | MS6: Alba DC | MU6: Alba DC | MV6: Belgium | MW6: Malaezia | MX6: China | MY6: Delivery to | MZ6: STOCKS | NA6: Alba DC | NC6: Alba DC | ND6: Belgium | NE6: Malaezia | NF6: China | NG6: Delivery to | NH6: STOCKS | NI6: Alba DC | NK6: Alba DC | NL6: Belgium | NM6: Malaezia | NN6: China | NO6: Delivery to | NP6: STOCKS | NQ6: Alba DC | NS6: Alba DC | NT6: Belgium | NU6: Malaezia | NV6: China | NW6: Delivery to | NX6: STOCKS | NY6: Alba DC | OA6: Alba DC | OB6: Belgium | OC6: Malaezia | OD6: China | OE6: Delivery to | OF6: STOCKS | OG6: Alba DC | OI6: Alba DC | OJ6: Belgium | OK6: Malaezia | OL6: China | OM6: Delivery to | ON6: STOCKS | OO6: Alba DC | OQ6: Alba DC | OR6: Belgium | OS6: Malaezia | OT6: China | OU6: Delivery to | OV6: STOCKS | OW6: Alba DC | OY6: Alba DC | OZ6: Belgium | PA6: Malaezia | PB6: China | PC6: Delivery to | PD6: STOCKS | PE6: Alba DC | PG6: Alba DC | PH6: Belgium | PI6: Malaezia | PJ6: China | PK6: Delivery to | PL6: STOCKS | PM6: Alba DC | PO6: Alba DC | PP6: Belgium | PQ6: Malaezia | PR6: China | PS6: Delivery to | PT6: STOCKS | PU6: Alba DC | PW6: Alba DC | PX6: Belgium | PY6: Malaezia | PZ6: China | QA6: Delivery to | QB6: STOCKS | QC6: Alba DC | QE6: Alba DC | QF6: Belgium | QG6: Malaezia | QH6: China | QI6: Delivery to | QJ6: STOCKS | QK6: Alba DC | QM6: Alba DC | QN6: Belgium | QO6: Malaezia | QP6: China | QQ6: Delivery to | QR6: STOCKS | QS6: Alba DC | QU6: Alba DC | QV6: Belgium | QW6: Malaezia | QX6: China | QY6: Delivery to | QZ6: STOCKS | RA6: Alba DC | RC6: Alba DC | RD6: Belgium | RE6: Malaezia | RF6: China | RG6: Delivery to | RH6: STOCKS | RI6: Alba DC | RK6: Alba DC | RL6: Belgium | RM6: Malaezia | RN6: China | RO6: Delivery to | RP6: STOCKS | RQ6: Alba DC | RS6: Alba DC | RT6: Belgium | RU6: Malaezia | RV6: China | RW6: Delivery to | RX6: STOCKS | RY6: Alba DC | SA6: Alba DC | SB6: Belgium | SC6: Malaezia | SD6: China | SE6: Delivery to | SF6: STOCKS | SG6: Alba DC | SI6: Alba DC | SJ6: Belgium | SK6: Malaezia | SL6: China | SM6: Delivery to | SN6: STOCKS | SO6: Alba DC | SQ6: Alba DC | SR6: Belgium | SS6: Malaezia | ST6: China | SU6: Delivery to | SV6: STOCKS | SW6: Alba DC | SY6: Alba DC | SZ6: Belgium | TA6: Malaezia | TB6: China | TC6: Delivery to | TD6: STOCKS | TE6: Alba DC | TG6: Alba DC | TH6: Belgium | TI6: Malaezia | TJ6: China | TK6: Delivery to | TL6: STOCKS | TM6: Alba DC | TO6: Alba DC | TP6: Belgium | TQ6: Malaezia | TR6: China | TS6: Delivery to | TT6: STOCKS | TU6: Alba DC | TW6: Alba DC | TX6: Belgium | TY6: Malaezia | TZ6: China | UA6: Delivery to | UB6: STOCKS | UC6: Alba DC | UE6: Alba DC | UF6: Belgium | UG6: Malaezia | UH6: China | UI6: Delivery to | UJ6: STOCKS | UK6: Alba DC | UM6: Alba DC | UN6: Belgium | UO6: Malaezia | UP6: China | UQ6: Delivery to | UR6: STOCKS | US6: Alba DC | UU6: Alba DC | UV6: Belgium | UW6: Malaezia | UX6: China | UY6: Delivery to | UZ6: STOCKS | VA6: Alba DC | VC6: Alba DC | VD6: Belgium | VE6: Malaezia | VF6: China | VG6: Delivery to | VH6: STOCKS | VI6: Alba DC | VK6: Alba DC | VL6: Belgium | VM6: Malaezia | VN6: China | VO6: Delivery to | VP6: STOCKS | VQ6: Alba DC
H7: O.S of | I7: Sales | J7: Sales | K7: Sales | L7: Assende | M7: VAR | N7: End of Stock | P7: O.S of | Q7: Sales | R7: Sales | S7: Sales | T7: Assende | U7: VAR | V7: End of Stock | X7: O.S of | Y7: Sales | Z7: Sales | AA7: Sales | AB7: Assende | AC7: VAR | AD7: End of Stock | AF7: O.S of | AG7: Sales | AH7: Sales | AI7: Sales | AJ7: Assende | AK7: VAR | AL7: End of Stock | AN7: O.S of | AO7: Sales | AP7: Sales | AQ7: Sales | AR7: 45930 | AS7: Assende | AT7: VAR | AU7: End of Stock | AW7: O.S of | AX7: Sales | AY7: Sales | AZ7: Sales | BA7: Assende | BB7: VAR | BC7: End of Stock | BE7: O.S of | BF7: Sales | BG7: Sales | BH7: Sales | BI7: 45937 | BJ7: 45944 | BK7: Assende | BL7: VAR | BM7: End of Stock | BO7: O.S of | BP7: Sales | BQ7: Sales | BR7: Sales | BS7: 45945 | BU7: 45948 | BV7: Assende | BW7: VAR | BX7: End of Stock | BZ7: O.S of | CA7: Sales | CB7: Sales | CC7: Sales | CD7: 45950 | CE7: 45953 | CF7: Assende | CG7: VAR | CH7: End of Stock | CJ7: O.S of | CK7: Sales | CL7: Sales | CM7: Sales | CN7: 45959 | CO7: Assende | CP7: VAR | CQ7: End of Stock | CS7: O.S of | CT7: Sales | CU7: Sales | CV7: Sales | CW7: 45966 | CX7: 45966 | CY7: Assende | CZ7: VAR | DA7: End of Stock | DC7: O.S of | DD7: Sales | DE7: Sales | DF7: Sales | DG7: 45973 | DH7: Assende | DI7: VAR | DJ7: End of Stock | DL7: O.S of | DM7: Sales | DN7: Sales | DO7: Sales | DP7: Assende | DQ7: VAR | DR7: End of Stock | DT7: O.S of | DU7: Sales | DV7: Sales | DW7: Sales | DX7: 45980 | DY7: 45987 | DZ7: Assende | EA7: VAR | EB7: End of Stock | ED7: O.S of | EE7: Sales | EF7: Sales | EG7: Sales | EH7: 45994 | EI7: Assende | EJ7: VAR | EK7: End of Stock | EM7: O.S of | EN7: Sales | EO7: Sales | EP7: Sales | EQ7: Assende | ER7: VAR | ES7: End of Stock | EU7: O.S of | EV7: Sales | EW7: Sales | EX7: Sales | EY7: Assende | EZ7: VAR | FA7: End of Stock | FC7: O.S of | FD7: Sales | FE7: Sales | FF7: Sales | FG7: Assende | FH7: VAR | FI7: End of Stock | FK7: O.S of | FL7: Sales | FM7: Sales | FN7: Sales | FO7: Assende | FP7: VAR | FQ7: End of Stock | FS7: O.S of | FT7: Sales | FU7: Sales | FV7: Sales | FW7: 46002 | FX7: 46009 | FZ7: 46016 | GA7: 46028 | GB7: Assende | GC7: VAR | GD7: End of Stock | GF7: O.S of | GG7: Sales | GH7: Sales | GI7: Sales | GJ7: 46036 | GK7: Assende | GL7: VAR | GM7: End of Stock | GO7: O.S of | GP7: Sales | GQ7: Sales | GR7: Sales | GS7: 46043 | GT7: Assende | GU7: VAR | GV7: End of Stock | GX7: O.S of | GY7: Sales | GZ7: Sales | HA7: Sales | HB7: 46050 | HC7: Assende | HD7: VAR | HE7: End of Stock | HG7: O.S of | HH7: Sales | HI7: Sales | HJ7: Sales | HK7: 46057 | HL7: Assende | HM7: VAR | HN7: End of Stock | HP7: O.S of | HQ7: Sales | HR7: Sales | HS7: Sales | HT7: 46064 | HU7: Assende | HV7: VAR | HW7: End of Stock | HY7: O.S of | HZ7: Sales | IA7: Sales | IB7: Sales | IC7: 46070 | ID7: Assende | IE7: VAR | IF7: End of Stock | IH7: O.S of | II7: Sales | IJ7: Sales | IK7: Sales | IL7: Assende | IM7: VAR | IN7: End of Stock | IP7: O.S of | IQ7: Sales | IR7: Sales | IS7: Sales | IT7: 46085 | IU7: Assende | IV7: VAR | IW7: End of Stock | IY7: O.S of | IZ7: Sales | JA7: Sales | JB7: Sales | JC7: Assende | JD7: VAR | JE7: End of Stock | JG7: O.S of | JH7: Sales | JI7: Sales | JJ7: Sales | JK7: 46099 | JL7: Assende | JM7: VAR | JN7: End of Stock | JP7: O.S of | JQ7: Sales | JR7: Sales | JS7: Sales | JT7: Assende | JU7: VAR | JV7: End of Stock | JX7: O.S of | JY7: Sales | JZ7: Sales | KA7: Sales | KB7: Assende | KC7: VAR | KD7: End of Stock | KF7: O.S of | KG7: Sales | KH7: Sales | KI7: Sales | KJ7: 46111 | KK7: Assende | KL7: VAR | KM7: End of Stock | KO7: O.S of | KP7: Sales | KQ7: Sales | KR7: Sales | KS7: 46127 | KT7: Assende | KU7: VAR | KV7: End of Stock | KX7: O.S of | KY7: Sales | KZ7: Sales | LA7: Sales | LB7: Assende | LC7: VAR | LD7: End of Stock | LF7: O.S of | LG7: Sales | LH7: Sales | LI7: Sales | LJ7: 46123 | LK7: Assende | LL7: VAR | LM7: End of Stock | LO7: O.S of | LP7: Sales | LQ7: Sales | LR7: Sales | LS7: Assende | LT7: VAR | LU7: End of Stock | LW7: O.S of | LX7: Sales | LY7: Sales | LZ7: Sales | MA7: Assende | MB7: VAR | MC7: End of Stock | ME7: O.S of | MF7: Sales | MG7: Sales | MH7: Sales | MI7: Assende | MJ7: VAR | MK7: End of Stock | MM7: O.S of | MN7: Sales | MO7: Sales | MP7: Sales | MQ7: Assende | MR7: VAR | MS7: End of Stock | MU7: O.S of | MV7: Sales | MW7: Sales | MX7: Sales | MY7: Assende | MZ7: VAR | NA7: End of Stock | NC7: O.S of | ND7: Sales | NE7: Sales | NF7: Sales | NG7: Assende | NH7: VAR | NI7: End of Stock | NK7: O.S of | NL7: Sales | NM7: Sales | NN7: Sales | NO7: Assende | NP7: VAR | NQ7: End of Stock | NS7: O.S of | NT7: Sales | NU7: Sales | NV7: Sales | NW7: Assende | NX7: VAR | NY7: End of Stock | OA7: O.S of | OB7: Sales | OC7: Sales | OD7: Sales | OE7: Assende | OF7: VAR | OG7: End of Stock | OI7: O.S of | OJ7: Sales | OK7: Sales | OL7: Sales | OM7: Assende | ON7: VAR | OO7: End of Stock | OQ7: O.S of | OR7: Sales | OS7: Sales | OT7: Sales | OU7: Assende | OV7: VAR | OW7: End of Stock | OY7: O.S of | OZ7: Sales | PA7: Sales | PB7: Sales | PC7: Assende | PD7: VAR | PE7: End of Stock | PG7: O.S of | PH7: Sales | PI7: Sales | PJ7: Sales | PK7: Assende | PL7: VAR | PM7: End of Stock | PO7: O.S of | PP7: Sales | PQ7: Sales | PR7: Sales | PS7: Assende | PT7: VAR | PU7: End of Stock | PW7: O.S of | PX7: Sales | PY7: Sales | PZ7: Sales | QA7: Assende | QB7: VAR | QC7: End of Stock | QE7: O.S of | QF7: Sales | QG7: Sales | QH7: Sales | QI7: Assende | QJ7: VAR | QK7: End of Stock | QM7: O.S of | QN7: Sales | QO7: Sales | QP7: Sales | QQ7: Assende | QR7: VAR | QS7: End of Stock | QU7: O.S of | QV7: Sales | QW7: Sales | QX7: Sales | QY7: Assende | QZ7: VAR | RA7: End of Stock | RC7: O.S of | RD7: Sales | RE7: Sales | RF7: Sales | RG7: Assende | RH7: VAR | RI7: End of Stock | RK7: O.S of | RL7: Sales | RM7: Sales | RN7: Sales | RO7: Assende | RP7: VAR | RQ7: End of Stock | RS7: O.S of | RT7: Sales | RU7: Sales | RV7: Sales | RW7: Assende | RX7: VAR | RY7: End of Stock | SA7: O.S of | SB7: Sales | SC7: Sales | SD7: Sales | SE7: Assende | SF7: VAR | SG7: End of Stock | SI7: O.S of | SJ7: Sales | SK7: Sales | SL7: Sales | SM7: Assende | SN7: VAR | SO7: End of Stock | SQ7: O.S of | SR7: Sales | SS7: Sales | ST7: Sales | SU7: Assende | SV7: VAR | SW7: End of Stock | SY7: O.S of | SZ7: Sales | TA7: Sales | TB7: Sales | TC7: Assende | TD7: VAR | TE7: End of Stock | TG7: O.S of | TH7: Sales | TI7: Sales | TJ7: Sales | TK7: Assende | TL7: VAR | TM7: End of Stock | TO7: O.S of | TP7: Sales | TQ7: Sales | TR7: Sales | TS7: Assende | TT7: VAR | TU7: End of Stock | TW7: O.S of | TX7: Sales | TY7: Sales | TZ7: Sales | UA7: Assende | UB7: VAR | UC7: End of Stock | UE7: O.S of | UF7: Sales | UG7: Sales | UH7: Sales | UI7: Assende | UJ7: VAR | UK7: End of Stock | UM7: O.S of | UN7: Sales | UO7: Sales | UP7: Sales | UQ7: Assende | UR7: VAR | US7: End of Stock | UU7: O.S of | UV7: Sales | UW7: Sales | UX7: Sales | UY7: Assende | UZ7: VAR | VA7: End of Stock | VC7: O.S of | VD7: Sales | VE7: Sales | VF7: Sales | VG7: Assende | VH7: VAR | VI7: End of Stock | VK7: O.S of | VL7: Sales | VM7: Sales | VN7: Sales | VO7: Assende | VP7: VAR | VQ7: End of Stock
H8: =H5 -> WK 36 | I8: 45901 | J8: 45901 | K8: 45901 | L8: =Q8 -> 45908 | M8: =H5 -> WK 36 | N8: =H5 -> WK 36 | P8: =P5 -> WK 37 | Q8: =I8+7 -> 45908 | R8: =Q8 -> 45908 | S8: =R8 -> 45908 | T8: =Y8 -> 45915 | U8: =V8 -> WK 37 | V8: =P5 -> WK 37 | X8: =X5 -> WK 38 | Y8: =Q8+7 -> 45915 | Z8: =Y8 -> 45915 | AA8: =Z8 -> 45915 | AB8: =AG8 -> 45922 | AC8: =AD8 -> WK 38 | AD8: =X5 -> WK 38 | AF8: =AF5 -> WK 39 | AG8: =Y8+7 -> 45922 | AH8: =AG8 -> 45922 | AI8: =AH8 -> 45922 | AJ8: =AO8 -> 45929 | AK8: =AL8 -> WK 39 | AL8: =AF5 -> WK 39 | AN8: =AN5 -> WK 40 | AO8: =AG8+7 -> 45929 | AP8: =AO8 -> 45929 | AQ8: =AP8 -> 45929 | AR8: 45933 | AS8: =AW5 -> WK 41 | AT8: =AU8 -> WK 40 | AU8: =AN5 -> WK 40 | AW8: =AW5 -> WK 41 | AX8: =AO8+7 -> 45936 | AY8: =AX8 -> 45936 | AZ8: =AY8 -> 45936 | BA8: =BE5 -> WK 42 | BB8: =BC8 -> WK 41 | BC8: =AW5 -> WK 41 | BE8: =BE5 -> WK 42 | BF8: =AX8+7 -> 45943 | BG8: =BF8 -> 45943 | BH8: =BG8 -> 45943 | BI8: 45943 | BJ8: 45947 | BK8: =BO5 -> WK 43 | BL8: =BM8 -> WK 42 | BM8: =BE5 -> WK 42 | BO8: =BO5 -> WK 43 | BP8: =BH8+7 -> 45950 | BQ8: =BP8 -> 45950 | BR8: =BQ8 -> 45950 | BS8: 45953 | BU8: 45954 | BV8: =BZ5 -> WK 44 | BW8: =BX8 -> WK 43 | BX8: =BO5 -> WK 43 | BZ8: =BZ5 -> WK 44 | CA8: =BP8+7 -> 45957 | CB8: =CA8 -> 45957 | CC8: =CB8 -> 45957 | CD8: 45957 | CE8: 45958 | CF8: =CJ5 -> WK 45 | CG8: =CH8 -> WK 44 | CH8: =BZ5 -> WK 44 | CJ8: =CJ5 -> WK 45 | CK8: =CA8+7 -> 45964 | CL8: =CK8 -> 45964 | CM8: =CL8 -> 45964 | CN8: 45967 | CO8: =CS5 -> WK 46 | CP8: =CQ8 -> WK 45 | CQ8: =CJ5 -> WK 45 | CS8: =CS5 -> WK 46 | CT8: =CK8+7 -> 45971 | CU8: =CT8 -> 45971 | CV8: =CU8 -> 45971 | CW8: 45971 | CX8: 45975 | CY8: =DC5 -> WK 47 | CZ8: =DA8 -> WK 46 | DA8: =CS5 -> WK 46 | DC8: =DC5 -> WK 47 | DD8: =CT8+7 -> 45978 | DE8: =DD8 -> 45978 | DF8: =DE8 -> 45978 | DG8: 45982 | DH8: =DL5 -> WK 48 | DI8: =DJ8 -> WK 47 | DJ8: =DC5 -> WK 47 | DL8: =DL5 -> WK 48 | DM8: =DD8+7 -> 45985 | DN8: =DM8 -> 45985 | DO8: =DN8 -> 45985 | DP8: =DT5 -> WK 49 | DQ8: =DR8 -> WK 48 | DR8: =DL5 -> WK 48 | DT8: =DT5 -> WK 49 | DU8: =DM8+7 -> 45992 | DV8: =DU8 -> 45992 | DW8: =DV8 -> 45992 | DX8: 45993 | DY8: 45996 | DZ8: =ED5 -> WK 50 | EA8: =EB8 -> WK 49 | EB8: =DT5 -> WK 49 | ED8: =ED5 -> WK 50 | EE8: =DU8+7 -> 45999 | EF8: =EE8 -> 45999 | EG8: =EF8 -> 45999 | EH8: 46002 | EI8: =EM5 -> WK 51 | EJ8: =EK8 -> WK 50 | EK8: =ED5 -> WK 50 | EM8: =EM5 -> WK 51 | EN8: =EE8+7 -> 46006 | EO8: =EN8 -> 46006 | EP8: =EO8 -> 46006 | EQ8: WK 52 | ER8: =ES8 -> WK 51 | ES8: =EM5 -> WK 51 | EU8: =EU5 -> WK 52 | EV8: =EN8+7 -> 46013 | EW8: =EV8 -> 46013 | EX8: =EW8 -> 46013 | EY8: =FK5 -> WK 02 | EZ8: =FA8 -> WK 52 | FA8: =EU5 -> WK 52 | FC8: =FC5 -> WK 01 | FD8: =EV8+7 -> 46020 | FE8: =FD8 -> 46020 | FF8: =FE8 -> 46020 | FG8: =FC5 -> WK 01 | FH8: =FI8 -> WK 01 | FI8: =FC5 -> WK 01 | FK8: =FK5 -> WK 02 | FL8: =FD8+7 -> 46027 | FM8: =FL8 -> 46027 | FN8: =FM8 -> 46027 | FO8: =FS5 -> WK 03 | FP8: =FQ8 -> WK 02 | FQ8: =FK5 -> WK 02 | FS8: =FS5 -> WK 03 | FT8: =FL8+7 -> 46034 | FU8: =FT8 -> 46034 | FV8: =FU8 -> 46034 | FW8: 46038 | FX8: 46037 | FZ8: 46038 | GA8: 46038 | GB8: =GF5 -> WK 04 | GC8: =GD8 -> WK 03 | GD8: =FS5 -> WK 03 | GF8: =GF5 -> WK 04 | GG8: =FT8+7 -> 46041 | GH8: =GG8 -> 46041 | GI8: =GH8 -> 46041 | GJ8: 46045 | GK8: =GO5 -> WK 05 | GL8: =GM8 -> WK 04 | GM8: =GF5 -> WK 04 | GO8: =GO5 -> WK 05 | GP8: =GG8+7 -> 46048 | GQ8: =GP8 -> 46048 | GR8: =GQ8 -> 46048 | GS8: 46052 | GT8: =GX5 -> WK 06 | GU8: =GV8 -> WK 05 | GV8: =GO5 -> WK 05 | GX8: =GX5 -> WK 06 | GY8: =GP8+7 -> 46055 | GZ8: =GY8 -> 46055 | HA8: =GZ8 -> 46055 | HB8: 46059 | HC8: =HG5 -> WK 07 | HD8: =HE8 -> WK 06 | HE8: =GX5 -> WK 06 | HG8: =HG5 -> WK 07 | HH8: =GY8+7 -> 46062 | HI8: =HH8 -> 46062 | HJ8: =HI8 -> 46062 | HK8: 46066 | HL8: =HP5 -> WK 08 | HM8: =HN8 -> WK 07 | HN8: =HG5 -> WK 07 | HP8: =HP5 -> WK 08 | HQ8: =HH8+7 -> 46069 | HR8: =HQ8 -> 46069 | HS8: =HR8 -> 46069 | HT8: 46073 | HU8: =HY5 -> WK 09 | HV8: =HW8 -> WK 08 | HW8: =HP5 -> WK 08 | HY8: =HY5 -> WK 09 | HZ8: =HQ8+7 -> 46076 | IA8: =HZ8 -> 46076 | IB8: =IA8 -> 46076 | IC8: 46080 | ID8: =IH5 -> WK 10 | IE8: =IF8 -> WK 09 | IF8: =HY5 -> WK 09 | IH8: =IH5 -> WK 10 | II8: =HZ8+7 -> 46083 | IJ8: =II8 -> 46083 | IK8: =IJ8 -> 46083 | IL8: =IP5 -> WK 11 | IM8: =IN8 -> WK 10 | IN8: =IH5 -> WK 10 | IP8: =IP5 -> WK 11 | IQ8: =II8+7 -> 46090 | IR8: =IQ8 -> 46090 | IS8: =IR8 -> 46090 | IT8: 46094 | IU8: =IY5 -> WK 12 | IV8: =IW8 -> WK 11 | IW8: =IP5 -> WK 11 | IY8: =IY5 -> WK 12 | IZ8: =IQ8+7 -> 46097 | JA8: =IZ8 -> 46097 | JB8: =JA8 -> 46097 | JC8: =JG5 -> WK 13 | JD8: =JE8 -> WK 12 | JE8: =IY5 -> WK 12 | JG8: =JG5 -> WK 13 | JH8: =IZ8+7 -> 46104 | JI8: =JH8 -> 46104 | JJ8: =JI8 -> 46104 | JK8: 46108 | JL8: =JP5 -> WK 14 | JM8: =JN8 -> WK 13 | JN8: =JG5 -> WK 13 | JP8: =JP5 -> WK 14 | JQ8: =JH8+7 -> 46111 | JR8: =JQ8 -> 46111 | JS8: =JR8 -> 46111 | JT8: =JX5 -> WK 15 | JU8: =JV8 -> WK 14 | JV8: =JP5 -> WK 14 | JX8: =JX5 -> WK 15 | JY8: =JQ8+7 -> 46118 | JZ8: =JY8 -> 46118 | KA8: =JZ8 -> 46118 | KB8: =KF5 -> WK 16 | KC8: =KD8 -> WK 15 | KD8: =JX5 -> WK 15 | KF8: =KF5 -> WK 16 | KG8: =JY8+7 -> 46125 | KH8: =KG8 -> 46125 | KI8: =KH8 -> 46125 | KJ8: 46126 | KK8: =KO5 -> WK 17 | KL8: =KM8 -> WK 16 | KM8: =KF5 -> WK 16 | KO8: =KO5 -> WK 17 | KP8: =KG8+7 -> 46132 | KQ8: =KP8 -> 46132 | KR8: =KQ8 -> 46132 | KS8: 46136 | KT8: =KX5 -> WK 18 | KU8: =KV8 -> WK 17 | KV8: =KO5 -> WK 17 | KX8: =KX5 -> WK 18 | KY8: =KP8+7 -> 46139 | KZ8: =KY8 -> 46139 | LA8: =KZ8 -> 46139 | LB8: =LF5 -> WK 19 | LC8: =LD8 -> WK 18 | LD8: =KX5 -> WK 18 | LF8: =LF5 -> WK 19 | LG8: =KY8+7 -> 46146 | LH8: =LG8 -> 46146 | LI8: =LH8 -> 46146 | LJ8: 46150 | LK8: =LO5 -> WK 20 | LL8: =LM8 -> WK 19 | LM8: =LF5 -> WK 19 | LO8: =LO5 -> WK 20 | LP8: =LG8+7 -> 46153 | LQ8: =LP8 -> 46153 | LR8: =LQ8 -> 46153 | LS8: =LW5 -> WK 21 | LT8: =LU8 -> WK 20 | LU8: =LO5 -> WK 20 | LW8: =LW5 -> WK 21 | LX8: =LP8+7 -> 46160 | LY8: =LX8 -> 46160 | LZ8: =LY8 -> 46160 | MA8: =ME5 -> WK 22 | MB8: =MC8 -> WK 21 | MC8: =LW5 -> WK 21 | ME8: =ME5 -> WK 22 | MF8: =LX8+7 -> 46167 | MG8: =MF8 -> 46167 | MH8: =MG8 -> 46167 | MI8: =MM5 -> WK 23 | MJ8: =MK8 -> WK 22 | MK8: =ME5 -> WK 22 | MM8: =MM5 -> WK 23 | MN8: =MF8+7 -> 46174 | MO8: =MN8 -> 46174 | MP8: =MO8 -> 46174 | MQ8: =MU5 -> WK 24 | MR8: =MS8 -> WK 23 | MS8: =MM5 -> WK 23 | MU8: =MU5 -> WK 24 | MV8: =MN8+7 -> 46181 | MW8: =MV8 -> 46181 | MX8: =MW8 -> 46181 | MY8: =NC5 -> WK 25 | MZ8: =NA8 -> WK 24 | NA8: =MU5 -> WK 24 | NC8: =NC5 -> WK 25 | ND8: =MV8+7 -> 46188 | NE8: =ND8 -> 46188 | NF8: =NE8 -> 46188 | NG8: =NK5 -> WK 26 | NH8: =NI8 -> WK 25 | NI8: =NC5 -> WK 25 | NK8: =NK5 -> WK 26 | NL8: =ND8+7 -> 46195 | NM8: =NL8 -> 46195 | NN8: =NM8 -> 46195 | NO8: =NS5 -> WK 27 | NP8: =NQ8 -> WK 26 | NQ8: =NK5 -> WK 26 | NS8: =NS5 -> WK 27 | NT8: =NL8+7 -> 46202 | NU8: =NT8 -> 46202 | NV8: =NU8 -> 46202 | NW8: =OA5 -> WK 28 | NX8: =NY8 -> WK 27 | NY8: =NS5 -> WK 27 | OA8: =OA5 -> WK 28 | OB8: =NT8+7 -> 46209 | OC8: =OB8 -> 46209 | OD8: =OC8 -> 46209 | OE8: =OI5 -> WK 29 | OF8: =OG8 -> WK 28 | OG8: =OA5 -> WK 28 | OI8: =OI5 -> WK 29 | OJ8: =OB8+7 -> 46216 | OK8: =OJ8 -> 46216 | OL8: =OK8 -> 46216 | OM8: =OQ5 -> WK 30 | ON8: =OO8 -> WK 29 | OO8: =OI5 -> WK 29 | OQ8: =OQ5 -> WK 30 | OR8: =OJ8+7 -> 46223 | OS8: =OR8 -> 46223 | OT8: =OS8 -> 46223 | OU8: =OY5 -> WK 31 | OV8: =OW8 -> WK 30 | OW8: =OQ5 -> WK 30 | OY8: =OY5 -> WK 31 | OZ8: =OR8+7 -> 46230 | PA8: =OZ8 -> 46230 | PB8: =PA8 -> 46230 | PC8: =PG5 -> WK 32 | PD8: =PE8 -> WK 31 | PE8: =OY5 -> WK 31 | PG8: =PG5 -> WK 32 | PH8: =OZ8+7 -> 46237 | PI8: =PH8 -> 46237 | PJ8: =PI8 -> 46237 | PK8: =PO5 -> WK 33 | PL8: =PM8 -> WK 32 | PM8: =PG5 -> WK 32 | PO8: =PO5 -> WK 33 | PP8: =PH8+7 -> 46244 | PQ8: =PP8 -> 46244 | PR8: =PQ8 -> 46244 | PS8: =PW5 -> WK 34 | PT8: =PU8 -> WK 33 | PU8: =PO5 -> WK 33 | PW8: =PW5 -> WK 34 | PX8: =PP8+7 -> 46251 | PY8: =PX8 -> 46251 | PZ8: =PY8 -> 46251 | QA8: =QE5 -> WK 35 | QB8: =QC8 -> WK 34 | QC8: =PW5 -> WK 34 | QE8: =QE5 -> WK 35 | QF8: =PX8+7 -> 46258 | QG8: =QF8 -> 46258 | QH8: =QG8 -> 46258 | QI8: =QM5 -> WK 36 | QJ8: =QK8 -> WK 35 | QK8: =QE5 -> WK 35 | QM8: =QM5 -> WK 36 | QN8: =QF8+7 -> 46265 | QO8: =QN8 -> 46265 | QP8: =QO8 -> 46265 | QQ8: =QU5 -> WK 37 | QR8: =QS8 -> WK 36 | QS8: =QM5 -> WK 36 | QU8: =QU5 -> WK 37 | QV8: =QN8+7 -> 46272 | QW8: =QV8 -> 46272 | QX8: =QW8 -> 46272 | QY8: =RC5 -> WK 38 | QZ8: =RA8 -> WK 37 | RA8: =QU5 -> WK 37 | RC8: =RC5 -> WK 38 | RD8: =QV8+7 -> 46279 | RE8: =RD8 -> 46279 | RF8: =RE8 -> 46279 | RG8: =RK5 -> WK 39 | RH8: =RI8 -> WK 38 | RI8: =RC5 -> WK 38 | RK8: =RK5 -> WK 39 | RL8: =RD8+7 -> 46286 | RM8: =RL8 -> 46286 | RN8: =RM8 -> 46286 | RO8: =RS5 -> WK 40 | RP8: =RQ8 -> WK 39 | RQ8: =RK5 -> WK 39 | RS8: =RS5 -> WK 40 | RT8: =RL8+7 -> 46293 | RU8: =RT8 -> 46293 | RV8: =RU8 -> 46293 | RW8: =SA5 -> WK 41 | RX8: =RY8 -> WK 40 | RY8: =RS5 -> WK 40 | SA8: =SA5 -> WK 41 | SB8: =RT8+7 -> 46300 | SC8: =SB8 -> 46300 | SD8: =SC8 -> 46300 | SE8: =SI5 -> WK 42 | SF8: =SG8 -> WK 41 | SG8: =SA5 -> WK 41 | SI8: =SI5 -> WK 42 | SJ8: =SB8+7 -> 46307 | SK8: =SJ8 -> 46307 | SL8: =SK8 -> 46307 | SM8: =SQ5 -> WK 43 | SN8: =SO8 -> WK 42 | SO8: =SI5 -> WK 42 | SQ8: =SQ5 -> WK 43 | SR8: =SJ8+7 -> 46314 | SS8: =SR8 -> 46314 | ST8: =SS8 -> 46314 | SU8: =SY5 -> WK 44 | SV8: =SW8 -> WK 43 | SW8: =SQ5 -> WK 43 | SY8: =SY5 -> WK 44 | SZ8: =SR8+7 -> 46321 | TA8: =SZ8 -> 46321 | TB8: =TA8 -> 46321 | TC8: =TG5 -> WK 45 | TD8: =TE8 -> WK 44 | TE8: =SY5 -> WK 44 | TG8: =TG5 -> WK 45 | TH8: =SZ8+7 -> 46328 | TI8: =TH8 -> 46328 | TJ8: =TI8 -> 46328 | TK8: =TO5 -> WK 46 | TL8: =TM8 -> WK 45 | TM8: =TG5 -> WK 45 | TO8: =TO5 -> WK 46 | TP8: =TH8+7 -> 46335 | TQ8: =TP8 -> 46335 | TR8: =TQ8 -> 46335 | TS8: =TW5 -> WK 47 | TT8: =TU8 -> WK 46 | TU8: =TO5 -> WK 46 | TW8: =TW5 -> WK 47 | TX8: =TP8+7 -> 46342 | TY8: =TX8 -> 46342 | TZ8: =TY8 -> 46342 | UA8: =UE5 -> WK 48 | UB8: =UC8 -> WK 47 | UC8: =TW5 -> WK 47 | UE8: =UE5 -> WK 48 | UF8: =TX8+7 -> 46349 | UG8: =UF8 -> 46349 | UH8: =UG8 -> 46349 | UI8: =UM5 -> WK 49 | UJ8: =UK8 -> WK 48 | UK8: =UE5 -> WK 48 | UM8: =UM5 -> WK 49 | UN8: =UF8+7 -> 46356 | UO8: =UN8 -> 46356 | UP8: =UO8 -> 46356 | UQ8: =UU5 -> WK 50 | UR8: =US8 -> WK 49 | US8: =UM5 -> WK 49 | UU8: =UU5 -> WK 50 | UV8: =UN8+7 -> 46363 | UW8: =UV8 -> 46363 | UX8: =UW8 -> 46363 | UY8: =VC5 -> WK 51 | UZ8: =VA8 -> WK 50 | VA8: =UU5 -> WK 50 | VC8: =VC5 -> WK 51 | VD8: =UV8+7 -> 46370 | VE8: =VD8 -> 46370 | VF8: =VE8 -> 46370 | VG8: =VK5 -> WK 52 | VH8: =VI8 -> WK 51 | VI8: =VC5 -> WK 51 | VK8: =VK5 -> WK 52 | VL8: =VD8+7 -> 46377 | VM8: =VL8 -> 46377 | VN8: =VM8 -> 46377 | VO8: =VS5 -> 0 | VP8: =VQ8 -> WK 52 | VQ8: =VK5 -> WK 52
A10: VOLVO | B10: JCI2 LH | C10: 32248362 | D10: 4172750 | E10: 40 | H10: 1720 | I10: =IFERROR(VLOOKUP($D10,'Adient Assende (Belgium) WK.17'!$B:C,J$1,0),0) -> 0 | J10: =IFERROR(VLOOKUP($D10,'Adient Arendal (Malzia) WK.12'!$B:C,J$1,0),0) -> 0 | K10: =IFERROR(VLOOKUP($D10,'Adient Taizhou (China) WK.16'!$B:C,J$1,0),0) -> 0 | L10: 320 | M10: 0 | N10: =((H10-(L10+J10+K10))+M10) -> 1400 | P10: =N10 -> 1400 | Q10: =IFERROR(VLOOKUP($D10,'Adient Assende (Belgium) WK.17'!$B:K,R$1,0),0) -> 320 | R10: =IFERROR(VLOOKUP($D10,'Adient Arendal (Malzia) WK.12'!$B:K,R$1,0),0) -> 0 | S10: =IFERROR(VLOOKUP($D10,'Adient Taizhou (China) WK.16'!$B:K,R$1,0),0) -> 0 | T10: 160 | U10: 0 | V10: =((P10-(T10+R10+S10))+U10) -> 1240 | X10: =V10 -> 1240 | Y10: =IFERROR(VLOOKUP($D10,'Adient Assende (Belgium) WK.17'!$B:S,Z$1,0),0) -> 160 | Z10: =IFERROR(VLOOKUP($D10,'Adient Arendal (Malzia) WK.12'!$B:S,Z$1,0),0) -> 0 | AA10: =IFERROR(VLOOKUP($D10,'Adient Taizhou (China) WK.16'!$B:S,Z$1,0),0) -> 0 | AB10: 320 | AC10: 0 | AD10: =((X10-(AB10+Z10+AA10))+AC10) -> 920 | AF10: =AD10 -> 920 | AG10: =IFERROR(VLOOKUP($D10,'Adient Assende (Belgium) WK.17'!$B:AA,AH$1,0),0) -> 320 | AH10: =IFERROR(VLOOKUP($D10,'Adient Arendal (Malzia) WK.12'!$B:AA,AH$1,0),0) -> 0 | AI10: =IFERROR(VLOOKUP($D10,'Adient Taizhou (China) WK.16'!$B:AA,AH$1,0),0) -> 0 | AJ10: 160 | AK10: 0 | AL10: =((AF10-(AJ10+AH10+AI10))+AK10) -> 760 | AN10: =AL10 -> 760 | AO10: =IFERROR(VLOOKUP($D10,'Adient Assende (Belgium) WK.17'!$B:AI,AP$1,0),0) -> 160 | AP10: =IFERROR(VLOOKUP($D10,'Adient Arendal (Malzia) WK.12'!$B:AI,AP$1,0),0) -> 0 | AQ10: =IFERROR(VLOOKUP($D10,'Adient Taizhou (China) WK.16'!$B:AI,AP$1,0),0) -> 0 | AR10: 160 | AS10: 160 | AT10: 0 | AU10: =((AN10-(AS10+AP10+AQ10))+AT10)+AR10 -> 760 | AW10: =AU10 -> 760 | AX10: =IFERROR(VLOOKUP($D10,'Adient Assende (Belgium) WK.17'!$B:AR,AY$1,0),0) -> 160 | AY10: =IFERROR(VLOOKUP($D10,'Adient Arendal (Malzia) WK.12'!$B:AR,AY$1,0),0) -> 0 | AZ10: =IFERROR(VLOOKUP($D10,'Adient Taizhou (China) WK.16'!$B:AU,AY$1,0),0) -> 0 | BA10: 320 | BB10: 0 | BC10: =((AW10-(BA10+AY10+AZ10))+BB10) -> 440 | BE10: =BC10 -> 440 | BF10: =IFERROR(VLOOKUP($D10,'Adient Assende (Belgium) WK.17'!$B:AX,BG$1,0),0) -> 320 | BG10: =IFERROR(VLOOKUP($D10,'Adient Arendal (Malzia) WK.12'!$B:AZ,BG$1,0),0) -> 0 | BH10: =IFERROR(VLOOKUP($D10,'Adient Taizhou (China) WK.16'!$B:BB,BG$1,0),0) -> 0 | BI10: 120 | BJ10: 0 | BK10: 160 | BL10: 0 | BM10: =((BE10-(BK10+BG10+BH10))+BL10)+BI10+BJ10 -> 400 | BO10: =BM10 -> 400 | BP10: =IFERROR(VLOOKUP($D10,'Adient Assende (Belgium) WK.17'!$B:BH,BQ$1,0),0) -> 160 | BQ10: =IFERROR(VLOOKUP($D10,'Adient Arendal (Malzia) WK.12'!$B:BI,BQ$1,0),0) -> 0 | BR10: =IFERROR(VLOOKUP($D10,'Adient Taizhou (China) WK.16'!$B:BL,BQ$1,0),0) -> 0 | BS10: 200 | BT10: 600 | BU10: 0 | BV10: 160 | BW10: 0 | BX10: =((BO10-(BV10+BQ10+BR10))+BW10)+BS10+BT10+BU10 -> 1040 | BZ10: =BX10 -> 1040 | CA10: =IFERROR(VLOOKUP($D10,'Adient Assende (Belgium) WK.17'!$B:BS,CB$1,0),0) -> 160 | CB10: =IFERROR(VLOOKUP($D10,'Adient Arendal (Malzia) WK.12'!$B:BT,CB$1,0),0) -> 0 | CC10: =IFERROR(VLOOKUP($D10,'Adient Taizhou (China) WK.16'!$B:BW,CB$1,0),0) -> 0 | CD10: 0 | CE10: 0 | CF10: 480 | CG10: 0 | CH10: =((BZ10-(CF10+CB10+CC10))+CG10)+CD10+CE10 -> 560 | CJ10: =CH10 -> 560 | CK10: =IFERROR(VLOOKUP($D10,'Adient Assende (Belgium) WK.17'!$B:CC,CL$1,0),0) -> 480 | CL10: =IFERROR(VLOOKUP($D10,'Adient Arendal (Malzia) WK.12'!$B:CD,CL$1,0),0) -> 0 | CM10: =IFERROR(VLOOKUP($D10,'Adient Taizhou (China) WK.16'!$B:CG,CL$1,0),0) -> 0 | CN10: 0 | CO10: 0 | CP10: 0 | CQ10: =((CJ10-(CO10+CL10+CM10))+CP10)+CN10 -> 560 | CS10: =CQ10 -> 560 | CT10: =IFERROR(VLOOKUP($D10,'Adient Assende (Belgium) WK.17'!$B:CL,CU$1,0),0) -> 0 | CU10: =IFERROR(VLOOKUP($D10,'Adient Arendal (Malzia) WK.12'!$B:CM,CU$1,0),0) -> 0 | CV10: =IFERROR(VLOOKUP($D10,'Adient Taizhou (China) WK.16'!$B:CP,CU$1,0),0) -> 0 | CW10: 0 | CX10: 200 | CY10: 160 | CZ10: 0 | DA10: =((CS10-(CY10+CU10+CV10))+CZ10)+CW10+CX10 -> 600 | DC10: =DA10 -> 600 | DD10: =IFERROR(VLOOKUP($D10,'Adient Assende (Belgium) WK.17'!$B:CS,DE$1,0),0) -> 160 | DE10: =IFERROR(VLOOKUP($D10,'Adient Arendal (Malzia) WK.12'!$B:CU,DE$1,0),0) -> 0 | DF10: =IFERROR(VLOOKUP($D10,'Adient Taizhou (China) WK.16'!$B:CX,DE$1,0),0) -> 0 | DG10: 160 | DH10: 160 | DI10: 0 | DJ10: =((DC10-(DH10+DE10+DF10))+DI10)+DG10 -> 600 | DL10: =DJ10 -> 600 | DM10: =IFERROR(VLOOKUP($D10,'Adient Assende (Belgium) WK.17'!$B:DB,DN$1,0),0) -> 160 | DN10: =IFERROR(VLOOKUP($D10,'Adient Arendal (Malzia) WK.12'!$B:DC,DN$1,0),0) -> 0 | DO10: =IFERROR(VLOOKUP($D10,'Adient Taizhou (China) WK.16'!$B:DF,DN$1,0),0) -> 0 | DP10: 160 | DQ10: 0 | DR10: =((DL10-(DN10+DO10+DP10)+DQ10)) -> 440 | DT10: =DR10 -> 440 | DU10: =IFERROR(VLOOKUP($D10,'Adient Assende (Belgium) WK.17'!$B:DJ,DV$1,0),0) -> 160 | DV10: =IFERROR(VLOOKUP($D10,'Adient Arendal (Malzia) WK.12'!$B:DK,DV$1,0),0) -> 0 | DW10: =IFERROR(VLOOKUP($D10,'Adient Taizhou (China) WK.16'!$B:DN,DV$1,0),0) -> 0 | DX10: 40 | DY10: 400 | DZ10: 320 | EA10: 0 | EB10: =((DT10-(DV10+DW10+DZ10)+EA10))+DX10+DY10 -> 560 | ED10: =EB10 -> 560 | EE10: =IFERROR(VLOOKUP($D10,'Adient Assende (Belgium) WK.17'!$B:DR,EF$1,0),0) -> 320 | EF10: =IFERROR(VLOOKUP($D10,'Adient Arendal (Malzia) WK.12'!$B:DS,EF$1,0),0) -> 0 | EG10: =IFERROR(VLOOKUP($D10,'Adient Taizhou (China) WK.16'!$B:DV,EF$1,0),0) -> 0 | EH10: 440 | EI10: 160 | EJ10: 0 | EK10: =((ED10-(EF10+EG10+EI10)+EJ10))+EH10 -> 840 | EM10: =EK10 -> 840 | EN10: =IFERROR(VLOOKUP($D10,'Adient Assende (Belgium) WK.17'!$B:DZ,EO$1,0),0) -> 160 | EO10: =IFERROR(VLOOKUP($D10,'Adient Arendal (Malzia) WK.12'!$B:EA,EO$1,0),0) -> 0 | EP10: =IFERROR(VLOOKUP($D10,'Adient Taizhou (China) WK.16'!$B:ED,EO$1,0),0) -> 0 | EQ10: 160 | ER10: 0 | ES10: =((EM10-(EO10+EP10+EQ10)+ER10)) -> 680 | EU10: =ES10 -> 680 | EV10: =IFERROR(VLOOKUP($D10,'Adient Assende (Belgium) WK.17'!$B:EH,EW$1,0),0) -> 160 | EW10: =IFERROR(VLOOKUP($D10,'Adient Arendal (Malzia) WK.12'!$B:EI,EW$1,0),0) -> 0 | EX10: =IFERROR(VLOOKUP($D10,'Adient Taizhou (China) WK.16'!$B:EL,EW$1,0),0) -> 0 | EY10: 0 | EZ10: 0 | FA10: =((EU10-(EW10+EX10+EY10)+EZ10)) -> 680 | FC10: =FA10 -> 680 | FD10: =IFERROR(VLOOKUP($D10,'Adient Assende (Belgium) WK.17'!$B:EP,FE$1,0),0) -> 0 | FE10: =IFERROR(VLOOKUP($D10,'Adient Arendal (Malzia) WK.12'!$B:EQ,FE$1,0),0) -> 0 | FF10: =IFERROR(VLOOKUP($D10,'Adient Taizhou (China) WK.16'!$B:ET,FE$1,0),0) -> 0 | FG10: 0 | FH10: 0 | FI10: =((FC10-(FE10+FF10+FG10)+FH10)) -> 680 | FK10: =FI10 -> 680 | FL10: =IFERROR(VLOOKUP($D10,'Adient Assende (Belgium) WK.17'!$B:EX,FM$1,0),0) -> 0 | FM10: =IFERROR(VLOOKUP($D10,'Adient Arendal (Malzia) WK.12'!$B:EY,FM$1,0),0) -> 0 | FN10: =IFERROR(VLOOKUP($D10,'Adient Taizhou (China) WK.16'!$B:FB,FM$1,0),0) -> 0 | FO10: 160 | FP10: 0 | FQ10: =((FK10-(FM10+FN10+FO10)+FP10)) -> 520 | FS10: =FQ10 -> 520 | FT10: =IFERROR(VLOOKUP($D10,'Adient Assende (Belgium) WK.17'!$B:FF,FU$1,0),0) -> 160 | FU10: =IFERROR(VLOOKUP($D10,'Adient Arendal (Malzia) WK.12'!$B:FG,FU$1,0),0) -> 0 | FV10: =IFERROR(VLOOKUP($D10,'Adient Taizhou (China) WK.16'!$B:FJ,FU$1,0),0) -> 0 | FW10: 200 | FX10: 200 | FY10: 80 | FZ10: 40 | GA10: 320 | GB10: 0 | GC10: 0 | GD10: =((FS10-(FU10+FV10+GB10)+GC10))+FW10+FX10+FY10+FZ10+GA10 -> 1360 | GF10: =GD10 -> 1360 | GG10: =IFERROR(VLOOKUP($D10,'Adient Assende (Belgium) WK.17'!$B:FN,GH$1,0),0) -> 0 | GH10: =IFERROR(VLOOKUP($D10,'Adient Arendal (Malzia) WK.12'!$B:FO,GH$1,0),0) -> 0 | GI10: =IFERROR(VLOOKUP($D10,'Adient Taizhou (China) WK.16'!$B:FR,GH$1,0),0) -> 0 | GJ10: 0 | GK10: 320 | GL10: 0 | GM10: =((GF10-(GH10+GI10+GK10)+GL10))+GJ10 -> 1040 | GO10: =GM10 -> 1040 | GP10: =IFERROR(VLOOKUP($D10,'Adient Assende (Belgium) WK.17'!$B:FV,GQ$1,0),0) -> 320 | GQ10: =IFERROR(VLOOKUP($D10,'Adient Arendal (Malzia) WK.12'!$B:FW,GQ$1,0),0) -> 0 | GR10: =IFERROR(VLOOKUP($D10,'Adient Taizhou (China) WK.16'!$B:FZ,GQ$1,0),0) -> 0 | GS10: 0 | GT10: 160 | GU10: 0 | GV10: =((GO10-(GQ10+GR10+GT10)+GU10))+GS10 -> 880 | GX10: =GV10 -> 880 | GY10: =IFERROR(VLOOKUP($D10,'Adient Assende (Belgium) WK.17'!$B:GD,GZ$1,0),0) -> 160 | GZ10: =IFERROR(VLOOKUP($D10,'Adient Arendal (Malzia) WK.12'!$B:GE,GZ$1,0),0) -> 0 | HA10: =IFERROR(VLOOKUP($D10,'Adient Taizhou (China) WK.16'!$B:GH,GZ$1,0),0) -> 0 | HB10: 320 | HC10: 160 | HD10: 0 | HE10: =((GX10-(GZ10+HA10+HC10)+HD10))+HB10 -> 1040 | HG10: =HE10 -> 1040 | HH10: =IFERROR(VLOOKUP($D10,'Adient Assende (Belgium) WK.17'!$B:GL,HI$1,0),0) -> 160 | HI10: =IFERROR(VLOOKUP($D10,'Adient Arendal (Malzia) WK.12'!$B:GM,HI$1,0),0) -> 0 | HJ10: =IFERROR(VLOOKUP($D10,'Adient Taizhou (China) WK.16'!$B:GP,HI$1,0),0) -> 0 | HK10: 120 | HL10: 0 | HM10: 0 | HN10: =((HG10-(HI10+HJ10+HL10)+HM10))+HK10 -> 1160 | HP10: =HN10 -> 1160 | HQ10: =IFERROR(VLOOKUP($D10,'Adient Assende (Belgium) WK.17'!$B:GT,HR$1,0),0) -> 0 | HR10: =IFERROR(VLOOKUP($D10,'Adient Arendal (Malzia) WK.12'!$B:GU,HR$1,0),0) -> 0 | HS10: =IFERROR(VLOOKUP($D10,'Adient Taizhou (China) WK.16'!$B:GX,HR$1,0),0) -> 0 | HT10: 80 | HU10: 160 | HV10: 0 | HW10: =((HP10-(HR10+HS10+HU10)+HV10))+HT10 -> 1080 | HY10: =HW10 -> 1080 | HZ10: =IFERROR(VLOOKUP($D10,'Adient Assende (Belgium) WK.17'!$B:HB,IA$1,0),0) -> 160 | IA10: =IFERROR(VLOOKUP($D10,'Adient Arendal (Malzia) WK.12'!$B:HC,IA$1,0),0) -> 0 | IB10: =IFERROR(VLOOKUP($D10,'Adient Taizhou (China) WK.16'!$B:HF,IA$1,0),0) -> 0 | IC10: 0 | ID10: 320 | IE10: 0 | IF10: =((HY10-(IA10+IB10+ID10)+IE10))+IC10 -> 760 | IH10: =IF10 -> 760 | II10: =IFERROR(VLOOKUP($D10,'Adient Assende (Belgium) WK.17'!$B:HJ,IJ$1,0),0) -> 320 | IJ10: =IFERROR(VLOOKUP($D10,'Adient Arendal (Malzia) WK.12'!$B:HK,IJ$1,0),0) -> 0 | IK10: =IFERROR(VLOOKUP($D10,'Adient Taizhou (China) WK.16'!$B:HN,IJ$1,0),0) -> 0 | IL10: 160 | IM10: 0 | IN10: =((IH10-(IJ10+IK10+IL10)+IM10)) -> 600 | IP10: =IN10 -> 600 | IQ10: =IFERROR(VLOOKUP($D10,'Adient Assende (Belgium) WK.17'!$B:HR,IR$1,0),0) -> 160 | IR10: =IFERROR(VLOOKUP($D10,'Adient Arendal (Malzia) WK.12'!$B:HS,IR$1,0),0) -> 0 | IS10: =IFERROR(VLOOKUP($D10,'Adient Taizhou (China) WK.16'!$B:HV,IR$1,0),0) -> 0 | IT10: 240 | IU10: 320 | IV10: 0 | IW10: =((IP10-(IR10+IS10+IU10)+IV10))+IT10 -> 520 | IY10: =IW10 -> 520 | IZ10: =IFERROR(VLOOKUP($D10,'Adient Assende (Belgium) WK.17'!$B:HZ,JA$1,0),0) -> 320 | JA10: =IFERROR(VLOOKUP($D10,'Adient Arendal (Malzia) WK.12'!$B:IA,JA$1,0),0) -> 0 | JB10: =IFERROR(VLOOKUP($D10,'Adient Taizhou (China) WK.16'!$B:ID,JA$1,0),0) -> 0 | JC10: 0 | JD10: 0 | JE10: =((IY10-(JA10+JB10+JC10)+JD10)) -> 520 | JG10: =JE10 -> 520 | JH10: =IFERROR(VLOOKUP($D10,'Adient Assende (Belgium) WK.17'!$B:IH,JI$1,0),0) -> 0 | JI10: =IFERROR(VLOOKUP($D10,'Adient Arendal (Malzia) WK.12'!$B:II,JI$1,0),0) -> 0 | JJ10: =IFERROR(VLOOKUP($D10,'Adient Taizhou (China) WK.16'!$B:IL,JI$1,0),0) -> 0 | JK10: 440 | JL10: 480 | JM10: 0 | JN10: =((JG10-(JI10+JJ10+JL10)+JM10))+JK10 -> 480 | JP10: =JN10 -> 480 | JQ10: =IFERROR(VLOOKUP($D10,'Adient Assende (Belgium) WK.17'!$B:IP,JR$1,0),0) -> 480 | JR10: =IFERROR(VLOOKUP($D10,'Adient Arendal (Malzia) WK.12'!$B:IQ,JR$1,0),0) -> 0 | JS10: =IFERROR(VLOOKUP($D10,'Adient Taizhou (China) WK.16'!$B:IT,JR$1,0),0) -> 0 | JT10: 0 | JU10: 0 | JV10: =((JP10-(JR10+JS10+JT10)+JU10)) -> 480 | JX10: =JV10 -> 480 | JY10: =IFERROR(VLOOKUP($D10,'Adient Assende (Belgium) WK.17'!$B:IX,JZ$1,0),0) -> 0 | JZ10: =IFERROR(VLOOKUP($D10,'Adient Arendal (Malzia) WK.12'!$B:IY,JZ$1,0),0) -> 0 | KA10: =IFERROR(VLOOKUP($D10,'Adient Taizhou (China) WK.16'!$B:JB,JZ$1,0),0) -> 0 | KB10: 160 | KC10: 0 | KD10: =((JX10-(JZ10+KA10+KB10)+KC10)) -> 320 | KF10: =KD10 -> 320 | KG10: =IFERROR(VLOOKUP($D10,'Adient Assende (Belgium) WK.17'!$B:JF,KH$1,0),0) -> 160 | KH10: =IFERROR(VLOOKUP($D10,'Adient Arendal (Malzia) WK.12'!$B:JG,KH$1,0),0) -> 0 | KI10: =IFERROR(VLOOKUP($D10,'Adient Taizhou (China) WK.16'!$B:JJ,KH$1,0),0) -> 0 | KJ10: 0 | KK10: 0 | KL10: 0 | KM10: =((KF10-(KH10+KI10+KK10)+KL10))+KJ10 -> 320 | KO10: =KM10 -> 320 | KP10: =IFERROR(VLOOKUP($D10,'Adient Assende (Belgium) WK.17'!$B:JN,KQ$1,0),0) -> 0 | KQ10: =IFERROR(VLOOKUP($D10,'Adient Arendal (Malzia) WK.12'!$B:JO,KQ$1,0),0) -> 0 | KR10: =IFERROR(VLOOKUP($D10,'Adient Taizhou (China) WK.16'!$B:JR,KQ$1,0),0) -> 0 | KS10: 680 | KT10: 160 | KU10: 0 | KV10: =((KO10-(KQ10+KR10+KT10)+KU10))+KS10 -> 840 | KX10: =KV10 -> 840 | KY10: =IFERROR(VLOOKUP($D10,'Adient Assende (Belgium) WK.17'!$B:JV,KZ$1,0),0) -> 160 | KZ10: =IFERROR(VLOOKUP($D10,'Adient Arendal (Malzia) WK.12'!$B:JW,KZ$1,0),0) -> 0 | LA10: =IFERROR(VLOOKUP($D10,'Adient Taizhou (China) WK.16'!$B:JZ,KZ$1,0),0) -> 0 | LB10: 0 | LC10: 0 | LD10: =((KX10-(KZ10+LA10+LB10)+LC10)) -> 840 | LF10: =LD10 -> 840 | LG10: =IFERROR(VLOOKUP($D10,'Adient Assende (Belgium) WK.17'!$B:KD,LH$1,0),0) -> 160 | LH10: =IFERROR(VLOOKUP($D10,'Adient Arendal (Malzia) WK.12'!$B:KE,LH$1,0),0) -> 0 | LI10: =IFERROR(VLOOKUP($D10,'Adient Taizhou (China) WK.16'!$B:KH,LH$1,0),0) -> 0 | LJ10: 0 | LK10: 0 | LL10: 0 | LM10: =((LF10-(LG10+LH10+LI10)+LL10))+LJ10 -> 680 | LO10: =LM10 -> 680 | LP10: =IFERROR(VLOOKUP($D10,'Adient Assende (Belgium) WK.17'!$B:KL,LQ$1,0),0) -> 160 | LQ10: =IFERROR(VLOOKUP($D10,'Adient Arendal (Malzia) WK.12'!$B:KM,LQ$1,0),0) -> 0 | LR10: =IFERROR(VLOOKUP($D10,'Adient Taizhou (China) WK.16'!$B:KP,LQ$1,0),0) -> 0 | LS10: 0 | LT10: 0 | LU10: =((LO10-(LP10+LQ10+LR10)+LT10)) -> 520 | LW10: =LU10 -> 520 | LX10: =IFERROR(VLOOKUP($D10,'Adient Assende (Belgium) WK.17'!$B:KT,LY$1,0),0) -> 320 | LY10: =IFERROR(VLOOKUP($D10,'Adient Arendal (Malzia) WK.12'!$B:KU,LY$1,0),0) -> 0 | LZ10: =IFERROR(VLOOKUP($D10,'Adient Taizhou (China) WK.16'!$B:KX,LY$1,0),0) -> 0 | MA10: 0 | MB10: 0 | MC10: =((LW10-(LX10+LY10+LZ10)+MB10)) -> 200 | ME10: =MC10 -> 200 | MF10: =IFERROR(VLOOKUP($D10,'Adient Assende (Belgium) WK.17'!$B:LB,MG$1,0),0) -> 0 | MG10: =IFERROR(VLOOKUP($D10,'Adient Arendal (Malzia) WK.12'!$B:LC,MG$1,0),0) -> 0 | MH10: =IFERROR(VLOOKUP($D10,'Adient Taizhou (China) WK.16'!$B:LF,MG$1,0),0) -> 0 | MI10: 0 | MJ10: 0 | MK10: =((ME10-(MF10+MG10+MH10)+MJ10)) -> 200 | MM10: =MK10 -> 200 | MN10: =IFERROR(VLOOKUP($D10,'Adient Assende (Belgium) WK.17'!$B:LJ,MO$1,0),0) -> 160 | MO10: =IFERROR(VLOOKUP($D10,'Adient Arendal (Malzia) WK.12'!$B:LK,MO$1,0),0) -> 0 | MP10: =IFERROR(VLOOKUP($D10,'Adient Taizhou (China) WK.16'!$B:LN,MO$1,0),0) -> 0 | MQ10: 0 | MR10: 0 | MS10: =((MM10-(MN10+MO10+MP10)+MR10)) -> 40 | MU10: =MS10 -> 40 | MV10: =IFERROR(VLOOKUP($D10,'Adient Assende (Belgium) WK.17'!$B:LR,MW$1,0),0) -> 160 | MW10: =IFERROR(VLOOKUP($D10,'Adient Arendal (Malzia) WK.12'!$B:LS,MW$1,0),0) -> 0 | MX10: =IFERROR(VLOOKUP($D10,'Adient Taizhou (China) WK.16'!$B:LV,MW$1,0),0) -> 0 | MY10: 0 | MZ10: 0 | NA10: =((MU10-(MV10+MW10+MX10)+MZ10)) -> -120 | NC10: =NA10 -> -120 | ND10: =IFERROR(VLOOKUP($D10,'Adient Assende (Belgium) WK.17'!$B:LZ,NE$1,0),0) -> 160 | NE10: =IFERROR(VLOOKUP($D10,'Adient Arendal (Malzia) WK.12'!$B:MA,NE$1,0),0) -> 0 | NF10: =IFERROR(VLOOKUP($D10,'Adient Taizhou (China) WK.16'!$B:MD,NE$1,0),0) -> 0 | NG10: 0 | NH10: 0 | NI10: =((NC10-(ND10+NE10+NF10)+NH10)) -> -280 | NK10: =NI10 -> -280 | NL10: =IFERROR(VLOOKUP($D10,'Adient Assende (Belgium) WK.17'!$B:MH,NM$1,0),0) -> 160 | NM10: =IFERROR(VLOOKUP($D10,'Adient Arendal (Malzia) WK.12'!$B:MI,NM$1,0),0) -> 0 | NN10: =IFERROR(VLOOKUP($D10,'Adient Taizhou (China) WK.16'!$B:ML,NM$1,0),0) -> 0 | NO10: 0 | NP10: 0 | NQ10: =((NK10-(NL10+NM10+NN10)+NP10)) -> -440 | NS10: =NQ10 -> -440 | NT10: =IFERROR(VLOOKUP($D10,'Adient Assende (Belgium) WK.17'!$B:MP,NU$1,0),0) -> 160 | NU10: =IFERROR(VLOOKUP($D10,'Adient Arendal (Malzia) WK.12'!$B:MQ,NU$1,0),0) -> 0 | NV10: =IFERROR(VLOOKUP($D10,'Adient Taizhou (China) WK.16'!$B:MT,NU$1,0),0) -> 0 | NW10: 0 | NX10: 0 | NY10: =((NS10-(NT10+NU10+NV10)+NX10)) -> -600 | OA10: =NY10 -> -600 | OB10: =IFERROR(VLOOKUP($D10,'Adient Assende (Belgium) WK.17'!$B:MX,OC$1,0),0) -> 0 | OC10: =IFERROR(VLOOKUP($D10,'Adient Arendal (Malzia) WK.12'!$B:MY,OC$1,0),0) -> 0 | OD10: =IFERROR(VLOOKUP($D10,'Adient Taizhou (China) WK.16'!$B:NB,OC$1,0),0) -> 0 | OE10: 0 | OF10: 0 | OG10: =((OA10-(OB10+OC10+OD10)+OF10)) -> -600 | OI10: =OG10 -> -600 | OJ10: =IFERROR(VLOOKUP($D10,'Adient Assende (Belgium) WK.17'!$B:NF,OK$1,0),0) -> 160 | OK10: =IFERROR(VLOOKUP($D10,'Adient Arendal (Malzia) WK.12'!$B:NG,OK$1,0),0) -> 0 | OL10: =IFERROR(VLOOKUP($D10,'Adient Taizhou (China) WK.16'!$B:NJ,OK$1,0),0) -> 0 | OM10: 0 | ON10: 0 | OO10: =((OI10-(OJ10+OK10+OL10)+ON10)) -> -760 | OQ10: =OO10 -> -760 | OR10: =IFERROR(VLOOKUP($D10,'Adient Assende (Belgium) WK.17'!$B:NN,OS$1,0),0) -> 0 | OS10: =IFERROR(VLOOKUP($D10,'Adient Arendal (Malzia) WK.12'!$B:NO,OS$1,0),0) -> 0 | OT10: =IFERROR(VLOOKUP($D10,'Adient Taizhou (China) WK.16'!$B:NR,OS$1,0),0) -> 0 | OU10: 0 | OV10: 0 | OW10: =((OQ10-(OR10+OS10+OT10)+OV10)) -> -760 | OY10: =OW10 -> -760 | OZ10: =IFERROR(VLOOKUP($D10,'Adient Assende (Belgium) WK.17'!$B:NV,PA$1,0),0) -> 0 | PA10: =IFERROR(VLOOKUP($D10,'Adient Arendal (Malzia) WK.12'!$B:NW,PA$1,0),0) -> 0 | PB10: =IFERROR(VLOOKUP($D10,'Adient Taizhou (China) WK.16'!$B:NZ,PA$1,0),0) -> 0 | PC10: 0 | PD10: 0 | PE10: =((OY10-(OZ10+PA10+PB10)+PD10)) -> -760 | PG10: =PE10 -> -760 | PH10: =IFERROR(VLOOKUP($D10,'Adient Assende (Belgium) WK.17'!$B:OD,PI$1,0),0) -> 0 | PI10: =IFERROR(VLOOKUP($D10,'Adient Arendal (Malzia) WK.12'!$B:OE,PI$1,0),0) -> 0 | PJ10: =IFERROR(VLOOKUP($D10,'Adient Taizhou (China) WK.16'!$B:OH,PI$1,0),0) -> 0 | PK10: 0 | PL10: 0 | PM10: =((PG10-(PH10+PI10+PJ10)+PL10)) -> -760 | PO10: =PM10 -> -760 | PP10: =IFERROR(VLOOKUP($D10,'Adient Assende (Belgium) WK.17'!$B:OL,PQ$1,0),0) -> 0 | PQ10: =IFERROR(VLOOKUP($D10,'Adient Arendal (Malzia) WK.12'!$B:OM,PQ$1,0),0) -> 0 | PR10: =IFERROR(VLOOKUP($D10,'Adient Taizhou (China) WK.16'!$B:OP,PQ$1,0),0) -> 0 | PS10: 0 | PT10: 0 | PU10: =((PO10-(PP10+PQ10+PR10)+PT10)) -> -760 | PW10: =PU10 -> -760 | PX10: =IFERROR(VLOOKUP($D10,'Adient Assende (Belgium) WK.17'!$B:OT,PY$1,0),0) -> 160 | PY10: =IFERROR(VLOOKUP($D10,'Adient Arendal (Malzia) WK.12'!$B:OU,PY$1,0),0) -> 0 | PZ10: =IFERROR(VLOOKUP($D10,'Adient Taizhou (China) WK.16'!$B:OX,PY$1,0),0) -> 0 | QA10: 0 | QB10: 0 | QC10: =((PW10-(PX10+PY10+PZ10)+QB10)) -> -920 | QE10: =QC10 -> -920 | QF10: =IFERROR(VLOOKUP($D10,'Adient Assende (Belgium) WK.17'!$B:PB,QG$1,0),0) -> 0 | QG10: =IFERROR(VLOOKUP($D10,'Adient Arendal (Malzia) WK.12'!$B:PC,QG$1,0),0) -> 0 | QH10: =IFERROR(VLOOKUP($D10,'Adient Taizhou (China) WK.16'!$B:PF,QG$1,0),0) -> 0 | QI10: 0 | QJ10: 0 | QK10: =((QE10-(QF10+QG10+QH10)+QJ10)) -> -920 | QM10: =QK10 -> -920 | QN10: =IFERROR(VLOOKUP($D10,'Adient Assende (Belgium) WK.17'!$B:PJ,QO$1,0),0) -> 160 | QO10: =IFERROR(VLOOKUP($D10,'Adient Arendal (Malzia) WK.12'!$B:PK,QO$1,0),0) -> 0 | QP10: =IFERROR(VLOOKUP($D10,'Adient Taizhou (China) WK.16'!$B:PN,QO$1,0),0) -> 0 | QQ10: 0 | QR10: 0 | QS10: =((QM10-(QN10+QO10+QP10)+QR10)) -> -1080 | QU10: =QS10 -> -1080 | QV10: =IFERROR(VLOOKUP($D10,'Adient Assende (Belgium) WK.17'!$B:PR,QW$1,0),0) -> 80 | QW10: =IFERROR(VLOOKUP($D10,'Adient Arendal (Malzia) WK.12'!$B:PS,QW$1,0),0) -> 0 | QX10: =IFERROR(VLOOKUP($D10,'Adient Taizhou (China) WK.16'!$B:PV,QW$1,0),0) -> 0 | QY10: 0 | QZ10: 0 | RA10: =((QU10-(QV10+QW10+QX10)+QZ10)) -> -1160 | RC10: =RA10 -> -1160 | RD10: =IFERROR(VLOOKUP($D10,'Adient Assende (Belgium) WK.17'!$B:PZ,RE$1,0),0) -> 80 | RE10: =IFERROR(VLOOKUP($D10,'Adient Arendal (Malzia) WK.12'!$B:QA,RE$1,0),0) -> 0 | RF10: =IFERROR(VLOOKUP($D10,'Adient Taizhou (China) WK.16'!$B:QD,RE$1,0),0) -> 0 | RG10: 0 | RH10: 0 | RI10: =((RC10-(RD10+RE10+RF10)+RH10)) -> -1240 | RK10: =RI10 -> -1240 | RL10: =IFERROR(VLOOKUP($D10,'Adient Assende (Belgium) WK.17'!$B:QH,RM$1,0),0) -> 80 | RM10: =IFERROR(VLOOKUP($D10,'Adient Arendal (Malzia) WK.12'!$B:QI,RM$1,0),0) -> 0 | RN10: =IFERROR(VLOOKUP($D10,'Adient Taizhou (China) WK.16'!$B:QL,RM$1,0),0) -> 0 | RO10: 0 | RP10: 0 | RQ10: =((RK10-(RL10+RM10+RN10)+RP10)) -> -1320 | RS10: =RQ10 -> -1320 | RT10: =IFERROR(VLOOKUP($D10,'Adient Assende (Belgium) WK.17'!$B:QP,RU$1,0),0) -> 80 | RU10: =IFERROR(VLOOKUP($D10,'Adient Arendal (Malzia) WK.12'!$B:QQ,RU$1,0),0) -> 0 | RV10: =IFERROR(VLOOKUP($D10,'Adient Taizhou (China) WK.16'!$B:QT,RU$1,0),0) -> 0 | RW10: 0 | RX10: 0 | RY10: =((RS10-(RT10+RU10+RV10)+RX10)) -> -1400 | SA10: =RY10 -> -1400 | SB10: =IFERROR(VLOOKUP($D10,'Adient Assende (Belgium) WK.17'!$B:QX,SC$1,0),0) -> 80 | SC10: =IFERROR(VLOOKUP($D10,'Adient Arendal (Malzia) WK.12'!$B:QY,SC$1,0),0) -> 0 | SD10: =IFERROR(VLOOKUP($D10,'Adient Taizhou (China) WK.16'!$B:RB,SC$1,0),0) -> 0 | SE10: 0 | SF10: 0 | SG10: =((SA10-(SB10+SC10+SD10)+SF10)) -> -1480 | SI10: =SG10 -> -1480 | SJ10: =IFERROR(VLOOKUP($D10,'Adient Assende (Belgium) WK.17'!$B:RF,SK$1,0),0) -> 80 | SK10: =IFERROR(VLOOKUP($D10,'Adient Arendal (Malzia) WK.12'!$B:RG,SK$1,0),0) -> 0 | SL10: =IFERROR(VLOOKUP($D10,'Adient Taizhou (China) WK.16'!$B:RJ,SK$1,0),0) -> 0 | SM10: 0 | SN10: 0 | SO10: =((SI10-(SJ10+SK10+SL10)+SN10)) -> -1560 | SQ10: =SO10 -> -1560 | SR10: =IFERROR(VLOOKUP($D10,'Adient Assende (Belgium) WK.17'!$B:RN,SS$1,0),0) -> 80 | SS10: =IFERROR(VLOOKUP($D10,'Adient Arendal (Malzia) WK.12'!$B:RO,SS$1,0),0) -> 0 | ST10: =IFERROR(VLOOKUP($D10,'Adient Taizhou (China) WK.16'!$B:RR,SS$1,0),0) -> 0 | SU10: 0 | SV10: 0 | SW10: =((SQ10-(SR10+SS10+ST10)+SV10)) -> -1640 | SY10: =SW10 -> -1640 | SZ10: =IFERROR(VLOOKUP($D10,'Adient Assende (Belgium) WK.17'!$B:RV,TA$1,0),0) -> 80 | TA10: =IFERROR(VLOOKUP($D10,'Adient Arendal (Malzia) WK.12'!$B:RW,TA$1,0),0) -> 0 | TB10: =IFERROR(VLOOKUP($D10,'Adient Taizhou (China) WK.16'!$B:RZ,TA$1,0),0) -> 0 | TC10: 0 | TD10: 0 | TE10: =((SY10-(SZ10+TA10+TB10)+TD10)) -> -1720 | TG10: =TE10 -> -1720 | TH10: =IFERROR(VLOOKUP($D10,'Adient Assende (Belgium) WK.17'!$B:SD,TI$1,0),0) -> 130 | TI10: =IFERROR(VLOOKUP($D10,'Adient Arendal (Malzia) WK.12'!$B:SE,TI$1,0),0) -> 0 | TJ10: =IFERROR(VLOOKUP($D10,'Adient Taizhou (China) WK.16'!$B:SH,TI$1,0),0) -> 0 | TK10: 0 | TL10: 0 | TM10: =((TG10-(TH10+TI10+TJ10)+TL10)) -> -1850 | TO10: =TM10 -> -1850 | TP10: =IFERROR(VLOOKUP($D10,'Adient Assende (Belgium) WK.17'!$B:SL,TQ$1,0),0) -> 130 | TQ10: =IFERROR(VLOOKUP($D10,'Adient Arendal (Malzia) WK.12'!$B:SM,TQ$1,0),0) -> 0 | TR10: =IFERROR(VLOOKUP($D10,'Adient Taizhou (China) WK.16'!$B:SP,TQ$1,0),0) -> 0 | TS10: 0 | TT10: 0 | TU10: =((TO10-(TP10+TQ10+TR10)+TT10)) -> -1980 | TW10: =TU10 -> -1980 | TX10: =IFERROR(VLOOKUP($D10,'Adient Assende (Belgium) WK.17'!$B:ST,TY$1,0),0) -> 130 | TY10: =IFERROR(VLOOKUP($D10,'Adient Arendal (Malzia) WK.12'!$B:SU,TY$1,0),0) -> 0 | TZ10: =IFERROR(VLOOKUP($D10,'Adient Taizhou (China) WK.16'!$B:SX,TY$1,0),0) -> 0 | UA10: 0 | UB10: 0 | UC10: =((TW10-(TX10+TY10+TZ10)+UB10)) -> -2110 | UE10: =UC10 -> -2110 | UF10: =IFERROR(VLOOKUP($D10,'Adient Assende (Belgium) WK.17'!$B:TB,UG$1,0),0) -> 130 | UG10: =IFERROR(VLOOKUP($D10,'Adient Arendal (Malzia) WK.12'!$B:TC,UG$1,0),0) -> 0 | UH10: =IFERROR(VLOOKUP($D10,'Adient Taizhou (China) WK.16'!$B:TF,UG$1,0),0) -> 0 | UI10: 0 | UJ10: 0 | UK10: =((UE10-(UF10+UG10+UH10)+UJ10)) -> -2240 | UM10: =UK10 -> -2240 | UN10: =IFERROR(VLOOKUP($D10,'Adient Assende (Belgium) WK.17'!$B:TJ,UO$1,0),0) -> 120 | UO10: =IFERROR(VLOOKUP($D10,'Adient Arendal (Malzia) WK.12'!$B:TK,UO$1,0),0) -> 0 | UP10: =IFERROR(VLOOKUP($D10,'Adient Taizhou (China) WK.16'!$B:TN,UO$1,0),0) -> 0 | UQ10: 0 | UR10: 0 | US10: =((UM10-(UN10+UO10+UP10)+UR10)) -> -2360 | UU10: =US10 -> -2360 | UV10: =IFERROR(VLOOKUP($D10,'Adient Assende (Belgium) WK.17'!$B:TR,UW$1,0),0) -> 160 | UW10: =IFERROR(VLOOKUP($D10,'Adient Arendal (Malzia) WK.12'!$B:TS,UW$1,0),0) -> 0 | UX10: =IFERROR(VLOOKUP($D10,'Adient Taizhou (China) WK.16'!$B:TV,UW$1,0),0) -> 0 | UY10: 0 | UZ10: 0 | VA10: =((UU10-(UV10+UW10+UX10)+UZ10)) -> -2520 | VC10: =VA10 -> -2520 | VD10: =IFERROR(VLOOKUP($D10,'Adient Assende (Belgium) WK.17'!$B:TZ,VE$1,0),0) -> 160 | VE10: =IFERROR(VLOOKUP($D10,'Adient Arendal (Malzia) WK.12'!$B:UA,VE$1,0),0) -> 0 | VF10: =IFERROR(VLOOKUP($D10,'Adient Taizhou (China) WK.16'!$B:UD,VE$1,0),0) -> 0 | VG10: 0 | VH10: 0 | VI10: =((VC10-(VD10+VE10+VF10)+VH10)) -> -2680 | VK10: =VI10 -> -2680 | VL10: =IFERROR(VLOOKUP($D10,'Adient Assende (Belgium) WK.17'!$B:UH,VM$1,0),0) -> 0 | VM10: =IFERROR(VLOOKUP($D10,'Adient Arendal (Malzia) WK.12'!$B:UI,VM$1,0),0) -> 0 | VN10: =IFERROR(VLOOKUP($D10,'Adient Taizhou (China) WK.16'!$B:UL,VM$1,0),0) -> 0 | VO10: 0 | VP10: 0 | VQ10: =((VK10-(VL10+VM10+VN10)+VP10)) -> -2680
