Workbook

Sheet ✏️ Data Input
A1: ✏️ WEEKLY SALES DATA INPUT – VOLVO / SEWS PORT SAID MFG
A2: ⚡ Update any quantity cell below — all other sheets recalculate automatically
A3: Facility | B3: SEWS Part No. | C3: WK 20 | D3: WK 21 | E3: WK 22 | F3: WK 23 | G3: WK 24 | H3: WK 25 | I3: WK 26 | J3: WK 27 | K3: WK 28 | L3: WK 29 | M3: WK 30 | N3: WK 31 | O3: WK 32 | P3: WK 33 | Q3: WK 34 | R3: WK 35 | S3: WK 36 | T3: WK 37 | U3: WK 38 | V3: WK 39 | W3: WK 40 | X3: WK 41 | Y3: WK 42 | Z3: WK 43 | AA3: WK 44 | AB3: WK 45 | AC3: WK 46 | AD3: WK 47 | AE3: WK 48 | AF3: WK 49 | AG3: WK 50 | AH3: WK 51 | AI3: WK 52
A4: Week Start Date | C4: 46153 | D4: 46160 | E4: 46167 | F4: 46174 | G4: 46181 | H4: 46188 | I4: 46195 | J4: 46202 | K4: 46209 | L4: 46216 | M4: 46223 | N4: 46230 | O4: 46237 | P4: 46244 | Q4: 46251 | R4: 46258 | S4: 46265 | T4: 46272 | U4: 46279 | V4: 46286 | W4: 46293 | X4: 46300 | Y4: 46307 | Z4: 46314 | AA4: 46321 | AB4: 46328 | AC4: 46335 | AD4: 46342 | AE4: 46349 | AF4: 46356 | AG4: 46363 | AH4: 46370 | AI4: 46371
A5: JCI2 LH | B5: 4172750 | C5: 0 | D5: 480 | E5: 0 | F5: 0 | G5: 160 | H5: 320 | I5: 0 | J5: 160 | K5: 160 | L5: 160 | M5: 0 | N5: 0 | O5: 0 | P5: 0 | Q5: 160 | R5: 0 | S5: 160 | T5: 80 | U5: 80 | V5: 80 | W5: 80 | X5: 80 | Y5: 80 | Z5: 80 | AA5: 80 | AB5: 160 | AC5: 160 | AD5: 160 | AE5: 160 | AF5: 160 | AG5: 160 | AH5: 160 | AI5: 0
A6: JCI2 LH | B6: 4172755 | C6: 0 | D6: 160 | E6: 160 | F6: 160 | G6: 0 | H6: 160 | I6: 160 | J6: 0 | K6: 160 | L6: 160 | M6: 0 | N6: 0 | O6: 0 | P6: 0 | Q6: 0 | R6: 0 | S6: 160 | T6: 80 | U6: 80 | V6: 80 | W6: 80 | X6: 40 | Y6: 40 | Z6: 40 | AA6: 40 | AB6: 70 | AC6: 70 | AD6: 70 | AE6: 70 | AF6: 40 | AG6: 80 | AH6: 80 | AI6: 0
A7: JCI2 LH | B7: 5080299 | C7: 0 | D7: 0 | E7: 0 | F7: 0 | G7: 0 | H7: 0 | I7: 0 | J7: 0 | K7: 0 | L7: 0 | M7: 0 | N7: 0 | O7: 0 | P7: 0 | Q7: 0 | R7: 0 | S7: 0 | T7: 40 | U7: 40 | V7: 40 | W7: 40 | X7: 0 | Y7: 0 | Z7: 0 | AA7: 0 | AB7: 0 | AC7: 0 | AD7: 0 | AE7: 0 | AF7: 0 | AG7: 0 | AH7: 0 | AI7: 0
A8: JCI2 LH | B8: 5073059 | C8: 0 | D8: 160 | E8: 0 | F8: 0 | G8: 0 | H8: 160 | I8: 0 | J8: 160 | K8: 0 | L8: 0 | M8: 0 | N8: 0 | O8: 0 | P8: 0 | Q8: 160 | R8: 0 | S8: 0 | T8: 40 | U8: 40 | V8: 40 | W8: 40 | X8: 40 | Y8: 40 | Z8: 40 | AA8: 40 | AB8: 0 | AC8: 0 | AD8: 0 | AE8: 0 | AF8: 0 | AG8: 80 | AH8: 80 | AI8: 0
A9: JCI2 LH | B9: 5073061 | C9: 0 | D9: 0 | E9: 0 | F9: 0 | G9: 0 | H9: 0 | I9: 0 | J9: 0 | K9: 0 | L9: 0 | M9: 0 | N9: 0 | O9: 0 | P9: 0 | Q9: 0 | R9: 0 | S9: 0 | T9: 40 | U9: 40 | V9: 40 | W9: 40 | X9: 0 | Y9: 0 | Z9: 0 | AA9: 0 | AB9: 0 | AC9: 0 | AD9: 0 | AE9: 0 | AF9: 0 | AG9: 0 | AH9: 0 | AI9: 0
A10: JCI2 LH | B10: 4172749 | C10: 0 | D10: 200 | E10: 100 | F10: 200 | G10: 200 | H10: 100 | I10: 100 | J10: 100 | K10: 200 | L10: 100 | M10: 0 | N10: 0 | O10: 0 | P10: 0 | Q10: 200 | R10: 100 | S10: 100 | T10: 130 | U10: 130 | V10: 130 | W10: 110 | X10: 150 | Y10: 150 | Z10: 150 | AA10: 150 | AB10: 120 | AC10: 120 | AD10: 120 | AE10: 120 | AF10: 120 | AG10: 100 | AH10: 100 | AI10: 0
A11: JCI2 LH | B11: 4172753 | C11: 0 | D11: 0 | E11: 0 | F11: 0 | G11: 0 | H11: 100 | I11: 0 | J11: 0 | K11: 0 | L11: 0 | M11: 0 | N11: 0 | O11: 0 | P11: 0 | Q11: 100 | R11: 0 | S11: 0 | T11: 0 | U11: 0 | V11: 0 | W11: 0 | X11: 30 | Y11: 30 | Z11: 30 | AA11: 10 | AB11: 0 | AC11: 0 | AD11: 0 | AE11: 0 | AF11: 0 | AG11: 0 | AH11: 0 | AI11: 0
A12: JCI2 LH | B12: 5080294 | C12: 0 | D12: 100 | E12: 0 | F12: 0 | G12: 0 | H12: 100 | I12: 0 | J12: 0 | K12: 0 | L12: 100 | M12: 0 | N12: 0 | O12: 0 | P12: 0 | Q12: 0 | R12: 0 | S12: 0 | T12: 30 | U12: 30 | V12: 30 | W12: 10 | X12: 0 | Y12: 0 | Z12: 0 | AA12: 0 | AB12: 20 | AC12: 20 | AD12: 20 | AE12: 20 | AF12: 20 | AG12: 0 | AH12: 0 | AI12: 0
A13: JCI2 LH | B13: 5073058 | C13: 0 | D13: 300 | E13: 200 | F13: 100 | G13: 200 | H13: 200 | I13: 100 | J13: 100 | K13: 200 | L13: 300 | M13: 0 | N13: 0 | O13: 0 | P13: 0 | Q13: 100 | R13: 100 | S13: 200 | T13: 100 | U13: 100 | V13: 100 | W13: 100 | X13: 50 | Y13: 50 | Z13: 50 | AA13: 50 | AB13: 40 | AC13: 40 | AD13: 40 | AE13: 40 | AF13: 40 | AG13: 50 | AH13: 50 | AI13: 0
A14: JCI2 LH | B14: 4172770 | C14: 0 | D14: 0 | E14: 0 | F14: 0 | G14: 0 | H14: 0 | I14: 0 | J14: 0 | K14: 0 | L14: 0 | M14: 0 | N14: 0 | O14: 0 | P14: 0 | Q14: 0 | R14: 0 | S14: 0 | T14: 0 | U14: 0 | V14: 0 | W14: 0 | X14: 0 | Y14: 0 | Z14: 0 | AA14: 0 | AB14: 0 | AC14: 0 | AD14: 0 | AE14: 0 | AF14: 0 | AG14: 0 | AH14: 0 | AI14: 0
A15: JCI2 LH | B15: 4817100 | C15: 160 | D15: 1040 | E15: 1040 | F15: 800 | G15: 720 | H15: 720 | I15: 640 | J15: 640 | K15: 880 | L15: 1200 | M15: 0 | N15: 0 | O15: 0 | P15: 0 | Q15: 640 | R15: 640 | S15: 560 | T15: 700 | U15: 700 | V15: 700 | W15: 700 | X15: 540 | Y15: 540 | Z15: 540 | AA15: 540 | AB15: 550 | AC15: 550 | AD15: 550 | AE15: 550 | AF15: 520 | AG15: 400 | AH15: 400 | AI15: 0
A16: JCI2 LH | B16: 4817103 | C16: 0 | D16: 800 | E16: 0 | F16: 400 | G16: 480 | H16: 400 | I16: 400 | J16: 480 | K16: 720 | L16: 1040 | M16: 0 | N16: 0 | O16: 0 | P16: 0 | Q16: 640 | R16: 560 | S16: 560 | T16: 560 | U16: 560 | V16: 560 | W16: 560 | X16: 320 | Y16: 320 | Z16: 320 | AA16: 320 | AB16: 530 | AC16: 530 | AD16: 530 | AE16: 530 | AF16: 520 | AG16: 520 | AH16: 520 | AI16: 0
... A71: CUSHION | B71: 4429358 | C71: 0 | D71: 4800 | E71: 4800 | F71: 3840 | G71: 3840 | H71: 4800 | I71: 3840 | J71: 4800 | K71: 5760 | L71: 7680 | M71: 0 | N71: 0 | O71: 0 | P71: 0 | Q71: 3840 | R71: 3840 | S71: 3840 | T71: 4080 | U71: 4080 | V71: 4080 | W71: 4080 | X71: 2640 | Y71: 2640 | Z71: 2640 | AA71: 2640 | AB71: 3840 | AC71: 3840 | AD71: 3840 | AE71: 3840 | AF71: 3840 | AG71: 4800 | AH71: 4800 | AI71: 0
A72: GRAND TOTAL | C72: =SUM(C5:C71) -> 1040 | D72: =SUM(D5:D71) -> 26300 | E72: =SUM(E5:E71) -> 16420 | F72: =SUM(F5:F71) -> 18300 | G72: =SUM(G5:G71) -> 18651 | H72: =SUM(H5:H71) -> 18920 | I72: =SUM(I5:I71) -> 17220 | J72: =SUM(J5:J71) -> 18920 | ... AI72: =SUM(AI5:AI71) -> 0

Sheet 📊 Dashboard
B1: 📊 VOLVO SALES DASHBOARD – SEWS PORT SAID MFG
B3: ⚡ All values update automatically from the Data Input sheet
B5: KEY PERFORMANCE INDICATORS
B6: TOTAL SALES QTY | C6: WEEKLY AVERAGE | D6: TOTAL WEEKS | E6: TOTAL PARTS | F6: ACTIVE PARTS | G6: FACILITIES
B7: ='✏️ Data Input'!C72+'✏️ Data Input'!D72+'✏️ Data Input'!E72+'✏️ Data Input'!F72+'✏️ Data Input'!G72+'✏️ Data Input'!H72+'✏️ Data Input'!I72+'✏️ Data Input'!J72+'✏️ Data Input'!K72+'✏️ Data Input'!L72+'✏️ Data Input'!M72+'✏️ Data Input'!N72+'✏️ Data Input'!O72+'✏️ Data Input'!P72+'✏️ Data Input'!Q72+'✏️ Data Input'!R72+'✏️ Data Input'!S72+'✏️ Data Input'!T72+'✏️ Data Input'!U72+'✏️ Data Input'!V72+'✏️ Data Input'!W72+'✏️ Data Input'!X72+'✏️ Data Input'!Y72+'✏️ Data Input'!Z72+'✏️ Data Input'!AA72+'✏️ Data Input'!AB72+'✏️ Data Input'!AC72+'✏️ Data Input'!AD72+'✏️ Data Input'!AE72+'✏️ Data Input'!AF72+'✏️ Data Input'!AG72+'✏️ Data Input'!AH72+'✏️ Data Input'!AI72 -> 481691 | C7: =('✏️ Data Input'!C72+'✏️ Data Input'!D72+'✏️ Data Input'!E72+'✏️ Data Input'!F72+'✏️ Data Input'!G72+'✏️ Data Input'!H72+'✏️ Data Input'!I72+'✏️ Data Input'!J72+'✏️ Data Input'!K72+'✏️ Data Input'!L72+'✏️ Data Input'!M72+'✏️ Data Input'!N72+'✏️ Data Input'!O72+'✏️ Data Input'!P72+'✏️ Data Input'!Q72+'✏️ Data Input'!R72+'✏️ Data Input'!S72+'✏️ Data Input'!T72+'✏️ Data Input'!U72+'✏️ Data Input'!V72+'✏️ Data Input'!W72+'✏️ Data Input'!X72+'✏️ Data Input'!Y72+'✏️ Data Input'!Z72+'✏️ Data Input'!AA72+'✏️ Data Input'!AB72+'✏️ Data Input'!AC72+'✏️ Data Input'!AD72+'✏️ Data Input'!AE72+'✏️ Data Input'!AF72+'✏️ Data Input'!AG72+'✏️ Data Input'!AH72+'✏️ Data Input'!AI72)/33 -> 14596.697 | D7: 33 | E7: 67 | F7: =COUNTIF('✏️ Data Input'!C5:AI71,">"&0) -> 982 | G7: 4
B10: FACILITY BREAKDOWN
B11: Facility | C11: Total Qty | D11: Avg / Week | E11: Max Week | F11: Active Weeks | G11: % of Total
B12: JCI2 LH | C12: =SUMIF('✏️ Data Input'!A5:A71,"JCI2 LH",'✏️ Data Input'!C5:C71)+SUMIF('✏️ Data Input'!A5:A71,"JCI2 LH",'✏️ Data Input'!D5:D71)+SUMIF('✏️ Data Input'!A5:A71,"JCI2 LH",'✏️ Data Input'!E5:E71)+SUMIF('✏️ Data Input'!A5:A71,"JCI2 LH",'✏️ Data Input'!F5:F71)+SUMIF('✏️ Data Input'!A5:A71,"JCI2 LH",'✏️ Data Input'!G5:G71)+SUMIF('✏️ Data Input'!A5:A71,"JCI2 LH",'✏️ Data Input'!H5:H71)+SUMIF('✏️ Data Input'!A5:A71,"JCI2 LH",'✏️ Data Input'!I5:I71)+SUMIF('✏️ Data Input'!A5:A71,"JCI2 LH",'✏️ Data Input'!J5:J71)+SUMIF('✏️ Data Input'!A5:A71,"JCI2 LH",'✏️ Data Input'!K5:K71)+SUMIF('✏️ Data Input'!A5:A71,"JCI2 LH",'✏️ Data Input'!L5:L71)+SUMIF('✏️ Data Input'!A5:A71,"JCI2 LH",'✏️ Data Input'!M5:M71)+SUMIF('✏️ Data Input'!A5:A71,"JCI2 LH",'✏️ Data Input'!N5:N71)+SUMIF('✏️ Data Input'!A5:A71,"JCI2 LH",'✏️ Data Input'!O5:O71)+SUMIF('✏️ Data Input'!A5:A71,"JCI2 LH",'✏️ Data Input'!P5:P71)+SUMIF('✏️ Data Input'!A5:A71,"JCI2 LH",'✏️ Data Input'!Q5:Q71)+SUMIF('✏️ Data Input'!A5:A71,"JCI2 LH",'✏️ Data Input'!R5:R71)+SUMIF('✏️ Data Input'!A5:A71,"JCI2 LH",'✏️ Data Input'!S5:S71)+SUMIF('✏️ Data Input'!A5:A71,"JCI2 LH",'✏️ Data Input'!T5:T71)+SUMIF('✏️ Data Input'!A5:A71,"JCI2 LH",'✏️ Data Input'!U5:U71)+SUMIF('✏️ Data Input'!A5:A71,"JCI2 LH",'✏️ Data Input'!V5:V71)+SUMIF('✏️ Data Input'!A5:A71,"JCI2 LH",'✏️ Data Input'!W5:W71)+SUMIF('✏️ Data Input'!A5:A71,"JCI2 LH",'✏️ Data Input'!X5:X71)+SUMIF('✏️ Data Input'!A5:A71,"JCI2 LH",'✏️ Data Input'!Y5:Y71)+SUMIF('✏️ Data Input'!A5:A71,"JCI2 LH",'✏️ Data Input'!Z5:Z71)+SUMIF('✏️ Data Input'!A5:A71,"JCI2 LH",'✏️ Data Input'!AA5:AA71)+SUMIF('✏️ Data Input'!A5:A71,"JCI2 LH",'✏️ Data Input'!AB5:AB71)+SUMIF('✏️ Data Input'!A5:A71,"JCI2 LH",'✏️ Data Input'!AC5:AC71)+SUMIF('✏️ Data Input'!A5:A71,"JCI2 LH",'✏️ Data Input'!AD5:AD71)+SUMIF('✏️ Data Input'!A5:A71,"JCI2 LH",'✏️ Data Input'!AE5:AE71)+SUMIF('✏️ Data Input'!A5:A71,"JCI2 LH",'✏️ Data Input'!AF5:AF71)+SUMIF('✏️ Data Input'!A5:A71,"JCI2 LH",'✏️ Data Input'!AG5:AG71)+SUMIF('✏️ Data Input'!A5:A71,"JCI2 LH",'✏️ Data Input'!AH5:AH71)+SUMIF('✏️ Data Input'!A5:A71,"JCI2 LH",'✏️ Data Input'!AI5:AI71) -> 102636 | D12: =(SUMIF('✏️ Data Input'!A5:A71,"JCI2 LH",'✏️ Data Input'!C5:C71)+SUMIF('✏️ Data Input'!A5:A71,"JCI2 LH",'✏️ Data Input'!D5:D71)+SUMIF('✏️ Data Input'!A5:A71,"JCI2 LH",'✏️ Data Input'!E5:E71)+SUMIF('✏️ Data Input'!A5:A71,"JCI2 LH",'✏️ Data Input'!F5:F71)+SUMIF('✏️ Data Input'!A5:A71,"JCI2 LH",'✏️ Data Input'!G5:G71)+SUMIF('✏️ Data Input'!A5:A71,"JCI2 LH",'✏️ Data Input'!H5:H71)+SUMIF('✏️ Data Input'!A5:A71,"JCI2 LH",'✏️ Data Input'!I5:I71)+SUMIF('✏️ Data Input'!A5:A71,"JCI2 LH",'✏️ Data Input'!J5:J71)+SUMIF('✏️ Data Input'!A5:A71,"JCI2 LH",'✏️ Data Input'!K5:K71)+SUMIF('✏️ Data Input'!A5:A71,"JCI2 LH",'✏️ Data Input'!L5:L71)+SUMIF('✏️ Data Input'!A5:A71,"JCI2 LH",'✏️ Data Input'!M5:M71)+SUMIF('✏️ Data Input'!A5:A71,"JCI2 LH",'✏️ Data Input'!N5:N71)+SUMIF('✏️ Data Input'!A5:A71,"JCI2 LH",'✏️ Data Input'!O5:O71)+SUMIF('✏️ Data Input'!A5:A71,"JCI2 LH",'✏️ Data Input'!P5:P71)+SUMIF('✏️ Data Input'!A5:A71,"JCI2 LH",'✏️ Data Input'!Q5:Q71)+SUMIF('✏️ Data Input'!A5:A71,"JCI2 LH",'✏️ Data Input'!R5:R71)+SUMIF('✏️ Data Input'!A5:A71,"JCI2 LH",'✏️ Data Input'!S5:S71)+SUMIF('✏️ Data Input'!A5:A71,"JCI2 LH",'✏️ Data Input'!T5:T71)+SUMIF('✏️ Data Input'!A5:A71,"JCI2 LH",'✏️ Data Input'!U5:U71)+SUMIF('✏️ Data Input'!A5:A71,"JCI2 LH",'✏️ Data Input'!V5:V71)+SUMIF('✏️ Data Input'!A5:A71,"JCI2 LH",'✏️ Data Input'!W5:W71)+SUMIF('✏️ Data Input'!A5:A71,"JCI2 LH",'✏️ Data Input'!X5:X71)+SUMIF('✏️ Data Input'!A5:A71,"JCI2 LH",'✏️ Data Input'!Y5:Y71)+SUMIF('✏️ Data Input'!A5:A71,"JCI2 LH",'✏️ Data Input'!Z5:Z71)+SUMIF('✏️ Data Input'!A5:A71,"JCI2 LH",'✏️ Data Input'!AA5:AA71)+SUMIF('✏️ Data Input'!A5:A71,"JCI2 LH",'✏️ Data Input'!AB5:AB71)+SUMIF('✏️ Data Input'!A5:A71,"JCI2 LH",'✏️ Data Input'!AC5:AC71)+SUMIF('✏️ Data Input'!A5:A71,"JCI2 LH",'✏️ Data Input'!AD5:AD71)+SUMIF('✏️ Data Input'!A5:A71,"JCI2 LH",'✏️ Data Input'!AE5:AE71)+SUMIF('✏️ Data Input'!A5:A71,"JCI2 LH",'✏️ Data Input'!AF5:AF71)+SUMIF('✏️ Data Input'!A5:A71,"JCI2 LH",'✏️ Data Input'!AG5:AG71)+SUMIF('✏️ Data Input'!A5:A71,"JCI2 LH",'✏️ Data Input'!AH5:AH71)+SUMIF('✏️ Data Input'!A5:A71,"JCI2 LH",'✏️ Data Input'!AI5:AI71))/33 -> 3110.1818 | E12: — | F12: — | G12: —
B13: JCI2 RH | C13: =SUMIF('✏️ Data Input'!A5:A71,"JCI2 RH",'✏️ Data Input'!C5:C71)+SUMIF('✏️ Data Input'!A5:A71,"JCI2 RH",'✏️ Data Input'!D5:D71)+SUMIF('✏️ Data Input'!A5:A71,"JCI2 RH",'✏️ Data Input'!E5:E71)+SUMIF('✏️ Data Input'!A5:A71,"JCI2 RH",'✏️ Data Input'!F5:F71)+SUMIF('✏️ Data Input'!A5:A71,"JCI2 RH",'✏️ Data Input'!G5:G71)+SUMIF('✏️ Data Input'!A5:A71,"JCI2 RH",'✏️ Data Input'!H5:H71)+SUMIF('✏️ Data Input'!A5:A71,"JCI2 RH",'✏️ Data Input'!I5:I71)+SUMIF('✏️ Data Input'!A5:A71,"JCI2 RH",'✏️ Data Input'!J5:J71)+SUMIF('✏️ Data Input'!A5:A71,"JCI2 RH",'✏️ Data Input'!K5:K71)+SUMIF('✏️ Data Input'!A5:A71,"JCI2 RH",'✏️ Data Input'!L5:L71)+SUMIF('✏️ Data Input'!A5:A71,"JCI2 RH",'✏️ Data Input'!M5:M71)+SUMIF('✏️ Data Input'!A5:A71,"JCI2 RH",'✏️ Data Input'!N5:N71)+SUMIF('✏️ Data Input'!A5:A71,"JCI2 RH",'✏️ Data Input'!O5:O71)+SUMIF('✏️ Data Input'!A5:A71,"JCI2 RH",'✏️ Data Input'!P5:P71)+SUMIF('✏️ Data Input'!A5:A71,"JCI2 RH",'✏️ Data Input'!Q5:Q71)+SUMIF('✏️ Data Input'!A5:A71,"JCI2 RH",'✏️ Data Input'!R5:R71)+SUMIF('✏️ Data Input'!A5:A71,"JCI2 RH",'✏️ Data Input'!S5:S71)+SUMIF('✏️ Data Input'!A5:A71,"JCI2 RH",'✏️ Data Input'!T5:T71)+SUMIF('✏️ Data Input'!A5:A71,"JCI2 RH",'✏️ Data Input'!U5:U71)+SUMIF('✏️ Data Input'!A5:A71,"JCI2 RH",'✏️ Data Input'!V5:V71)+SUMIF('✏️ Data Input'!A5:A71,"JCI2 RH",'✏️ Data Input'!W5:W71)+SUMIF('✏️ Data Input'!A5:A71,"JCI2 RH",'✏️ Data Input'!X5:X71)+SUMIF('✏️ Data Input'!A5:A71,"JCI2 RH",'✏️ Data Input'!Y5:Y71)+SUMIF('✏️ Data Input'!A5:A71,"JCI2 RH",'✏️ Data Input'!Z5:Z71)+SUMIF('✏️ Data Input'!A5:A71,"JCI2 RH",'✏️ Data Input'!AA5:AA71)+SUMIF('✏️ Data Input'!A5:A71,"JCI2 RH",'✏️ Data Input'!AB5:AB71)+SUMIF('✏️ Data Input'!A5:A71,"JCI2 RH",'✏️ Data Input'!AC5:AC71)+SUMIF('✏️ Data Input'!A5:A71,"JCI2 RH",'✏️ Data Input'!AD5:AD71)+SUMIF('✏️ Data Input'!A5:A71,"JCI2 RH",'✏️ Data Input'!AE5:AE71)+SUMIF('✏️ Data Input'!A5:A71,"JCI2 RH",'✏️ Data Input'!AF5:AF71)+SUMIF('✏️ Data Input'!A5:A71,"JCI2 RH",'✏️ Data Input'!AG5:AG71)+SUMIF('✏️ Data Input'!A5:A71,"JCI2 RH",'✏️ Data Input'!AH5:AH71)+SUMIF('✏️ Data Input'!A5:A71,"JCI2 RH",'✏️ Data Input'!AI5:AI71) -> 101975 | D13: =(SUMIF('✏️ Data Input'!A5:A71,"JCI2 RH",'✏️ Data Input'!C5:C71)+SUMIF('✏️ Data Input'!A5:A71,"JCI2 RH",'✏️ Data Input'!D5:D71)+SUMIF('✏️ Data Input'!A5:A71,"JCI2 RH",'✏️ Data Input'!E5:E71)+SUMIF('✏️ Data Input'!A5:A71,"JCI2 RH",'✏️ Data Input'!F5:F71)+SUMIF('✏️ Data Input'!A5:A71,"JCI2 RH",'✏️ Data Input'!G5:G71)+SUMIF('✏️ Data Input'!A5:A71,"JCI2 RH",'✏️ Data Input'!H5:H71)+SUMIF('✏️ Data Input'!A5:A71,"JCI2 RH",'✏️ Data Input'!I5:I71)+SUMIF('✏️ Data Input'!A5:A71,"JCI2 RH",'✏️ Data Input'!J5:J71)+SUMIF('✏️ Data Input'!A5:A71,"JCI2 RH",'✏️ Data Input'!K5:K71)+SUMIF('✏️ Data Input'!A5:A71,"JCI2 RH",'✏️ Data Input'!L5:L71)+SUMIF('✏️ Data Input'!A5:A71,"JCI2 RH",'✏️ Data Input'!M5:M71)+SUMIF('✏️ Data Input'!A5:A71,"JCI2 RH",'✏️ Data Input'!N5:N71)+SUMIF('✏️ Data Input'!A5:A71,"JCI2 RH",'✏️ Data Input'!O5:O71)+SUMIF('✏️ Data Input'!A5:A71,"JCI2 RH",'✏️ Data Input'!P5:P71)+SUMIF('✏️ Data Input'!A5:A71,"JCI2 RH",'✏️ Data Input'!Q5:Q71)+SUMIF('✏️ Data Input'!A5:A71,"JCI2 RH",'✏️ Data Input'!R5:R71)+SUMIF('✏️ Data Input'!A5:A71,"JCI2 RH",'✏️ Data Input'!S5:S71)+SUMIF('✏️ Data Input'!A5:A71,"JCI2 RH",'✏️ Data Input'!T5:T71)+SUMIF('✏️ Data Input'!A5:A71,"JCI2 RH",'✏️ Data Input'!U5:U71)+SUMIF('✏️ Data Input'!A5:A71,"JCI2 RH",'✏️ Data Input'!V5:V71)+SUMIF('✏️ Data Input'!A5:A71,"JCI2 RH",'✏️ Data Input'!W5:W71)+SUMIF('✏️ Data Input'!A5:A71,"JCI2 RH",'✏️ Data Input'!X5:X71)+SUMIF('✏️ Data Input'!A5:A71,"JCI2 RH",'✏️ Data Input'!Y5:Y71)+SUMIF('✏️ Data Input'!A5:A71,"JCI2 RH",'✏️ Data Input'!Z5:Z71)+SUMIF('✏️ Data Input'!A5:A71,"JCI2 RH",'✏️ Data Input'!AA5:AA71)+SUMIF('✏️ Data Input'!A5:A71,"JCI2 RH",'✏️ Data Input'!AB5:AB71)+SUMIF('✏️ Data Input'!A5:A71,"JCI2 RH",'✏️ Data Input'!AC5:AC71)+SUMIF('✏️ Data Input'!A5:A71,"JCI2 RH",'✏️ Data Input'!AD5:AD71)+SUMIF('✏️ Data Input'!A5:A71,"JCI2 RH",'✏️ Data Input'!AE5:AE71)+SUMIF('✏️ Data Input'!A5:A71,"JCI2 RH",'✏️ Data Input'!AF5:AF71)+SUMIF('✏️ Data Input'!A5:A71,"JCI2 RH",'✏️ Data Input'!AG5:AG71)+SUMIF('✏️ Data Input'!A5:A71,"JCI2 RH",'✏️ Data Input'!AH5:AH71)+SUMIF('✏️ Data Input'!A5:A71,"JCI2 RH",'✏️ Data Input'!AI5:AI71))/33 -> 3090.1515 | E13: — | F13: — | G13: —
B14: REAR SEAT | C14: =SUMIF('✏️ Data Input'!A5:A71,"REAR SEAT",'✏️ Data Input'!C5:C71)+SUMIF('✏️ Data Input'!A5:A71,"REAR SEAT",'✏️ Data Input'!D5:D71)+SUMIF('✏️ Data Input'!A5:A71,"REAR SEAT",'✏️ Data Input'!E5:E71)+SUMIF('✏️ Data Input'!A5:A71,"REAR SEAT",'✏️ Data Input'!F5:F71)+SUMIF('✏️ Data Input'!A5:A71,"REAR SEAT",'✏️ Data Input'!G5:G71)+SUMIF('✏️ Data Input'!A5:A71,"REAR SEAT",'✏️ Data Input'!H5:H71)+SUMIF('✏️ Data Input'!A5:A71,"REAR SEAT",'✏️ Data Input'!I5:I71)+SUMIF('✏️ Data Input'!A5:A71,"REAR SEAT",'✏️ Data Input'!J5:J71)+SUMIF('✏️ Data Input'!A5:A71,"REAR SEAT",'✏️ Data Input'!K5:K71)+SUMIF('✏️ Data Input'!A5:A71,"REAR SEAT",'✏️ Data Input'!L5:L71)+SUMIF('✏️ Data Input'!A5:A71,"REAR SEAT",'✏️ Data Input'!M5:M71)+SUMIF('✏️ Data Input'!A5:A71,"REAR SEAT",'✏️ Data Input'!N5:N71)+SUMIF('✏️ Data Input'!A5:A71,"REAR SEAT",'✏️ Data Input'!O5:O71)+SUMIF('✏️ Data Input'!A5:A71,"REAR SEAT",'✏️ Data Input'!P5:P71)+SUMIF('✏️ Data Input'!A5:A71,"REAR SEAT",'✏️ Data Input'!Q5:Q71)+SUMIF('✏️ Data Input'!A5:A71,"REAR SEAT",'✏️ Data Input'!R5:R71)+SUMIF('✏️ Data Input'!A5:A71,"REAR SEAT",'✏️ Data Input'!S5:S71)+SUMIF('✏️ Data Input'!A5:A71,"REAR SEAT",'✏️ Data Input'!T5:T71)+SUMIF('✏️ Data Input'!A5:A71,"REAR SEAT",'✏️ Data Input'!U5:U71)+SUMIF('✏️ Data Input'!A5:A71,"REAR SEAT",'✏️ Data Input'!V5:V71)+SUMIF('✏️ Data Input'!A5:A71,"REAR SEAT",'✏️ Data Input'!W5:W71)+SUMIF('✏️ Data Input'!A5:A71,"REAR SEAT",'✏️ Data Input'!X5:X71)+SUMIF('✏️ Data Input'!A5:A71,"REAR SEAT",'✏️ Data Input'!Y5:Y71)+SUMIF('✏️ Data Input'!A5:A71,"REAR SEAT",'✏️ Data Input'!Z5:Z71)+SUMIF('✏️ Data Input'!A5:A71,"REAR SEAT",'✏️ Data Input'!AA5:AA71)+SUMIF('✏️ Data Input'!A5:A71,"REAR SEAT",'✏️ Data Input'!AB5:AB71)+SUMIF('✏️ Data Input'!A5:A71,"REAR SEAT",'✏️ Data Input'!AC5:AC71)+SUMIF('✏️ Data Input'!A5:A71,"REAR SEAT",'✏️ Data Input'!AD5:AD71)+SUMIF('✏️ Data Input'!A5:A71,"REAR SEAT",'✏️ Data Input'!AE5:AE71)+SUMIF('✏️ Data Input'!A5:A71,"REAR SEAT",'✏️ Data Input'!AF5:AF71)+SUMIF('✏️ Data Input'!A5:A71,"REAR SEAT",'✏️ Data Input'!AG5:AG71)+SUMIF('✏️ Data Input'!A5:A71,"REAR SEAT",'✏️ Data Input'!AH5:AH71)+SUMIF('✏️ Data Input'!A5:A71,"REAR SEAT",'✏️ Data Input'!AI5:AI71) -> 165720 | D14: =(SUMIF('✏️ Data Input'!A5:A71,"REAR SEAT",'✏️ Data Input'!C5:C71)+SUMIF('✏️ Data Input'!A5:A71,"REAR SEAT",'✏️ Data Input'!D5:D71)+SUMIF('✏️ Data Input'!A5:A71,"REAR SEAT",'✏️ Data Input'!E5:E71)+SUMIF('✏️ Data Input'!A5:A71,"REAR SEAT",'✏️ Data Input'!F5:F71)+SUMIF('✏️ Data Input'!A5:A71,"REAR SEAT",'✏️ Data Input'!G5:G71)+SUMIF('✏️ Data Input'!A5:A71,"REAR SEAT",'✏️ Data Input'!H5:H71)+SUMIF('✏️ Data Input'!A5:A71,"REAR SEAT",'✏️ Data Input'!I5:I71)+SUMIF('✏️ Data Input'!A5:A71,"REAR SEAT",'✏️ Data Input'!J5:J71)+SUMIF('✏️ Data Input'!A5:A71,"REAR SEAT",'✏️ Data Input'!K5:K71)+SUMIF('✏️ Data Input'!A5:A71,"REAR SEAT",'✏️ Data Input'!L5:L71)+SUMIF('✏️ Data Input'!A5:A71,"REAR SEAT",'✏️ Data Input'!M5:M71)+SUMIF('✏️ Data Input'!A5:A71,"REAR SEAT",'✏️ Data Input'!N5:N71)+SUMIF('✏️ Data Input'!A5:A71,"REAR SEAT",'✏️ Data Input'!O5:O71)+SUMIF('✏️ Data Input'!A5:A71,"REAR SEAT",'✏️ Data Input'!P5:P71)+SUMIF('✏️ Data Input'!A5:A71,"REAR SEAT",'✏️ Data Input'!Q5:Q71)+SUMIF('✏️ Data Input'!A5:A71,"REAR SEAT",'✏️ Data Input'!R5:R71)+SUMIF('✏️ Data Input'!A5:A71,"REAR SEAT",'✏️ Data Input'!S5:S71)+SUMIF('✏️ Data Input'!A5:A71,"REAR SEAT",'✏️ Data Input'!T5:T71)+SUMIF('✏️ Data Input'!A5:A71,"REAR SEAT",'✏️ Data Input'!U5:U71)+SUMIF('✏️ Data Input'!A5:A71,"REAR SEAT",'✏️ Data Input'!V5:V71)+SUMIF('✏️ Data Input'!A5:A71,"REAR SEAT",'✏️ Data Input'!W5:W71)+SUMIF('✏️ Data Input'!A5:A71,"REAR SEAT",'✏️ Data Input'!X5:X71)+SUMIF('✏️ Data Input'!A5:A71,"REAR SEAT",'✏️ Data Input'!Y5:Y71)+SUMIF('✏️ Data Input'!A5:A71,"REAR SEAT",'✏️ Data Input'!Z5:Z71)+SUMIF('✏️ Data Input'!A5:A71,"REAR SEAT",'✏️ Data Input'!AA5:AA71)+SUMIF('✏️ Data Input'!A5:A71,"REAR SEAT",'✏️ Data Input'!AB5:AB71)+SUMIF('✏️ Data Input'!A5:A71,"REAR SEAT",'✏️ Data Input'!AC5:AC71)+SUMIF('✏️ Data Input'!A5:A71,"REAR SEAT",'✏️ Data Input'!AD5:AD71)+SUMIF('✏️ Data Input'!A5:A71,"REAR SEAT",'✏️ Data Input'!AE5:AE71)+SUMIF('✏️ Data Input'!A5:A71,"REAR SEAT",'✏️ Data Input'!AF5:AF71)+SUMIF('✏️ Data Input'!A5:A71,"REAR SEAT",'✏️ Data Input'!AG5:AG71)+SUMIF('✏️ Data Input'!A5:A71,"REAR SEAT",'✏️ Data Input'!AH5:AH71)+SUMIF('✏️ Data Input'!A5:A71,"REAR SEAT",'✏️ Data Input'!AI5:AI71))/33 -> 5021.8182 | E14: — | F14: — | G14: —
B15: CUSHION | C15: =SUMIF('✏️ Data Input'!A5:A71,"CUSHION",'✏️ Data Input'!C5:C71)+SUMIF('✏️ Data Input'!A5:A71,"CUSHION",'✏️ Data Input'!D5:D71)+SUMIF('✏️ Data Input'!A5:A71,"CUSHION",'✏️ Data Input'!E5:E71)+SUMIF('✏️ Data Input'!A5:A71,"CUSHION",'✏️ Data Input'!F5:F71)+SUMIF('✏️ Data Input'!A5:A71,"CUSHION",'✏️ Data Input'!G5:G71)+SUMIF('✏️ Data Input'!A5:A71,"CUSHION",'✏️ Data Input'!H5:H71)+SUMIF('✏️ Data Input'!A5:A71,"CUSHION",'✏️ Data Input'!I5:I71)+SUMIF('✏️ Data Input'!A5:A71,"CUSHION",'✏️ Data Input'!J5:J71)+SUMIF('✏️ Data Input'!A5:A71,"CUSHION",'✏️ Data Input'!K5:K71)+SUMIF('✏️ Data Input'!A5:A71,"CUSHION",'✏️ Data Input'!L5:L71)+SUMIF('✏️ Data Input'!A5:A71,"CUSHION",'✏️ Data Input'!M5:M71)+SUMIF('✏️ Data Input'!A5:A71,"CUSHION",'✏️ Data Input'!N5:N71)+SUMIF('✏️ Data Input'!A5:A71,"CUSHION",'✏️ Data Input'!O5:O71)+SUMIF('✏️ Data Input'!A5:A71,"CUSHION",'✏️ Data Input'!P5:P71)+SUMIF('✏️ Data Input'!A5:A71,"CUSHION",'✏️ Data Input'!Q5:Q71)+SUMIF('✏️ Data Input'!A5:A71,"CUSHION",'✏️ Data Input'!R5:R71)+SUMIF('✏️ Data Input'!A5:A71,"CUSHION",'✏️ Data Input'!S5:S71)+SUMIF('✏️ Data Input'!A5:A71,"CUSHION",'✏️ Data Input'!T5:T71)+SUMIF('✏️ Data Input'!A5:A71,"CUSHION",'✏️ Data Input'!U5:U71)+SUMIF('✏️ Data Input'!A5:A71,"CUSHION",'✏️ Data Input'!V5:V71)+SUMIF('✏️ Data Input'!A5:A71,"CUSHION",'✏️ Data Input'!W5:W71)+SUMIF('✏️ Data Input'!A5:A71,"CUSHION",'✏️ Data Input'!X5:X71)+SUMIF('✏️ Data Input'!A5:A71,"CUSHION",'✏️ Data Input'!Y5:Y71)+SUMIF('✏️ Data Input'!A5:A71,"CUSHION",'✏️ Data Input'!Z5:Z71)+SUMIF('✏️ Data Input'!A5:A71,"CUSHION",'✏️ Data Input'!AA5:AA71)+SUMIF('✏️ Data Input'!A5:A71,"CUSHION",'✏️ Data Input'!AB5:AB71)+SUMIF('✏️ Data Input'!A5:A71,"CUSHION",'✏️ Data Input'!AC5:AC71)+SUMIF('✏️ Data Input'!A5:A71,"CUSHION",'✏️ Data Input'!AD5:AD71)+SUMIF('✏️ Data Input'!A5:A71,"CUSHION",'✏️ Data Input'!AE5:AE71)+SUMIF('✏️ Data Input'!A5:A71,"CUSHION",'✏️ Data Input'!AF5:AF71)+SUMIF('✏️ Data Input'!A5:A71,"CUSHION",'✏️ Data Input'!AG5:AG71)+SUMIF('✏️ Data Input'!A5:A71,"CUSHION",'✏️ Data Input'!AH5:AH71)+SUMIF('✏️ Data Input'!A5:A71,"CUSHION",'✏️ Data Input'!AI5:AI71) -> 111360 | D15: =(SUMIF('✏️ Data Input'!A5:A71,"CUSHION",'✏️ Data Input'!C5:C71)+SUMIF('✏️ Data Input'!A5:A71,"CUSHION",'✏️ Data Input'!D5:D71)+SUMIF('✏️ Data Input'!A5:A71,"CUSHION",'✏️ Data Input'!E5:E71)+SUMIF('✏️ Data Input'!A5:A71,"CUSHION",'✏️ Data Input'!F5:F71)+SUMIF('✏️ Data Input'!A5:A71,"CUSHION",'✏️ Data Input'!G5:G71)+SUMIF('✏️ Data Input'!A5:A71,"CUSHION",'✏️ Data Input'!H5:H71)+SUMIF('✏️ Data Input'!A5:A71,"CUSHION",'✏️ Data Input'!I5:I71)+SUMIF('✏️ Data Input'!A5:A71,"CUSHION",'✏️ Data Input'!J5:J71)+SUMIF('✏️ Data Input'!A5:A71,"CUSHION",'✏️ Data Input'!K5:K71)+SUMIF('✏️ Data Input'!A5:A71,"CUSHION",'✏️ Data Input'!L5:L71)+SUMIF('✏️ Data Input'!A5:A71,"CUSHION",'✏️ Data Input'!M5:M71)+SUMIF('✏️ Data Input'!A5:A71,"CUSHION",'✏️ Data Input'!N5:N71)+SUMIF('✏️ Data Input'!A5:A71,"CUSHION",'✏️ Data Input'!O5:O71)+SUMIF('✏️ Data Input'!A5:A71,"CUSHION",'✏️ Data Input'!P5:P71)+SUMIF('✏️ Data Input'!A5:A71,"CUSHION",'✏️ Data Input'!Q5:Q71)+SUMIF('✏️ Data Input'!A5:A71,"CUSHION",'✏️ Data Input'!R5:R71)+SUMIF('✏️ Data Input'!A5:A71,"CUSHION",'✏️ Data Input'!S5:S71)+SUMIF('✏️ Data Input'!A5:A71,"CUSHION",'✏️ Data Input'!T5:T71)+SUMIF('✏️ Data Input'!A5:A71,"CUSHION",'✏️ Data Input'!U5:U71)+SUMIF('✏️ Data Input'!A5:A71,"CUSHION",'✏️ Data Input'!V5:V71)+SUMIF('✏️ Data Input'!A5:A71,"CUSHION",'✏️ Data Input'!W5:W71)+SUMIF('✏️ Data Input'!A5:A71,"CUSHION",'✏️ Data Input'!X5:X71)+SUMIF('✏️ Data Input'!A5:A71,"CUSHION",'✏️ Data Input'!Y5:Y71)+SUMIF('✏️ Data Input'!A5:A71,"CUSHION",'✏️ Data Input'!Z5:Z71)+SUMIF('✏️ Data Input'!A5:A71,"CUSHION",'✏️ Data Input'!AA5:AA71)+SUMIF('✏️ Data Input'!A5:A71,"CUSHION",'✏️ Data Input'!AB5:AB71)+SUMIF('✏️ Data Input'!A5:A71,"CUSHION",'✏️ Data Input'!AC5:AC71)+SUMIF('✏️ Data Input'!A5:A71,"CUSHION",'✏️ Data Input'!AD5:AD71)+SUMIF('✏️ Data Input'!A5:A71,"CUSHION",'✏️ Data Input'!AE5:AE71)+SUMIF('✏️ Data Input'!A5:A71,"CUSHION",'✏️ Data Input'!AF5:AF71)+SUMIF('✏️ Data Input'!A5:A71,"CUSHION",'✏️ Data Input'!AG5:AG71)+SUMIF('✏️ Data Input'!A5:A71,"CUSHION",'✏️ Data Input'!AH5:AH71)+SUMIF('✏️ Data Input'!A5:A71,"CUSHION",'✏️ Data Input'!AI5:AI71))/33 -> 3374.5455 | E15: — | F15: — | G15: —
B17: MONTHLY TOTALS (auto-calculated from Data Input)
B18: Facility | C18: May 2026 | D18: Jun 2026 | E18: Jul 2026 | F18: Aug 2026 | G18: Sep 2026 | H18: Oct 2026 | I18: Nov 2026
B19: JCI2 LH | C19: =SUMIF('✏️ Data Input'!A5:A71,"JCI2 LH",'✏️ Data Input'!C5:C71)+SUMIF('✏️ Data Input'!A5:A71,"JCI2 LH",'✏️ Data Input'!D5:D71)+SUMIF('✏️ Data Input'!A5:A71,"JCI2 LH",'✏️ Data Input'!E5:E71) -> 9600 | D19: =SUMIF('✏️ Data Input'!A5:A71,"JCI2 LH",'✏️ Data Input'!F5:F71)+SUMIF('✏️ Data Input'!A5:A71,"JCI2 LH",'✏️ Data Input'!G5:G71)+SUMIF('✏️ Data Input'!A5:A71,"JCI2 LH",'✏️ Data Input'!H5:H71)+SUMIF('✏️ Data Input'!A5:A71,"JCI2 LH",'✏️ Data Input'!I5:I71)+SUMIF('✏️ Data Input'!A5:A71,"JCI2 LH",'✏️ Data Input'!J5:J71) -> 19556 | E19: =SUMIF('✏️ Data Input'!A5:A71,"JCI2 LH",'✏️ Data Input'!K5:K71)+SUMIF('✏️ Data Input'!A5:A71,"JCI2 LH",'✏️ Data Input'!L5:L71)+SUMIF('✏️ Data Input'!A5:A71,"JCI2 LH",'✏️ Data Input'!M5:M71)+SUMIF('✏️ Data Input'!A5:A71,"JCI2 LH",'✏️ Data Input'!N5:N71) -> 11620 | F19: =SUMIF('✏️ Data Input'!A5:A71,"JCI2 LH",'✏️ Data Input'!O5:O71)+SUMIF('✏️ Data Input'!A5:A71,"JCI2 LH",'✏️ Data Input'!P5:P71)+SUMIF('✏️ Data Input'!A5:A71,"JCI2 LH",'✏️ Data Input'!Q5:Q71)+SUMIF('✏️ Data Input'!A5:A71,"JCI2 LH",'✏️ Data Input'!R5:R71)+SUMIF('✏️ Data Input'!A5:A71,"JCI2 LH",'✏️ Data Input'!S5:S71) -> 10580 | G19: =SUMIF('✏️ Data Input'!A5:A71,"JCI2 LH",'✏️ Data Input'!T5:T71)+SUMIF('✏️ Data Input'!A5:A71,"JCI2 LH",'✏️ Data Input'!U5:U71)+SUMIF('✏️ Data Input'!A5:A71,"JCI2 LH",'✏️ Data Input'!V5:V71)+SUMIF('✏️ Data Input'!A5:A71,"JCI2 LH",'✏️ Data Input'!W5:W71) -> 14520 | H19: =SUMIF('✏️ Data Input'!A5:A71,"JCI2 LH",'✏️ Data Input'!X5:X71)+SUMIF('✏️ Data Input'!A5:A71,"JCI2 LH",'✏️ Data Input'!Y5:Y71)+SUMIF('✏️ Data Input'!A5:A71,"JCI2 LH",'✏️ Data Input'!Z5:Z71)+SUMIF('✏️ Data Input'!A5:A71,"JCI2 LH",'✏️ Data Input'!AA5:AA71) -> 10360 | I19: =SUMIF('✏️ Data Input'!A5:A71,"JCI2 LH",'✏️ Data Input'!AB5:AB71)+SUMIF('✏️ Data Input'!A5:A71,"JCI2 LH",'✏️ Data Input'!AC5:AC71)+SUMIF('✏️ Data Input'!A5:A71,"JCI2 LH",'✏️ Data Input'!AD5:AD71)+SUMIF('✏️ Data Input'!A5:A71,"JCI2 LH",'✏️ Data Input'!AE5:AE71)+SUMIF('✏️ Data Input'!A5:A71,"JCI2 LH",'✏️ Data Input'!AF5:AF71) -> 18560
B20: JCI2 RH | C20: =SUMIF('✏️ Data Input'!A5:A71,"JCI2 RH",'✏️ Data Input'!C5:C71)+SUMIF('✏️ Data Input'!A5:A71,"JCI2 RH",'✏️ Data Input'!D5:D71)+SUMIF('✏️ Data Input'!A5:A71,"JCI2 RH",'✏️ Data Input'!E5:E71) -> 9680 | D20: =SUMIF('✏️ Data Input'!A5:A71,"JCI2 RH",'✏️ Data Input'!F5:F71)+SUMIF('✏️ Data Input'!A5:A71,"JCI2 RH",'✏️ Data Input'!G5:G71)+SUMIF('✏️ Data Input'!A5:A71,"JCI2 RH",'✏️ Data Input'!H5:H71)+SUMIF('✏️ Data Input'!A5:A71,"JCI2 RH",'✏️ Data Input'!I5:I71)+SUMIF('✏️ Data Input'!A5:A71,"JCI2 RH",'✏️ Data Input'!J5:J71) -> 19655 | E20: =SUMIF('✏️ Data Input'!A5:A71,"JCI2 RH",'✏️ Data Input'!K5:K71)+SUMIF('✏️ Data Input'!A5:A71,"JCI2 RH",'✏️ Data Input'!L5:L71)+SUMIF('✏️ Data Input'!A5:A71,"JCI2 RH",'✏️ Data Input'!M5:M71)+SUMIF('✏️ Data Input'!A5:A71,"JCI2 RH",'✏️ Data Input'!N5:N71) -> 11700 | F20: =SUMIF('✏️ Data Input'!A5:A71,"JCI2 RH",'✏️ Data Input'!O5:O71)+SUMIF('✏️ Data Input'!A5:A71,"JCI2 RH",'✏️ Data Input'!P5:P71)+SUMIF('✏️ Data Input'!A5:A71,"JCI2 RH",'✏️ Data Input'!Q5:Q71)+SUMIF('✏️ Data Input'!A5:A71,"JCI2 RH",'✏️ Data Input'!R5:R71)+SUMIF('✏️ Data Input'!A5:A71,"JCI2 RH",'✏️ Data Input'!S5:S71) -> 10400 | G20: =SUMIF('✏️ Data Input'!A5:A71,"JCI2 RH",'✏️ Data Input'!T5:T71)+SUMIF('✏️ Data Input'!A5:A71,"JCI2 RH",'✏️ Data Input'!U5:U71)+SUMIF('✏️ Data Input'!A5:A71,"JCI2 RH",'✏️ Data Input'!V5:V71)+SUMIF('✏️ Data Input'!A5:A71,"JCI2 RH",'✏️ Data Input'!W5:W71) -> 14660 | H20: =SUMIF('✏️ Data Input'!A5:A71,"JCI2 RH",'✏️ Data Input'!X5:X71)+SUMIF('✏️ Data Input'!A5:A71,"JCI2 RH",'✏️ Data Input'!Y5:Y71)+SUMIF('✏️ Data Input'!A5:A71,"JCI2 RH",'✏️ Data Input'!Z5:Z71)+SUMIF('✏️ Data Input'!A5:A71,"JCI2 RH",'✏️ Data Input'!AA5:AA71) -> 9960 | I20: =SUMIF('✏️ Data Input'!A5:A71,"JCI2 RH",'✏️ Data Input'!AB5:AB71)+SUMIF('✏️ Data Input'!A5:A71,"JCI2 RH",'✏️ Data Input'!AC5:AC71)+SUMIF('✏️ Data Input'!A5:A71,"JCI2 RH",'✏️ Data Input'!AD5:AD71)+SUMIF('✏️ Data Input'!A5:A71,"JCI2 RH",'✏️ Data Input'!AE5:AE71)+SUMIF('✏️ Data Input'!A5:A71,"JCI2 RH",'✏️ Data Input'!AF5:AF71) -> 18400
B21: REAR SEAT | C21: =SUMIF('✏️ Data Input'!A5:A71,"REAR SEAT",'✏️ Data Input'!C5:C71)+SUMIF('✏️ Data Input'!A5:A71,"REAR SEAT",'✏️ Data Input'!D5:D71)+SUMIF('✏️ Data Input'!A5:A71,"REAR SEAT",'✏️ Data Input'!E5:E71) -> 14880 | D21: =SUMIF('✏️ Data Input'!A5:A71,"REAR SEAT",'✏️ Data Input'!F5:F71)+SUMIF('✏️ Data Input'!A5:A71,"REAR SEAT",'✏️ Data Input'!G5:G71)+SUMIF('✏️ Data Input'!A5:A71,"REAR SEAT",'✏️ Data Input'!H5:H71)+SUMIF('✏️ Data Input'!A5:A71,"REAR SEAT",'✏️ Data Input'!I5:I71)+SUMIF('✏️ Data Input'!A5:A71,"REAR SEAT",'✏️ Data Input'!J5:J71) -> 31680 | E21: =SUMIF('✏️ Data Input'!A5:A71,"REAR SEAT",'✏️ Data Input'!K5:K71)+SUMIF('✏️ Data Input'!A5:A71,"REAR SEAT",'✏️ Data Input'!L5:L71)+SUMIF('✏️ Data Input'!A5:A71,"REAR SEAT",'✏️ Data Input'!M5:M71)+SUMIF('✏️ Data Input'!A5:A71,"REAR SEAT",'✏️ Data Input'!N5:N71) -> 19040 | F21: =SUMIF('✏️ Data Input'!A5:A71,"REAR SEAT",'✏️ Data Input'!O5:O71)+SUMIF('✏️ Data Input'!A5:A71,"REAR SEAT",'✏️ Data Input'!P5:P71)+SUMIF('✏️ Data Input'!A5:A71,"REAR SEAT",'✏️ Data Input'!Q5:Q71)+SUMIF('✏️ Data Input'!A5:A71,"REAR SEAT",'✏️ Data Input'!R5:R71)+SUMIF('✏️ Data Input'!A5:A71,"REAR SEAT",'✏️ Data Input'!S5:S71) -> 17480 | G21: =SUMIF('✏️ Data Input'!A5:A71,"REAR SEAT",'✏️ Data Input'!T5:T71)+SUMIF('✏️ Data Input'!A5:A71,"REAR SEAT",'✏️ Data Input'!U5:U71)+SUMIF('✏️ Data Input'!A5:A71,"REAR SEAT",'✏️ Data Input'!V5:V71)+SUMIF('✏️ Data Input'!A5:A71,"REAR SEAT",'✏️ Data Input'!W5:W71) -> 23480 | H21: =SUMIF('✏️ Data Input'!A5:A71,"REAR SEAT",'✏️ Data Input'!X5:X71)+SUMIF('✏️ Data Input'!A5:A71,"REAR SEAT",'✏️ Data Input'!Y5:Y71)+SUMIF('✏️ Data Input'!A5:A71,"REAR SEAT",'✏️ Data Input'!Z5:Z71)+SUMIF('✏️ Data Input'!A5:A71,"REAR SEAT",'✏️ Data Input'!AA5:AA71) -> 16720 | I21: =SUMIF('✏️ Data Input'!A5:A71,"REAR SEAT",'✏️ Data Input'!AB5:AB71)+SUMIF('✏️ Data Input'!A5:A71,"REAR SEAT",'✏️ Data Input'!AC5:AC71)+SUMIF('✏️ Data Input'!A5:A71,"REAR SEAT",'✏️ Data Input'!AD5:AD71)+SUMIF('✏️ Data Input'!A5:A71,"REAR SEAT",'✏️ Data Input'!AE5:AE71)+SUMIF('✏️ Data Input'!A5:A71,"REAR SEAT",'✏️ Data Input'!AF5:AF71) -> 30240
B22: CUSHION | C22: =SUMIF('✏️ Data Input'!A5:A71,"CUSHION",'✏️ Data Input'!C5:C71)+SUMIF('✏️ Data Input'!A5:A71,"CUSHION",'✏️ Data Input'!D5:D71)+SUMIF('✏️ Data Input'!A5:A71,"CUSHION",'✏️ Data Input'!E5:E71) -> 9600 | D22: =SUMIF('✏️ Data Input'!A5:A71,"CUSHION",'✏️ Data Input'!F5:F71)+SUMIF('✏️ Data Input'!A5:A71,"CUSHION",'✏️ Data Input'!G5:G71)+SUMIF('✏️ Data Input'!A5:A71,"CUSHION",'✏️ Data Input'!H5:H71)+SUMIF('✏️ Data Input'!A5:A71,"CUSHION",'✏️ Data Input'!I5:I71)+SUMIF('✏️ Data Input'!A5:A71,"CUSHION",'✏️ Data Input'!J5:J71) -> 21120 | E22: =SUMIF('✏️ Data Input'!A5:A71,"CUSHION",'✏️ Data Input'!K5:K71)+SUMIF('✏️ Data Input'!A5:A71,"CUSHION",'✏️ Data Input'!L5:L71)+SUMIF('✏️ Data Input'!A5:A71,"CUSHION",'✏️ Data Input'!M5:M71)+SUMIF('✏️ Data Input'!A5:A71,"CUSHION",'✏️ Data Input'!N5:N71) -> 13440 | F22: =SUMIF('✏️ Data Input'!A5:A71,"CUSHION",'✏️ Data Input'!O5:O71)+SUMIF('✏️ Data Input'!A5:A71,"CUSHION",'✏️ Data Input'!P5:P71)+SUMIF('✏️ Data Input'!A5:A71,"CUSHION",'✏️ Data Input'!Q5:Q71)+SUMIF('✏️ Data Input'!A5:A71,"CUSHION",'✏️ Data Input'!R5:R71)+SUMIF('✏️ Data Input'!A5:A71,"CUSHION",'✏️ Data Input'!S5:S71) -> 11520 | G22: =SUMIF('✏️ Data Input'!A5:A71,"CUSHION",'✏️ Data Input'!T5:T71)+SUMIF('✏️ Data Input'!A5:A71,"CUSHION",'✏️ Data Input'!U5:U71)+SUMIF('✏️ Data Input'!A5:A71,"CUSHION",'✏️ Data Input'!V5:V71)+SUMIF('✏️ Data Input'!A5:A71,"CUSHION",'✏️ Data Input'!W5:W71) -> 16320 | H22: =SUMIF('✏️ Data Input'!A5:A71,"CUSHION",'✏️ Data Input'!X5:X71)+SUMIF('✏️ Data Input'!A5:A71,"CUSHION",'✏️ Data Input'!Y5:Y71)+SUMIF('✏️ Data Input'!A5:A71,"CUSHION",'✏️ Data Input'!Z5:Z71)+SUMIF('✏️ Data Input'!A5:A71,"CUSHION",'✏️ Data Input'!AA5:AA71) -> 10560 | I22: =SUMIF('✏️ Data Input'!A5:A71,"CUSHION",'✏️ Data Input'!AB5:AB71)+SUMIF('✏️ Data Input'!A5:A71,"CUSHION",'✏️ Data Input'!AC5:AC71)+SUMIF('✏️ Data Input'!A5:A71,"CUSHION",'✏️ Data Input'!AD5:AD71)+SUMIF('✏️ Data Input'!A5:A71,"CUSHION",'✏️ Data Input'!AE5:AE71)+SUMIF('✏️ Data Input'!A5:A71,"CUSHION",'✏️ Data Input'!AF5:AF71) -> 19200
B23: TOTAL | C23: ='✏️ Data Input'!C72+'✏️ Data Input'!D72+'✏️ Data Input'!E72 -> 43760 | D23: ='✏️ Data Input'!F72+'✏️ Data Input'!G72+'✏️ Data Input'!H72+'✏️ Data Input'!I72+'✏️ Data Input'!J72 -> 92011 | E23: ='✏️ Data Input'!K72+'✏️ Data Input'!L72+'✏️ Data Input'!M72+'✏️ Data Input'!N72 -> 55800 | F23: ='✏️ Data Input'!O72+'✏️ Data Input'!P72+'✏️ Data Input'!Q72+'✏️ Data Input'!R72+'✏️ Data Input'!S72 -> 49980 | G23: ='✏️ Data Input'!T72+'✏️ Data Input'!U72+'✏️ Data Input'!V72+'✏️ Data Input'!W72 -> 68980 | H23: ='✏️ Data Input'!X72+'✏️ Data Input'!Y72+'✏️ Data Input'!Z72+'✏️ Data Input'!AA72 -> 47600 | I23: ='✏️ Data Input'!AB72+'✏️ Data Input'!AC72+'✏️ Data Input'!AD72+'✏️ Data Input'!AE72+'✏️ Data Input'!AF72 -> 86400

Sheet 📈 Weekly Trend
B1: 📈 WEEKLY TREND – ALL FACILITIES (formula-driven)
B2: Week | C2: Grand Total | D2: JCI2 LH | E2: JCI2 RH | F2: REAR SEAT | G2: CUSHION
B3: WK 20 | C3: ='✏️ Data Input'!C72 -> 1040 | D3: =SUMIF('✏️ Data Input'!A5:A71,"JCI2 LH",'✏️ Data Input'!C5:C71) -> 240 | E3: =SUMIF('✏️ Data Input'!A5:A71,"JCI2 RH",'✏️ Data Input'!C5:C71) -> 320 | F3: =SUMIF('✏️ Data Input'!A5:A71,"REAR SEAT",'✏️ Data Input'!C5:C71) -> 480 | G3: =SUMIF('✏️ Data Input'!A5:A71,"CUSHION",'✏️ Data Input'!C5:C71) -> 0
B4: WK 21 | C4: ='✏️ Data Input'!D72 -> 26300 | D4: =SUMIF('✏️ Data Input'!A5:A71,"JCI2 LH",'✏️ Data Input'!D5:D71) -> 5960 | E4: =SUMIF('✏️ Data Input'!A5:A71,"JCI2 RH",'✏️ Data Input'!D5:D71) -> 5700 | F4: =SUMIF('✏️ Data Input'!A5:A71,"REAR SEAT",'✏️ Data Input'!D5:D71) -> 9840 | G4: =SUMIF('✏️ Data Input'!A5:A71,"CUSHION",'✏️ Data Input'!D5:D71) -> 4800
B5: WK 22 | C5: ='✏️ Data Input'!E72 -> 16420 | D5: =SUMIF('✏️ Data Input'!A5:A71,"JCI2 LH",'✏️ Data Input'!E5:E71) -> 3400 | E5: =SUMIF('✏️ Data Input'!A5:A71,"JCI2 RH",'✏️ Data Input'!E5:E71) -> 3660 | F5: =SUMIF('✏️ Data Input'!A5:A71,"REAR SEAT",'✏️ Data Input'!E5:E71) -> 4560 | G5: =SUMIF('✏️ Data Input'!A5:A71,"CUSHION",'✏️ Data Input'!E5:E71) -> 4800
B6: WK 23 | C6: ='✏️ Data Input'!F72 -> 18300 | D6: =SUMIF('✏️ Data Input'!A5:A71,"JCI2 LH",'✏️ Data Input'!F5:F71) -> 3900 | E6: =SUMIF('✏️ Data Input'!A5:A71,"JCI2 RH",'✏️ Data Input'!F5:F71) -> 4240 | F6: =SUMIF('✏️ Data Input'!A5:A71,"REAR SEAT",'✏️ Data Input'!F5:F71) -> 6320 | G6: =SUMIF('✏️ Data Input'!A5:A71,"CUSHION",'✏️ Data Input'!F5:F71) -> 3840
B7: WK 24 | C7: ='✏️ Data Input'!G72 -> 18651 | D7: =SUMIF('✏️ Data Input'!A5:A71,"JCI2 LH",'✏️ Data Input'!G5:G71) -> 4116 | E7: =SUMIF('✏️ Data Input'!A5:A71,"JCI2 RH",'✏️ Data Input'!G5:G71) -> 3975 | F7: =SUMIF('✏️ Data Input'!A5:A71,"REAR SEAT",'✏️ Data Input'!G5:G71) -> 6720 | G7: =SUMIF('✏️ Data Input'!A5:A71,"CUSHION",'✏️ Data Input'!G5:G71) -> 3840
B8: WK 25 | C8: ='✏️ Data Input'!H72 -> 18920 | D8: =SUMIF('✏️ Data Input'!A5:A71,"JCI2 LH",'✏️ Data Input'!H5:H71) -> 4260 | E8: =SUMIF('✏️ Data Input'!A5:A71,"JCI2 RH",'✏️ Data Input'!H5:H71) -> 3860 | F8: =SUMIF('✏️ Data Input'!A5:A71,"REAR SEAT",'✏️ Data Input'!H5:H71) -> 6000 | G8: =SUMIF('✏️ Data Input'!A5:A71,"CUSHION",'✏️ Data Input'!H5:H71) -> 4800
B9: WK 26 | C9: ='✏️ Data Input'!I72 -> 17220 | D9: =SUMIF('✏️ Data Input'!A5:A71,"JCI2 LH",'✏️ Data Input'!I5:I71) -> 3560 | E9: =SUMIF('✏️ Data Input'!A5:A71,"JCI2 RH",'✏️ Data Input'!I5:I71) -> 3580 | F9: =SUMIF('✏️ Data Input'!A5:A71,"REAR SEAT",'✏️ Data Input'!I5:I71) -> 6240 | G9: =SUMIF('✏️ Data Input'!A5:A71,"CUSHION",'✏️ Data Input'!I5:I71) -> 3840
B10: WK 27 | C10: ='✏️ Data Input'!J72 -> 18920 | D10: =SUMIF('✏️ Data Input'!A5:A71,"JCI2 LH",'✏️ Data Input'!J5:J71) -> 3720 | E10: =SUMIF('✏️ Data Input'!A5:A71,"JCI2 RH",'✏️ Data Input'!J5:J71) -> 4000 | F10: =SUMIF('✏️ Data Input'!A5:A71,"REAR SEAT",'✏️ Data Input'!J5:J71) -> 6400 | G10: =SUMIF('✏️ Data Input'!A5:A71,"CUSHION",'✏️ Data Input'!J5:J71) -> 4800
B11: WK 28 | C11: ='✏️ Data Input'!K72 -> 24680 | D11: =SUMIF('✏️ Data Input'!A5:A71,"JCI2 LH",'✏️ Data Input'!K5:K71) -> 5120 | E11: =SUMIF('✏️ Data Input'!A5:A71,"JCI2 RH",'✏️ Data Input'!K5:K71) -> 5400 | F11: =SUMIF('✏️ Data Input'!A5:A71,"REAR SEAT",'✏️ Data Input'!K5:K71) -> 8400 | G11: =SUMIF('✏️ Data Input'!A5:A71,"CUSHION",'✏️ Data Input'!K5:K71) -> 5760
B12: WK 29 | C12: ='✏️ Data Input'!L72 -> 31120 | D12: =SUMIF('✏️ Data Input'!A5:A71,"JCI2 LH",'✏️ Data Input'!L5:L71) -> 6500 | E12: =SUMIF('✏️ Data Input'!A5:A71,"JCI2 RH",'✏️ Data Input'!L5:L71) -> 6300 | F12: =SUMIF('✏️ Data Input'!A5:A71,"REAR SEAT",'✏️ Data Input'!L5:L71) -> 10640 | G12: =SUMIF('✏️ Data Input'!A5:A71,"CUSHION",'✏️ Data Input'!L5:L71) -> 7680
B13: WK 30 | C13: ='✏️ Data Input'!M72 -> 0 | D13: =SUMIF('✏️ Data Input'!A5:A71,"JCI2 LH",'✏️ Data Input'!M5:M71) -> 0 | E13: =SUMIF('✏️ Data Input'!A5:A71,"JCI2 RH",'✏️ Data Input'!M5:M71) -> 0 | F13: =SUMIF('✏️ Data Input'!A5:A71,"REAR SEAT",'✏️ Data Input'!M5:M71) -> 0 | G13: =SUMIF('✏️ Data Input'!A5:A71,"CUSHION",'✏️ Data Input'!M5:M71) -> 0
B14: WK 31 | C14: ='✏️ Data Input'!N72 -> 0 | D14: =SUMIF('✏️ Data Input'!A5:A71,"JCI2 LH",'✏️ Data Input'!N5:N71) -> 0 | E14: =SUMIF('✏️ Data Input'!A5:A71,"JCI2 RH",'✏️ Data Input'!N5:N71) -> 0 | F14: =SUMIF('✏️ Data Input'!A5:A71,"REAR SEAT",'✏️ Data Input'!N5:N71) -> 0 | G14: =SUMIF('✏️ Data Input'!A5:A71,"CUSHION",'✏️ Data Input'!N5:N71) -> 0
B15: WK 32 | C15: ='✏️ Data Input'!O72 -> 0 | D15: =SUMIF('✏️ Data Input'!A5:A71,"JCI2 LH",'✏️ Data Input'!O5:O71) -> 0 | E15: =SUMIF('✏️ Data Input'!A5:A71,"JCI2 RH",'✏️ Data Input'!O5:O71) -> 0 | F15: =SUMIF('✏️ Data Input'!A5:A71,"REAR SEAT",'✏️ Data Input'!O5:O71) -> 0 | G15: =SUMIF('✏️ Data Input'!A5:A71,"CUSHION",'✏️ Data Input'!O5:O71) -> 0
B16: WK 33 | C16: ='✏️ Data Input'!P72 -> 0 | D16: =SUMIF('✏️ Data Input'!A5:A71,"JCI2 LH",'✏️ Data Input'!P5:P71) -> 0 | E16: =SUMIF('✏️ Data Input'!A5:A71,"JCI2 RH",'✏️ Data Input'!P5:P71) -> 0 | F16: =SUMIF('✏️ Data Input'!A5:A71,"REAR SEAT",'✏️ Data Input'!P5:P71) -> 0 | G16: =SUMIF('✏️ Data Input'!A5:A71,"CUSHION",'✏️ Data Input'!P5:P71) -> 0
B17: WK 34 | C17: ='✏️ Data Input'!Q72 -> 16700 | D17: =SUMIF('✏️ Data Input'!A5:A71,"JCI2 LH",'✏️ Data Input'!Q5:Q71) -> 3840 | E17: =SUMIF('✏️ Data Input'!A5:A71,"JCI2 RH",'✏️ Data Input'!Q5:Q71) -> 3740 | F17: =SUMIF('✏️ Data Input'!A5:A71,"REAR SEAT",'✏️ Data Input'!Q5:Q71) -> 5280 | G17: =SUMIF('✏️ Data Input'!A5:A71,"CUSHION",'✏️ Data Input'!Q5:Q71) -> 3840
B18: WK 35 | C18: ='✏️ Data Input'!R72 -> 16320 | D18: =SUMIF('✏️ Data Input'!A5:A71,"JCI2 LH",'✏️ Data Input'!R5:R71) -> 3080 | E18: =SUMIF('✏️ Data Input'!A5:A71,"JCI2 RH",'✏️ Data Input'!R5:R71) -> 3400 | F18: =SUMIF('✏️ Data Input'!A5:A71,"REAR SEAT",'✏️ Data Input'!R5:R71) -> 6000 | G18: =SUMIF('✏️ Data Input'!A5:A71,"CUSHION",'✏️ Data Input'!R5:R71) -> 3840
B19: WK 36 | C19: ='✏️ Data Input'!S72 -> 16960 | D19: =SUMIF('✏️ Data Input'!A5:A71,"JCI2 LH",'✏️ Data Input'!S5:S71) -> 3660 | E19: =SUMIF('✏️ Data Input'!A5:A71,"JCI2 RH",'✏️ Data Input'!S5:S71) -> 3260 | F19: =SUMIF('✏️ Data Input'!A5:A71,"REAR SEAT",'✏️ Data Input'!S5:S71) -> 6200 | G19: =SUMIF('✏️ Data Input'!A5:A71,"CUSHION",'✏️ Data Input'!S5:S71) -> 3840
B20: WK 37 | C20: ='✏️ Data Input'!T72 -> 17270 | D20: =SUMIF('✏️ Data Input'!A5:A71,"JCI2 LH",'✏️ Data Input'!T5:T71) -> 3640 | E20: =SUMIF('✏️ Data Input'!A5:A71,"JCI2 RH",'✏️ Data Input'!T5:T71) -> 3680 | F20: =SUMIF('✏️ Data Input'!A5:A71,"REAR SEAT",'✏️ Data Input'!T5:T71) -> 5870 | G20: =SUMIF('✏️ Data Input'!A5:A71,"CUSHION",'✏️ Data Input'!T5:T71) -> 4080
B21: WK 38 | C21: ='✏️ Data Input'!U72 -> 17270 | D21: =SUMIF('✏️ Data Input'!A5:A71,"JCI2 LH",'✏️ Data Input'!U5:U71) -> 3640 | E21: =SUMIF('✏️ Data Input'!A5:A71,"JCI2 RH",'✏️ Data Input'!U5:U71) -> 3680 | F21: =SUMIF('✏️ Data Input'!A5:A71,"REAR SEAT",'✏️ Data Input'!U5:U71) -> 5870 | G21: =SUMIF('✏️ Data Input'!A5:A71,"CUSHION",'✏️ Data Input'!U5:U71) -> 4080
B22: WK 39 | C22: ='✏️ Data Input'!V72 -> 17270 | D22: =SUMIF('✏️ Data Input'!A5:A71,"JCI2 LH",'✏️ Data Input'!V5:V71) -> 3640 | E22: =SUMIF('✏️ Data Input'!A5:A71,"JCI2 RH",'✏️ Data Input'!V5:V71) -> 3680 | F22: =SUMIF('✏️ Data Input'!A5:A71,"REAR SEAT",'✏️ Data Input'!V5:V71) -> 5870 | G22: =SUMIF('✏️ Data Input'!A5:A71,"CUSHION",'✏️ Data Input'!V5:V71) -> 4080
B23: WK 40 | C23: ='✏️ Data Input'!W72 -> 17170 | D23: =SUMIF('✏️ Data Input'!A5:A71,"JCI2 LH",'✏️ Data Input'!W5:W71) -> 3600 | E23: =SUMIF('✏️ Data Input'!A5:A71,"JCI2 RH",'✏️ Data Input'!W5:W71) -> 3620 | F23: =SUMIF('✏️ Data Input'!A5:A71,"REAR SEAT",'✏️ Data Input'!W5:W71) -> 5870 | G23: =SUMIF('✏️ Data Input'!A5:A71,"CUSHION",'✏️ Data Input'!W5:W71) -> 4080
B24: WK 41 | C24: ='✏️ Data Input'!X72 -> 11920 | D24: =SUMIF('✏️ Data Input'!A5:A71,"JCI2 LH",'✏️ Data Input'!X5:X71) -> 2600 | E24: =SUMIF('✏️ Data Input'!A5:A71,"JCI2 RH",'✏️ Data Input'!X5:X71) -> 2500 | F24: =SUMIF('✏️ Data Input'!A5:A71,"REAR SEAT",'✏️ Data Input'!X5:X71) -> 4180 | G24: =SUMIF('✏️ Data Input'!A5:A71,"CUSHION",'✏️ Data Input'!X5:X71) -> 2640
B25: WK 42 | C25: ='✏️ Data Input'!Y72 -> 11920 | D25: =SUMIF('✏️ Data Input'!A5:A71,"JCI2 LH",'✏️ Data Input'!Y5:Y71) -> 2600 | E25: =SUMIF('✏️ Data Input'!A5:A71,"JCI2 RH",'✏️ Data Input'!Y5:Y71) -> 2500 | F25: =SUMIF('✏️ Data Input'!A5:A71,"REAR SEAT",'✏️ Data Input'!Y5:Y71) -> 4180 | G25: =SUMIF('✏️ Data Input'!A5:A71,"CUSHION",'✏️ Data Input'!Y5:Y71) -> 2640
B26: WK 43 | C26: ='✏️ Data Input'!Z72 -> 11920 | D26: =SUMIF('✏️ Data Input'!A5:A71,"JCI2 LH",'✏️ Data Input'!Z5:Z71) -> 2600 | E26: =SUMIF('✏️ Data Input'!A5:A71,"JCI2 RH",'✏️ Data Input'!Z5:Z71) -> 2500 | F26: =SUMIF('✏️ Data Input'!A5:A71,"REAR SEAT",'✏️ Data Input'!Z5:Z71) -> 4180 | G26: =SUMIF('✏️ Data Input'!A5:A71,"CUSHION",'✏️ Data Input'!Z5:Z71) -> 2640
B27: WK 44 | C27: ='✏️ Data Input'!AA72 -> 11840 | D27: =SUMIF('✏️ Data Input'!A5:A71,"JCI2 LH",'✏️ Data Input'!AA5:AA71) -> 2560 | E27: =SUMIF('✏️ Data Input'!A5:A71,"JCI2 RH",'✏️ Data Input'!AA5:AA71) -> 2460 | F27: =SUMIF('✏️ Data Input'!A5:A71,"REAR SEAT",'✏️ Data Input'!AA5:AA71) -> 4180 | G27: =SUMIF('✏️ Data Input'!A5:A71,"CUSHION",'✏️ Data Input'!AA5:AA71) -> 2640
B28: WK 45 | C28: ='✏️ Data Input'!AB72 -> 17430 | D28: =SUMIF('✏️ Data Input'!A5:A71,"JCI2 LH",'✏️ Data Input'!AB5:AB71) -> 3780 | E28: =SUMIF('✏️ Data Input'!A5:A71,"JCI2 RH",'✏️ Data Input'!AB5:AB71) -> 3750 | F28: =SUMIF('✏️ Data Input'!A5:A71,"REAR SEAT",'✏️ Data Input'!AB5:AB71) -> 6060 | G28: =SUMIF('✏️ Data Input'!A5:A71,"CUSHION",'✏️ Data Input'!AB5:AB71) -> 3840
B29: WK 46 | C29: ='✏️ Data Input'!AC72 -> 17430 | D29: =SUMIF('✏️ Data Input'!A5:A71,"JCI2 LH",'✏️ Data Input'!AC5:AC71) -> 3780 | E29: =SUMIF('✏️ Data Input'!A5:A71,"JCI2 RH",'✏️ Data Input'!AC5:AC71) -> 3750 | F29: =SUMIF('✏️ Data Input'!A5:A71,"REAR SEAT",'✏️ Data Input'!AC5:AC71) -> 6060 | G29: =SUMIF('✏️ Data Input'!A5:A71,"CUSHION",'✏️ Data Input'!AC5:AC71) -> 3840
B30: WK 47 | C30: ='✏️ Data Input'!AD72 -> 17420 | D30: =SUMIF('✏️ Data Input'!A5:A71,"JCI2 LH",'✏️ Data Input'!AD5:AD71) -> 3780 | E30: =SUMIF('✏️ Data Input'!A5:A71,"JCI2 RH",'✏️ Data Input'!AD5:AD71) -> 3740 | F30: =SUMIF('✏️ Data Input'!A5:A71,"REAR SEAT",'✏️ Data Input'!AD5:AD71) -> 6060 | G30: =SUMIF('✏️ Data Input'!A5:A71,"CUSHION",'✏️ Data Input'!AD5:AD71) -> 3840
B31: WK 48 | C31: ='✏️ Data Input'!AE72 -> 17420 | D31: =SUMIF('✏️ Data Input'!A5:A71,"JCI2 LH",'✏️ Data Input'!AE5:AE71) -> 3780 | E31: =SUMIF('✏️ Data Input'!A5:A71,"JCI2 RH",'✏️ Data Input'!AE5:AE71) -> 3740 | F31: =SUMIF('✏️ Data Input'!A5:A71,"REAR SEAT",'✏️ Data Input'!AE5:AE71) -> 6060 | G31: =SUMIF('✏️ Data Input'!A5:A71,"CUSHION",'✏️ Data Input'!AE5:AE71) -> 3840
B32: WK 49 | C32: ='✏️ Data Input'!AF72 -> 16700 | D32: =SUMIF('✏️ Data Input'!A5:A71,"JCI2 LH",'✏️ Data Input'!AF5:AF71) -> 3440 | E32: =SUMIF('✏️ Data Input'!A5:A71,"JCI2 RH",'✏️ Data Input'!AF5:AF71) -> 3420 | F32: =SUMIF('✏️ Data Input'!A5:A71,"REAR SEAT",'✏️ Data Input'!AF5:AF71) -> 6000 | G32: =SUMIF('✏️ Data Input'!A5:A71,"CUSHION",'✏️ Data Input'!AF5:AF71) -> 3840
B33: WK 50 | C33: ='✏️ Data Input'!AG72 -> 18580 | D33: =SUMIF('✏️ Data Input'!A5:A71,"JCI2 LH",'✏️ Data Input'!AG5:AG71) -> 3920 | E33: =SUMIF('✏️ Data Input'!A5:A71,"JCI2 RH",'✏️ Data Input'!AG5:AG71) -> 3760 | F33: =SUMIF('✏️ Data Input'!A5:A71,"REAR SEAT",'✏️ Data Input'!AG5:AG71) -> 6100 | G33: =SUMIF('✏️ Data Input'!A5:A71,"CUSHION",'✏️ Data Input'!AG5:AG71) -> 4800
B34: WK 51 | C34: ='✏️ Data Input'!AH72 -> 18580 | D34: =SUMIF('✏️ Data Input'!A5:A71,"JCI2 LH",'✏️ Data Input'!AH5:AH71) -> 3920 | E34: =SUMIF('✏️ Data Input'!A5:A71,"JCI2 RH",'✏️ Data Input'!AH5:AH71) -> 3760 | F34: =SUMIF('✏️ Data Input'!A5:A71,"REAR SEAT",'✏️ Data Input'!AH5:AH71) -> 6100 | G34: =SUMIF('✏️ Data Input'!A5:A71,"CUSHION",'✏️ Data Input'!AH5:AH71) -> 4800
B35: WK 52 | C35: ='✏️ Data Input'!AI72 -> 0 | D35: =SUMIF('✏️ Data Input'!A5:A71,"JCI2 LH",'✏️ Data Input'!AI5:AI71) -> 0 | E35: =SUMIF('✏️ Data Input'!A5:A71,"JCI2 RH",'✏️ Data Input'!AI5:AI71) -> 0 | F35: =SUMIF('✏️ Data Input'!A5:A71,"REAR SEAT",'✏️ Data Input'!AI5:AI71) -> 0 | G35: =SUMIF('✏️ Data Input'!A5:A71,"CUSHION",'✏️ Data Input'!AI5:AI71) -> 0

Sheet 🏭 Facility Analysis
A1: 🏭 FACILITY ANALYSIS (formula-driven – auto-updates from Data Input)
A3: JCI2 LH
A4: Part No. | C4: WK 20 | D4: WK 21 | E4: WK 22 | F4: WK 23 | G4: WK 24 | H4: WK 25 | I4: WK 26 | J4: WK 27 | K4: WK 28 | L4: WK 29 | M4: WK 30 | N4: WK 31 | O4: WK 32 | P4: WK 33 | Q4: WK 34 | R4: WK 35 | S4: WK 36 | T4: WK 37 | U4: WK 38 | V4: WK 39 | W4: WK 40 | X4: WK 41 | Y4: WK 42 | Z4: WK 43 | AA4: WK 44 | AB4: WK 45 | AC4: WK 46 | AD4: WK 47 | AE4: WK 48 | AF4: WK 49 | AG4: WK 50 | AH4: WK 51 | AI4: WK 52
A5: ='✏️ Data Input'!B5 -> 4172750 | C5: ='✏️ Data Input'!C5 -> 0 | D5: ='✏️ Data Input'!D5 -> 480 | E5: ='✏️ Data Input'!E5 -> 0 | F5: ='✏️ Data Input'!F5 -> 0 | G5: ='✏️ Data Input'!G5 -> 160 | H5: ='✏️ Data Input'!H5 -> 320 | I5: ='✏️ Data Input'!I5 -> 0 | J5: ='✏️ Data Input'!J5 -> 160 | ... AI5: ='✏️ Data Input'!AI5 -> 0
A6: ='✏️ Data Input'!B6 -> 4172755 | C6: ='✏️ Data Input'!C6 -> 0 | D6: ='✏️ Data Input'!D6 -> 160 | E6: ='✏️ Data Input'!E6 -> 160 | F6: ='✏️ Data Input'!F6 -> 160 | G6: ='✏️ Data Input'!G6 -> 0 | H6: ='✏️ Data Input'!H6 -> 160 | I6: ='✏️ Data Input'!I6 -> 160 | J6: ='✏️ Data Input'!J6 -> 0 | ... AI6: ='✏️ Data Input'!AI6 -> 0
A7: ='✏️ Data Input'!B7 -> 5080299 | C7: ='✏️ Data Input'!C7 -> 0 | D7: ='✏️ Data Input'!D7 -> 0 | E7: ='✏️ Data Input'!E7 -> 0 | F7: ='✏️ Data Input'!F7 -> 0 | G7: ='✏️ Data Input'!G7 -> 0 | H7: ='✏️ Data Input'!H7 -> 0 | I7: ='✏️ Data Input'!I7 -> 0 | J7: ='✏️ Data Input'!J7 -> 0 | ... AI7: ='✏️ Data Input'!AI7 -> 0
A8: ='✏️ Data Input'!B8 -> 5073059 | C8: ='✏️ Data Input'!C8 -> 0 | D8: ='✏️ Data Input'!D8 -> 160 | E8: ='✏️ Data Input'!E8 -> 0 | F8: ='✏️ Data Input'!F8 -> 0 | G8: ='✏️ Data Input'!G8 -> 0 | H8: ='✏️ Data Input'!H8 -> 160 | I8: ='✏️ Data Input'!I8 -> 0 | J8: ='✏️ Data Input'!J8 -> 160 | ... AI8: ='✏️ Data Input'!AI8 -> 0
A9: ='✏️ Data Input'!B9 -> 5073061 | C9: ='✏️ Data Input'!C9 -> 0 | D9: ='✏️ Data Input'!D9 -> 0 | E9: ='✏️ Data Input'!E9 -> 0 | F9: ='✏️ Data Input'!F9 -> 0 | G9: ='✏️ Data Input'!G9 -> 0 | H9: ='✏️ Data Input'!H9 -> 0 | I9: ='✏️ Data Input'!I9 -> 0 | J9: ='✏️ Data Input'!J9 -> 0 | ... AI9: ='✏️ Data Input'!AI9 -> 0
A10: ='✏️ Data Input'!B10 -> 4172749 | C10: ='✏️ Data Input'!C10 -> 0 | D10: ='✏️ Data Input'!D10 -> 200 | E10: ='✏️ Data Input'!E10 -> 100 | F10: ='✏️ Data Input'!F10 -> 200 | G10: ='✏️ Data Input'!G10 -> 200 | H10: ='✏️ Data Input'!H10 -> 100 | I10: ='✏️ Data Input'!I10 -> 100 | J10: ='✏️ Data Input'!J10 -> 100 | ... AI10: ='✏️ Data Input'!AI10 -> 0
A11: ='✏️ Data Input'!B11 -> 4172753 | C11: ='✏️ Data Input'!C11 -> 0 | D11: ='✏️ Data Input'!D11 -> 0 | E11: ='✏️ Data Input'!E11 -> 0 | F11: ='✏️ Data Input'!F11 -> 0 | G11: ='✏️ Data Input'!G11 -> 0 | H11: ='✏️ Data Input'!H11 -> 100 | I11: ='✏️ Data Input'!I11 -> 0 | J11: ='✏️ Data Input'!J11 -> 0 | ... AI11: ='✏️ Data Input'!AI11 -> 0
A12: ='✏️ Data Input'!B12 -> 5080294 | C12: ='✏️ Data Input'!C12 -> 0 | D12: ='✏️ Data Input'!D12 -> 100 | E12: ='✏️ Data Input'!E12 -> 0 | F12: ='✏️ Data Input'!F12 -> 0 | G12: ='✏️ Data Input'!G12 -> 0 | H12: ='✏️ Data Input'!H12 -> 100 | I12: ='✏️ Data Input'!I12 -> 0 | J12: ='✏️ Data Input'!J12 -> 0 | ... AI12: ='✏️ Data Input'!AI12 -> 0
A13: ='✏️ Data Input'!B13 -> 5073058 | C13: ='✏️ Data Input'!C13 -> 0 | D13: ='✏️ Data Input'!D13 -> 300 | E13: ='✏️ Data Input'!E13 -> 200 | F13: ='✏️ Data Input'!F13 -> 100 | G13: ='✏️ Data Input'!G13 -> 200 | H13: ='✏️ Data Input'!H13 -> 200 | I13: ='✏️ Data Input'!I13 -> 100 | J13: ='✏️ Data Input'!J13 -> 100 | ... AI13: ='✏️ Data Input'!AI13 -> 0
A14: ='✏️ Data Input'!B14 -> 4172770 | C14: ='✏️ Data Input'!C14 -> 0 | D14: ='✏️ Data Input'!D14 -> 0 | E14: ='✏️ Data Input'!E14 -> 0 | F14: ='✏️ Data Input'!F14 -> 0 | G14: ='✏️ Data Input'!G14 -> 0 | H14: ='✏️ Data Input'!H14 -> 0 | I14: ='✏️ Data Input'!I14 -> 0 | J14: ='✏️ Data Input'!J14 -> 0 | ... AI14: ='✏️ Data Input'!AI14 -> 0
A15: ='✏️ Data Input'!B15 -> 4817100 | C15: ='✏️ Data Input'!C15 -> 160 | D15: ='✏️ Data Input'!D15 -> 1040 | E15: ='✏️ Data Input'!E15 -> 1040 | F15: ='✏️ Data Input'!F15 -> 800 | G15: ='✏️ Data Input'!G15 -> 720 | H15: ='✏️ Data Input'!H15 -> 720 | I15: ='✏️ Data Input'!I15 -> 640 | J15: ='✏️ Data Input'!J15 -> 640 | ... AI15: ='✏️ Data Input'!AI15 -> 0
A16: ='✏️ Data Input'!B16 -> 4817103 | C16: ='✏️ Data Input'!C16 -> 0 | D16: ='✏️ Data Input'!D16 -> 800 | E16: ='✏️ Data Input'!E16 -> 0 | F16: ='✏️ Data Input'!F16 -> 400 | G16: ='✏️ Data Input'!G16 -> 480 | H16: ='✏️ Data Input'!H16 -> 400 | I16: ='✏️ Data Input'!I16 -> 400 | J16: ='✏️ Data Input'!J16 -> 480 | ... AI16: ='✏️ Data Input'!AI16 -> 0
... A33: ='✏️ Data Input'!B33 -> 5080263 | C33: ='✏️ Data Input'!C33 -> 0 | D33: ='✏️ Data Input'!D33 -> 80 | E33: ='✏️ Data Input'!E33 -> 60 | F33: ='✏️ Data Input'!F33 -> 0 | G33: ='✏️ Data Input'!G33 -> 36 | H33: ='✏️ Data Input'!H33 -> 0 | I33: ='✏️ Data Input'!I33 -> 0 | J33: ='✏️ Data Input'!J33 -> 0 | ... AI33: ='✏️ Data Input'!AI33 -> 0
A34: SUBTOTAL | C34: =SUMIF('✏️ Data Input'!A5:A71,"JCI2 LH",'✏️ Data Input'!C5:C71) -> 240 | D34: =SUMIF('✏️ Data Input'!A5:A71,"JCI2 LH",'✏️ Data Input'!D5:D71) -> 5960 | E34: =SUMIF('✏️ Data Input'!A5:A71,"JCI2 LH",'✏️ Data Input'!E5:E71) -> 3400 | F34: =SUMIF('✏️ Data Input'!A5:A71,"JCI2 LH",'✏️ Data Input'!F5:F71) -> 3900 | G34: =SUMIF('✏️ Data Input'!A5:A71,"JCI2 LH",'✏️ Data Input'!G5:G71) -> 4116 | H34: =SUMIF('✏️ Data Input'!A5:A71,"JCI2 LH",'✏️ Data Input'!H5:H71) -> 4260 | I34: =SUMIF('✏️ Data Input'!A5:A71,"JCI2 LH",'✏️ Data Input'!I5:I71) -> 3560 | J34: =SUMIF('✏️ Data Input'!A5:A71,"JCI2 LH",'✏️ Data Input'!J5:J71) -> 3720 | K34: =SUMIF('✏️ Data Input'!A5:A71,"JCI2 LH",'✏️ Data Input'!K5:K71) -> 5120 | L34: =SUMIF('✏️ Data Input'!A5:A71,"JCI2 LH",'✏️ Data Input'!L5:L71) -> 6500 | M34: =SUMIF('✏️ Data Input'!A5:A71,"JCI2 LH",'✏️ Data Input'!M5:M71) -> 0 | N34: =SUMIF('✏️ Data Input'!A5:A71,"JCI2 LH",'✏️ Data Input'!N5:N71) -> 0 | O34: =SUMIF('✏️ Data Input'!A5:A71,"JCI2 LH",'✏️ Data Input'!O5:O71) -> 0 | P34: =SUMIF('✏️ Data Input'!A5:A71,"JCI2 LH",'✏️ Data Input'!P5:P71) -> 0 | Q34: =SUMIF('✏️ Data Input'!A5:A71,"JCI2 LH",'✏️ Data Input'!Q5:Q71) -> 3840 | R34: =SUMIF('✏️ Data Input'!A5:A71,"JCI2 LH",'✏️ Data Input'!R5:R71) -> 3080 | S34: =SUMIF('✏️ Data Input'!A5:A71,"JCI2 LH",'✏️ Data Input'!S5:S71) -> 3660 | T34: =SUMIF('✏️ Data Input'!A5:A71,"JCI2 LH",'✏️ Data Input'!T5:T71) -> 3640 | U34: =SUMIF('✏️ Data Input'!A5:A71,"JCI2 LH",'✏️ Data Input'!U5:U71) -> 3640 | V34: =SUMIF('✏️ Data Input'!A5:A71,"JCI2 LH",'✏️ Data Input'!V5:V71) -> 3640 | W34: =SUMIF('✏️ Data Input'!A5:A71,"JCI2 LH",'✏️ Data Input'!W5:W71) -> 3600 | X34: =SUMIF('✏️ Data Input'!A5:A71,"JCI2 LH",'✏️ Data Input'!X5:X71) -> 2600 | Y34: =SUMIF('✏️ Data Input'!A5:A71,"JCI2 LH",'✏️ Data Input'!Y5:Y71) -> 2600 | Z34: =SUMIF('✏️ Data Input'!A5:A71,"JCI2 LH",'✏️ Data Input'!Z5:Z71) -> 2600 | AA34: =SUMIF('✏️ Data Input'!A5:A71,"JCI2 LH",'✏️ Data Input'!AA5:AA71) -> 2560 | AB34: =SUMIF('✏️ Data Input'!A5:A71,"JCI2 LH",'✏️ Data Input'!AB5:AB71) -> 3780 | AC34: =SUMIF('✏️ Data Input'!A5:A71,"JCI2 LH",'✏️ Data Input'!AC5:AC71) -> 3780 | AD34: =SUMIF('✏️ Data Input'!A5:A71,"JCI2 LH",'✏️ Data Input'!AD5:AD71) -> 3780 | AE34: =SUMIF('✏️ Data Input'!A5:A71,"JCI2 LH",'✏️ Data Input'!AE5:AE71) -> 3780 | AF34: =SUMIF('✏️ Data Input'!A5:A71,"JCI2 LH",'✏️ Data Input'!AF5:AF71) -> 3440 | AG34: =SUMIF('✏️ Data Input'!A5:A71,"JCI2 LH",'✏️ Data Input'!AG5:AG71) -> 3920 | AH34: =SUMIF('✏️ Data Input'!A5:A71,"JCI2 LH",'✏️ Data Input'!AH5:AH71) -> 3920 | AI34: =SUMIF('✏️ Data Input'!A5:A71,"JCI2 LH",'✏️ Data Input'!AI5:AI71) -> 0
A36: JCI2 RH
A37: Part No. | C37: WK 20 | D37: WK 21 | E37: WK 22 | F37: WK 23 | G37: WK 24 | H37: WK 25 | I37: WK 26 | J37: WK 27 | K37: WK 28 | L37: WK 29 | M37: WK 30 | N37: WK 31 | O37: WK 32 | P37: WK 33 | Q37: WK 34 | R37: WK 35 | S37: WK 36 | T37: WK 37 | U37: WK 38 | V37: WK 39 | W37: WK 40 | X37: WK 41 | Y37: WK 42 | Z37: WK 43 | AA37: WK 44 | AB37: WK 45 | AC37: WK 46 | AD37: WK 47 | AE37: WK 48 | AF37: WK 49 | AG37: WK 50 | AH37: WK 51 | AI37: WK 52
A38: ='✏️ Data Input'!B34 -> 4172784 | C38: ='✏️ Data Input'!C34 -> 0 | D38: ='✏️ Data Input'!D34 -> 100 | E38: ='✏️ Data Input'!E34 -> 0 | F38: ='✏️ Data Input'!F34 -> 0 | G38: ='✏️ Data Input'!G34 -> 0 | H38: ='✏️ Data Input'!H34 -> 0 | I38: ='✏️ Data Input'!I34 -> 0 | J38: ='✏️ Data Input'!J34 -> 100 | ... AI38: ='✏️ Data Input'!AI34 -> 0
A39: ='✏️ Data Input'!B35 -> 4172800 | C39: ='✏️ Data Input'!C35 -> 0 | D39: ='✏️ Data Input'!D35 -> 100 | E39: ='✏️ Data Input'!E35 -> 0 | F39: ='✏️ Data Input'!F35 -> 0 | G39: ='✏️ Data Input'!G35 -> 0 | H39: ='✏️ Data Input'!H35 -> 0 | I39: ='✏️ Data Input'!I35 -> 100 | J39: ='✏️ Data Input'!J35 -> 0 | ... AI39: ='✏️ Data Input'!AI35 -> 0
A40: ='✏️ Data Input'!B36 -> 4172821 | C40: ='✏️ Data Input'!C36 -> 0 | D40: ='✏️ Data Input'!D36 -> 0 | E40: ='✏️ Data Input'!E36 -> 0 | F40: ='✏️ Data Input'!F36 -> 0 | G40: ='✏️ Data Input'!G36 -> 0 | H40: ='✏️ Data Input'!H36 -> 0 | I40: ='✏️ Data Input'!I36 -> 0 | J40: ='✏️ Data Input'!J36 -> 0 | ... AI40: ='✏️ Data Input'!AI36 -> 0
A41: ='✏️ Data Input'!B37 -> 4172826 | C41: ='✏️ Data Input'!C37 -> 0 | D41: ='✏️ Data Input'!D37 -> 400 | E41: ='✏️ Data Input'!E37 -> 400 | F41: ='✏️ Data Input'!F37 -> 300 | G41: ='✏️ Data Input'!G37 -> 300 | H41: ='✏️ Data Input'!H37 -> 500 | I41: ='✏️ Data Input'!I37 -> 200 | J41: ='✏️ Data Input'!J37 -> 300 | ... AI41: ='✏️ Data Input'!AI37 -> 0
A42: ='✏️ Data Input'!B38 -> 5080446 | C42: ='✏️ Data Input'!C38 -> 0 | D42: ='✏️ Data Input'!D38 -> 0 | E42: ='✏️ Data Input'!E38 -> 0 | F42: ='✏️ Data Input'!F38 -> 100 | G42: ='✏️ Data Input'!G38 -> 0 | H42: ='✏️ Data Input'!H38 -> 0 | I42: ='✏️ Data Input'!I38 -> 0 | J42: ='✏️ Data Input'!J38 -> 0 | ... AI42: ='✏️ Data Input'!AI38 -> 0
A43: ='✏️ Data Input'!B39 -> 5073064 | C43: ='✏️ Data Input'!C39 -> 0 | D43: ='✏️ Data Input'!D39 -> 0 | E43: ='✏️ Data Input'!E39 -> 0 | F43: ='✏️ Data Input'!F39 -> 0 | G43: ='✏️ Data Input'!G39 -> 100 | H43: ='✏️ Data Input'!H39 -> 0 | I43: ='✏️ Data Input'!I39 -> 0 | J43: ='✏️ Data Input'!J39 -> 0 | ... AI43: ='✏️ Data Input'!AI39 -> 0
A44: ='✏️ Data Input'!B40 -> 4172820 | C44: ='✏️ Data Input'!C40 -> 0 | D44: ='✏️ Data Input'!D40 -> 0 | E44: ='✏️ Data Input'!E40 -> 0 | F44: ='✏️ Data Input'!F40 -> 0 | G44: ='✏️ Data Input'!G40 -> 0 | H44: ='✏️ Data Input'!H40 -> 0 | I44: ='✏️ Data Input'!I40 -> 0 | J44: ='✏️ Data Input'!J40 -> 0 | ... AI44: ='✏️ Data Input'!AI40 -> 0
A45: ='✏️ Data Input'!B41 -> 4172825 | C45: ='✏️ Data Input'!C41 -> 80 | D45: ='✏️ Data Input'!D41 -> 720 | E45: ='✏️ Data Input'!E41 -> 640 | F45: ='✏️ Data Input'!F41 -> 560 | G45: ='✏️ Data Input'!G41 -> 560 | H45: ='✏️ Data Input'!H41 -> 400 | I45: ='✏️ Data Input'!I41 -> 320 | J45: ='✏️ Data Input'!J41 -> 400 | ... AI45: ='✏️ Data Input'!AI41 -> 0
A46: ='✏️ Data Input'!B42 -> 4264989 | C46: ='✏️ Data Input'!C42 -> 0 | D46: ='✏️ Data Input'!D42 -> 160 | E46: ='✏️ Data Input'!E42 -> 0 | F46: ='✏️ Data Input'!F42 -> 80 | G46: ='✏️ Data Input'!G42 -> 160 | H46: ='✏️ Data Input'!H42 -> 160 | I46: ='✏️ Data Input'!I42 -> 80 | J46: ='✏️ Data Input'!J42 -> 160 | ... AI46: ='✏️ Data Input'!AI42 -> 0
A47: ='✏️ Data Input'!B43 -> 4817124 | C47: ='✏️ Data Input'!C43 -> 0 | D47: ='✏️ Data Input'!D43 -> 880 | E47: ='✏️ Data Input'!E43 -> 880 | F47: ='✏️ Data Input'!F43 -> 800 | G47: ='✏️ Data Input'!G43 -> 720 | H47: ='✏️ Data Input'!H43 -> 720 | I47: ='✏️ Data Input'!I43 -> 800 | J47: ='✏️ Data Input'!J43 -> 800 | ... AI47: ='✏️ Data Input'!AI43 -> 0
A48: ='✏️ Data Input'!B44 -> 4817129 | C48: ='✏️ Data Input'!C44 -> 80 | D48: ='✏️ Data Input'!D44 -> 80 | E48: ='✏️ Data Input'!E44 -> 0 | F48: ='✏️ Data Input'!F44 -> 160 | G48: ='✏️ Data Input'!G44 -> 80 | H48: ='✏️ Data Input'!H44 -> 80 | I48: ='✏️ Data Input'!I44 -> 160 | J48: ='✏️ Data Input'!J44 -> 160 | ... AI48: ='✏️ Data Input'!AI44 -> 0
A49: ='✏️ Data Input'!B45 -> 4817131 | C49: ='✏️ Data Input'!C45 -> 0 | D49: ='✏️ Data Input'!D45 -> 720 | E49: ='✏️ Data Input'!E45 -> 0 | F49: ='✏️ Data Input'!F45 -> 240 | G49: ='✏️ Data Input'!G45 -> 320 | H49: ='✏️ Data Input'!H45 -> 240 | I49: ='✏️ Data Input'!I45 -> 320 | J49: ='✏️ Data Input'!J45 -> 400 | ... AI49: ='✏️ Data Input'!AI45 -> 0
... A68: ='✏️ Data Input'!B64 -> 5180041 | C68: ='✏️ Data Input'!C64 -> 0 | D68: ='✏️ Data Input'!D64 -> 0 | E68: ='✏️ Data Input'!E64 -> 0 | F68: ='✏️ Data Input'!F64 -> 80 | G68: ='✏️ Data Input'!G64 -> 0 | H68: ='✏️ Data Input'!H64 -> 0 | I68: ='✏️ Data Input'!I64 -> 0 | J68: ='✏️ Data Input'!J64 -> 80 | ... AI68: ='✏️ Data Input'!AI64 -> 0
